<?xml version="1.0"?>

<robot name="powerbot"
	xmlns:sensor="http://playerstage.sourceforge.net/gazebo/xmlschema/#sensor"
	xmlns:controller="http://playerstage.sourceforge.net/gazebo/xmlschema/#controller"
	xmlns:interface="http://playerstage.sourceforge.net/gazebo/xmlschema/#interface"
	xmlns:xacro="http://ros.org/wiki/xacro">


 <!-- robot name -->
  <xacro:macro name="powerbot" params="prefix parent_link xyz rpy">
    <joint name ="${prefix}/world_joint" type="planar">
      <parent link="${parent_link}"/>
      <child link="base_center"/>
      <origin xyz="${xyz}" rpy="${rpy}"/>
    </joint>
  </xacro:macro>

  <!-- Include powerbot wheels -->
  <xacro:include filename="$(find champ_description)/urdf/powerbot/powerbot_wheel.xacro"/>
  <!-- Include powerbot swivel wheels -->
  <xacro:include filename="$(find champ_description)/urdf/powerbot/powerbot_swivel_ball.xacro"/>
  <!-- where to find all meshes -->
  <xacro:property name="mesh_directory" value="package://champ_description/meshes/p3dx_meshes"/>

  <!--bcz = base_center z value -->
  <xacro:property name="bcz" value="0.067"/> <!-- 0.148 -->



<!-- Brown arm plate -->
<link name="arm_plate">
	<inertial>
		<mass value="0.01"/>	
		<origin xyz="0.2 0 0.03" rpy="0 0 0"/>
		<inertia ixx="1" ixy="0" ixz="0" iyy="1" iyz="0" izz="1"/>
	</inertial>
	<visual>			
		<geometry>
			<box size="0.45 0.75 0.05"/>
		</geometry>
		<origin xyz="0.2 0 0.03" rpy="0 0 0"/>
		<material name="brown">
			<color rgba="0.8 0.4 0.3 1"/>
		</material>
	</visual>
	<collision>
		<origin xyz="0.2 0 0.03" rpy="0 0 0"/>
		<geometry>
			<box size="0.45 0.75 0.05"/>
		</geometry>
	</collision>
</link>

<joint name="arm_plate_joint" type="fixed">
	<parent link="top_plate"/>
	<child link="arm_plate"/>
	<origin xyz="0 0 0"/>
</joint>


<!-- Chassis -->
<link name="base_center">
	<inertial>
	  <mass value="120.0"/>
	  <origin xyz="-0.045 0 ${bcz}"/>
	  <inertia ixx="0.4255" ixy="0.0"    ixz="0.0"
		   		iyy="0.4955" iyz="0.0"
	          			     izz="0.7441"/>
	</inertial>
		<visual name="base_visual">
			<origin xyz="-0.045 0 ${bcz}" rpy="0 0 0"/>
			<geometry name="pioneer_geom">
				<mesh filename="${mesh_directory}/chassis.stl"/>
			</geometry>
	<material name="ChassisRed">
		<color rgba="0.8 0.0 0.0 1.0"/>
	</material>
		</visual>
		<collision>
			<origin xyz="-0.045 0 ${bcz}" rpy="0 0 0"/>
			<geometry>
				<mesh filename="${mesh_directory}/chassis.stl" scale="1.01 1.01 1.01"/>
			</geometry>
		</collision>
	</link>
	<gazebo reference="base_center">
		 <material>Gazebo/Red</material>
	</gazebo>

<!-- Top -->
	<joint name="base_top_joint" type="fixed">
		<!--origin xyz="-0.045 0 0.325" rpy="0 0 0"/-->
		<origin xyz="-0.045 0 0.277" rpy="0 0 0"/>
		<parent link="base_center"/>
		<child link="top_plate"/>
	</joint>

<!-- Top plate -->
	<link name="top_plate">
		<inertial>
			<mass value="0.1"/>	
			<origin xyz="0 0 0"/>
			<inertia ixx="1" ixy="0" ixz="0"
				 iyy="1" iyz="0"
 				izz="1"/>
		</inertial>
		<visual>
			<origin xyz="0 0 0" rpy="0 0 0"/>
			<geometry name="top_geom">
				<mesh filename="${mesh_directory}/top.stl"/>
			</geometry>

			<material name="TopBlack">
					<color rgba="0.038 0.038 0.038 1.0"/>
			</material>
		</visual>
		<collision>
			<origin xyz="0 0 0" rpy="0 0 0"/>
			<geometry>
				<mesh filename="${mesh_directory}/top.stl" />
			</geometry>
		</collision>
	</link>
	<gazebo reference="top_plate">
		<material value="Gazebo/Black"/>
	</gazebo>

  
 <xacro:powerbot_swivel_ball suffix="left" parent="base_center" reflect="1"/>
  <xacro:powerbot_swivel_ball suffix="right" parent="base_center" reflect="-1"/>



  <xacro:powerbot_wheel suffix="left" parent="base_center" reflect="1"/>
  <xacro:powerbot_wheel suffix="right" parent="base_center" reflect="-1"/>

<!-- Front + Back Sonar
	<link name="front_sonar">
		<inertial>
			<mass value="0.0001"/>	
			<origin xyz="0 0 0"/>
			<inertia ixx="1" ixy="0" ixz="0"
				 iyy="1" iyz="0" izz="1"/>
		</inertial>
		<visual name="base_visual">
			<origin xyz="-0.17 0 0.065" rpy="0 0 0"/>
			<geometry name="pioneer_geom">
				<mesh filename="${mesh_directory}/front_sonar.stl" scale="2 2 2"/>
			</geometry>
			<material name="SonarBrown">
				<color rgba="0.206 0.166 0.006 1.0"/>
			</material>
		</visual>
		<collision>
			<origin xyz="0 0 0" rpy="0 0 0"/>
			<geometry>
				<mesh filename="${mesh_directory}/front_sonar.stl" scale="2 2 2"/>
			</geometry>
		</collision>
	</link>

	<gazebo reference="front_sonar">
		<material value="Gazebo/Yellow"/>
	</gazebo>

	<joint name="base_front_joint" type="fixed">
		
		<origin xyz="-0.198 0 ${bcz + 0.06}" rpy="0 0 0"/>
		<parent link="base_center"/>
		<child link="front_sonar"/>
	</joint>

	<link name="back_sonar">
		<inertial>
			<mass value="0.0001"/>	
			<origin xyz="0 0 0"/>
			<inertia ixx="1" ixy="0" ixz="0"
				 iyy="1" iyz="0" izz="1"/>
		</inertial>
		<visual name="back_sonar_vis">
			<origin xyz="0.17 0 0.064" rpy="0 0 0"/>
			<geometry name="pioneer_geom">
				<mesh filename="${mesh_directory}/back_sonar.stl" scale="2 2 2"/>
			</geometry>
			<material name="SonarBrown">
				<color rgba="0.206 0.166 0.006 1.0"/>
			</material>
		</visual>
		<collision>
			<origin xyz="0 0 0" rpy="0 0 0"/>
			<geometry>
				<mesh filename="${mesh_directory}/back_sonar.stl" scale="2 2 2"/>
			</geometry>
		</collision>
	</link>

	<gazebo reference="back_sonar">
		<material value="Gazebo/Yellow"/>
	</gazebo>

	<joint name="base_back_joint" type="fixed">
		
		<origin xyz="0.109 0 ${bcz + 0.061}" rpy="0 0 0"/>
		<parent link="base_center"/>
		<child link="back_sonar"/>
	</joint>
 -->
<!--Actually include  "skid_steer_drive_controller" in robot urdf-->
  <gazebo>
    <!-- Robot locomotion plugin -->
	<plugin name="differential_drive_controller" filename="libgazebo_ros_diff_drive.so">
      <legacyMode>false</legacyMode>
      <alwaysOn>true</alwaysOn>
	  <updateRate>100.0</updateRate>
	  <leftJoint>base_left_wheel_joint</leftJoint>
      <rightJoint>base_right_wheel_joint</rightJoint>
	  <wheelSeparation>0.42</wheelSeparation>
	  <wheelDiameter>0.263</wheelDiameter>
	  <wheelTorque>5</wheelTorque>
      <wheelAcceleration>0</wheelAcceleration>
      <robotNamespace>wam_powerbot</robotNamespace>
	  <commandTopic>cmd_vel</commandTopic>
	  <odometryTopic>odom</odometryTopic>
      <odometrySource>world</odometrySource><!--Other option is Encoder-->
	  <odometryFrame>odom</odometryFrame>
      <robotBaseFrame>base_center</robotBaseFrame>
      <publishTf>1</publishTf>
      <publishWheelTF>false</publishWheelTF>
      <publishWheelJointState>false</publishWheelJointState>
      <rosDebugLevel>Warn</rosDebugLevel>
	</plugin>

    <!-- Fake localization plugin -->
    <plugin name="ground_truth_odometry" filename="libgazebo_ros_p3d.so">
	  <alwaysOn>true</alwaysOn>
	  <updateRate>100.0</updateRate>
	  <bodyName>base_center</bodyName>
	  <topicName>base_pose_ground_truth</topicName>
	  <gaussianNoise>0.01</gaussianNoise>
	  <frameName>world</frameName><!--other option is World-->
      <!-- initialize odometry for fake localization-->
	  <xyzOffsets>0 0 0</xyzOffsets>
	  <rpyOffsets>0 0 0</rpyOffsets>
	</plugin>

  </gazebo>
</robot>
