<?xml version="1.0" ?>
<!-- =================================================================================== -->
<!-- |    This document was autogenerated by xacro from ./powerbot.xacro               | -->
<!-- |    EDITING THIS FILE BY HAND IS NOT RECOMMENDED                                 | -->
<!-- =================================================================================== -->
<robot name="powerbot" xmlns:controller="http://playerstage.sourceforge.net/gazebo/xmlschema/#controller" xmlns:interface="http://playerstage.sourceforge.net/gazebo/xmlschema/#interface" xmlns:sensor="http://playerstage.sourceforge.net/gazebo/xmlschema/#sensor" xmlns:xacro="http://ros.org/wiki/xacro">
  <!--<xacro:include filename="$(find p2os_urdf)/defs/materials.xacro"/>-->
  <!-- 0.148 -->
  <!-- Chassis -->
  <link name="base_center">
    <inertial>
      <mass value="120.0"/>
      <origin xyz="-0.045 0 0.067"/>
      <inertia ixx="0.4255" ixy="0.0" ixz="0.0" iyy="0.4955" iyz="0.0" izz="0.7441"/>
    </inertial>
    <visual name="base_visual">
      <origin rpy="0 0 0" xyz="-0.045 0 0.067"/>
      <geometry name="pioneer_geom">
        <mesh filename="package://champ_description/meshes/p3dx_meshes/chassis.stl"/>
      </geometry>
      <material name="ChassisYellow">
        <color rgba="0.715 0.583 0.210 1.0"/>
      </material>
    </visual>
    <collision>
      <origin rpy="0 0 0" xyz="-0.045 0 0.067"/>
      <geometry>
        <mesh filename="package://champ_description/meshes/p3dx_meshes/chassis.stl"/>
      </geometry>
    </collision>
  </link>
  <gazebo reference="base_center">
    <material value="Gazebo/Yellow"/>
  </gazebo>
  <!-- Top -->
  <joint name="base_top_joint" type="fixed">
    <!--origin xyz="-0.045 0 0.325" rpy="0 0 0"/-->
    <origin rpy="0 0 0" xyz="-0.045 0 0.277"/>
    <parent link="base_center"/>
    <child link="top_plate"/>
  </joint>
  <!-- Top plate -->
  <link name="top_plate">
    <inertial>
      <mass value="0.1"/>
      <origin xyz="0 0 0"/>
      <inertia ixx="1" ixy="0" ixz="0" iyy="1" iyz="0" izz="1"/>
    </inertial>
    <visual>
      <origin rpy="0 0 0" xyz="0 0 0"/>
      <geometry name="top_geom">
        <mesh filename="package://champ_description/meshes/p3dx_meshes/top.stl"/>
      </geometry>
      <material name="TopBlack">
        <color rgba="0.038 0.038 0.038 1.0"/>
      </material>
    </visual>
    <collision>
      <origin rpy="0 0 0" xyz="0 0 0"/>
      <geometry>
        <mesh filename="package://champ_description/meshes/p3dx_meshes/top.stl"/>
      </geometry>
    </collision>
  </link>
  <gazebo reference="top_plate">
    <material value="Gazebo/Black"/>
  </gazebo>
  <!-- Right Swivel support-->
  <link name="right_swivel_support">
    <inertial>
      <mass value="0.1"/>
      <origin rpy="0 0 0" xyz="0 0 0"/>
      <inertia ixx="0.01" ixy="0" ixz="0" iyy="0.01" iyz="0" izz="0.01"/>
    </inertial>
    <visual name="right_swivel_support_visual">
      <origin rpy="0 0 0" xyz="0 0 0"/>
      <geometry name="swivel">
        <mesh filename="package://champ_description/meshes/p3dx_meshes/swivel_support.stl"/>
      </geometry>
      <material name="swivel">
        <color rgba="0.9 0.9 0.9 1"/>
      </material>
    </visual>
    <collision>
      <origin rpy="0 0 0" xyz="0 0 0"/>
      <geometry>
        <mesh filename="package://champ_description/meshes/p3dx_meshes/swivel_support.stl"/>
      </geometry>
    </collision>
  </link>
  <gazebo reference="swivel">
    <material value="Gazebo/Grey"/>
  </gazebo>
  <joint name="right_base_swivel_support_joint" type="fixed">
    <origin rpy="0 0 0" xyz="-0.215 -0.2 -0.091"/>
    <parent link="base_center"/>
    <child link="right_swivel_support"/>
  </joint>
  <!-- Right Swivel -->
  <link name="right_swivel">
    <inertial>
      <mass value="0.1"/>
      <origin rpy="0 0 0" xyz="0 0 0"/>
      <inertia ixx="0.01" ixy="0" ixz="0" iyy="0.01" iyz="0" izz="0.01"/>
    </inertial>
    <visual name="right_swivel_visual">
      <origin rpy="0 0 0" xyz="0 0 0"/>
      <geometry name="swivel">
        <mesh filename="package://champ_description/meshes/p3dx_meshes/swivel.stl"/>
      </geometry>
      <material name="swivel">
        <color rgba="0.5 0.5 0.5 1"/>
      </material>
    </visual>
    <collision>
      <origin rpy="0 0 0" xyz="0 0 0"/>
      <geometry>
        <mesh filename="package://champ_description/meshes/p3dx_meshes/swivel.stl"/>
      </geometry>
    </collision>
  </link>
  <gazebo reference="swivel">
    <material value="Gazebo/Grey"/>
  </gazebo>
  <joint name="right_base_swivel_joint" type="fixed">
    <origin rpy="0 0 0" xyz="0 0 -0.04855"/>
    <!--<axis xyz="0 0 1"/>
	    	<limit effort="100" velocity="100" k_velocity="0" />
	    	<joint_properties damping="0.0" friction="0.0" />-->
    <parent link="right_swivel_support"/>
    <child link="right_swivel"/>
  </joint>
  <!-- Right swivel Wheel + Hubcap -->
  <link name="right_swivel_hubcap">
    <inertial>
      <mass value="0.01"/>
      <origin xyz="0 0 0"/>
      <inertia ixx="0.012411765597" ixy="-0.000711733678" ixz="0.00050272983" iyy="0.015218160428" iyz="-0.000004273467" izz="0.011763977943"/>
    </inertial>
    <visual name="right_swivel_hubcap">
      <origin rpy="0 0 0" xyz="0 0 0"/>
      <geometry name="pioneer_geom">
        <mesh filename="package://champ_description/meshes/p3dx_meshes/center_hubcap.stl"/>
      </geometry>
      <material name="swivel">
        <color rgba="0.5 0.5 0.5 1"/>
      </material>
    </visual>
    <collision>
      <origin rpy="0 0 0" xyz="0 0 0"/>
      <geometry>
        <mesh filename="package://champ_description/meshes/p3dx_meshes/center_hubcap.stl"/>
      </geometry>
    </collision>
  </link>
  <gazebo reference="swivel_hubcap">
    <material value="Gazebo/Grey"/>
  </gazebo>
  <joint name="right_swivel_hubcap_joint" type="continuous">
    <origin rpy="0 0 0" xyz="-0.036 0 -0.029"/>
    <axis xyz="0 1 0"/>
    <anchor xyz="0 0 0"/>
    <limit effort="100" k_velocity="0" velocity="100"/>
    <joint_properties damping="0.0" friction="0.0"/>
    <parent link="right_swivel"/>
    <child link="right_swivel_hubcap"/>
  </joint>
  <link name="right_swivel_wheel">
    <inertial>
      <mass value="0.1"/>
      <origin xyz="0 0 0"/>
      <inertia ixx="0.012411765597" ixy="-0.000711733678" ixz="0.00050272983" iyy="0.015218160428" iyz="-0.000004273467" izz="0.011763977943"/>
    </inertial>
    <visual name="right_swivel_wheel">
      <origin rpy="0 0 0" xyz="0 0 0"/>
      <geometry name="swivel_wheel">
        <mesh filename="package://champ_description/meshes/p3dx_meshes/center_wheel.stl"/>
      </geometry>
      <material name="WheelBlack">
        <color rgba="0.117 0.117 0.117 1"/>
      </material>
    </visual>
    <collision>
      <origin rpy=" -1.57079635 0 0" xyz="0 0 0"/>
      <geometry>
        <cylinder length="0.0422" radius="0.0669"/>
      </geometry>
    </collision>
  </link>
  <gazebo reference="swivel_wheel">
    <material value="Gazebo/Black"/>
  </gazebo>
  <joint name="right_swivel_wheel_hubcap_joint" type="fixed">
    <origin rpy="0 0 0" xyz="0 0 0"/>
    <parent link="right_swivel_hubcap"/>
    <child link="right_swivel_wheel"/>
  </joint>
  <!-- Left Swivel support-->
  <link name="left_swivel_support">
    <inertial>
      <mass value="0.1"/>
      <origin rpy="0 0 0" xyz="0 0 0"/>
      <inertia ixx="0.01" ixy="0" ixz="0" iyy="0.01" iyz="0" izz="0.01"/>
    </inertial>
    <visual name="left_swivel_support_visual">
      <origin rpy="0 0 0" xyz="0 0 0"/>
      <geometry name="swivel">
        <mesh filename="package://champ_description/meshes/p3dx_meshes/swivel_support.stl"/>
      </geometry>
      <material name="swivel">
        <color rgba="0.9 0.9 0.9 1"/>
      </material>
    </visual>
    <collision>
      <origin rpy="0 0 0" xyz="0 0 0"/>
      <geometry>
        <mesh filename="package://champ_description/meshes/p3dx_meshes/swivel_support.stl"/>
      </geometry>
    </collision>
  </link>
  <gazebo reference="swivel">
    <material value="Gazebo/Grey"/>
  </gazebo>
  <joint name="left_base_swivel_support_joint" type="fixed">
    <origin rpy="0 0 0" xyz="-0.215 0.2 -0.091"/>
    <parent link="base_center"/>
    <child link="left_swivel_support"/>
  </joint>
  <!--Left Swivel -->
  <link name="left_swivel">
    <inertial>
      <mass value="0.1"/>
      <origin rpy="0 0 0" xyz="0 0 0"/>
      <inertia ixx="0.01" ixy="0" ixz="0" iyy="0.01" iyz="0" izz="0.01"/>
    </inertial>
    <visual name="left_swivel_visual">
      <origin rpy="0 0 0" xyz="0 0 0"/>
      <geometry name="swivel">
        <mesh filename="package://champ_description/meshes/p3dx_meshes/swivel.stl"/>
      </geometry>
      <material name="swivel">
        <color rgba="0.5 0.5 0.5 1"/>
      </material>
    </visual>
    <collision>
      <origin rpy="0 0 0" xyz="0 0 0"/>
      <geometry>
        <mesh filename="package://champ_description/meshes/p3dx_meshes/swivel.stl"/>
      </geometry>
    </collision>
  </link>
  <gazebo reference="swivel">
    <material value="Gazebo/Grey"/>
  </gazebo>
  <joint name="left_base_swivel_joint" type="fixed">
    <origin rpy="0 0 0" xyz="0 0 -0.04855"/>
    <!--	<axis xyz="0 0 1"/>
         <limit effort="100" velocity="100" k_velocity="0" />
    	<joint_properties damping="0.0" friction="0.0" />-->
    <parent link="left_swivel_support"/>
    <child link="left_swivel"/>
  </joint>
  <!-- left swivel Wheel + Hubcap -->
  <link name="left_swivel_hubcap">
    <inertial>
      <mass value="0.01"/>
      <origin xyz="0 0 0"/>
      <inertia ixx="0.012411765597" ixy="-0.000711733678" ixz="0.00050272983" iyy="0.015218160428" iyz="-0.000004273467" izz="0.011763977943"/>
    </inertial>
    <visual name="left_swivel_hubcap">
      <origin rpy="0 0 0" xyz="0 0 0"/>
      <geometry name="pioneer_geom">
        <mesh filename="package://champ_description/meshes/p3dx_meshes/center_hubcap.stl"/>
      </geometry>
      <material name="swivel">
        <color rgba="0.5 0.5 0.5 1"/>
      </material>
    </visual>
    <collision>
      <origin rpy="0 0 0" xyz="0 0 0"/>
      <geometry>
        <mesh filename="package://champ_description/meshes/p3dx_meshes/center_hubcap.stl"/>
      </geometry>
    </collision>
  </link>
  <gazebo reference="swivel_hubcap">
    <material value="Gazebo/Grey"/>
  </gazebo>
  <joint name="left_swivel_hubcap_joint" type="continuous">
    <origin rpy="0 0 0" xyz="-0.036 0 -0.029"/>
    <axis xyz="0 1 0"/>
    <anchor xyz="0 0 0"/>
    <limit effort="100" k_velocity="0" velocity="100"/>
    <joint_properties damping="0.0" friction="0.0"/>
    <parent link="left_swivel"/>
    <child link="left_swivel_hubcap"/>
  </joint>
  <link name="left_swivel_wheel">
    <inertial>
      <mass value="0.1"/>
      <origin xyz="0 0 0"/>
      <inertia ixx="0.012411765597" ixy="-0.000711733678" ixz="0.00050272983" iyy="0.015218160428" iyz="-0.000004273467" izz="0.011763977943"/>
    </inertial>
    <visual name="left_swivel_wheel">
      <origin rpy="0 0 0" xyz="0 0 0"/>
      <geometry name="swivel_wheel">
        <mesh filename="package://champ_description/meshes/p3dx_meshes/center_wheel.stl"/>
      </geometry>
      <material name="WheelBlack">
        <color rgba="0.117 0.117 0.117 1"/>
      </material>
    </visual>
    <collision>
      <origin rpy=" -1.57079635 0 0" xyz="0 0 0"/>
      <geometry>
        <cylinder length="0.0422" radius="0.0669"/>
      </geometry>
    </collision>
  </link>
  <gazebo reference="swivel_wheel">
    <material value="Gazebo/Black"/>
  </gazebo>
  <joint name="left_swivel_wheel_hubcap_joint" type="fixed">
    <origin rpy="0 0 0" xyz="0 0 0"/>
    <parent link="left_swivel_hubcap"/>
    <child link="left_swivel_wheel"/>
  </joint>
  <!--Left Wheel and hub-->
  <link name="left_hubcap">
    <inertial>
      <mass value="0.08"/>
      <origin xyz="0 0 0"/>
      <inertia ixx="0.012411765597" ixy="0" ixz="0" iyy="0.015218160428" iyz="0" izz="0.011763977943"/>
    </inertial>
    <visual>
      <origin rpy="0 0 0" xyz="0 0 0"/>
      <geometry>
        <mesh filename="package://champ_description/meshes/p3dx_meshes/hubcap.stl"/>
      </geometry>
      <material name="HubcapWhite">
        <color rgba="1.0 1.0 1.0 1.0"/>
      </material>
    </visual>
    <collision>
      <origin rpy="0 0 0" xyz="0 0 0"/>
      <geometry>
        <mesh filename="package://champ_description/meshes/p3dx_meshes/hubcap.stl"/>
      </geometry>
    </collision>
  </link>
  <joint name="left_hub_joint" type="fixed">
    <origin rpy="0 0 0" xyz="0.034 0.35 -0.0835"/>
    <!--<anchor xyz="0 0 0"/>
	        <limit effort="100" velocity="100" />
	        <joint_properties damping="0.0" friction="0.0" />-->
    <parent link="base_center"/>
    <child link="left_hubcap"/>
    <axis xyz="0 1 0"/>
  </joint>
  <link name="left_wheel">
    <inertial>
      <mass value="1.25"/>
      <origin xyz="0 0 0"/>
      <inertia ixx="0.012411765597" ixy="0" ixz="0" iyy="0.015218160428" iyz="0" izz="0.011763977943"/>
    </inertial>
    <visual>
      <origin rpy="0 0 0" xyz="0 0 0"/>
      <geometry>
        <mesh filename="package://champ_description/meshes/p3dx_meshes/wheel.stl"/>
      </geometry>
      <material name="WheelBlack">
        <color rgba="0.117 0.117 0.117 1"/>
      </material>
    </visual>
    <collision>
      <origin rpy="-1.57079635 0 0" xyz="0 0 0"/>
      <geometry>
        <cylinder length="0.065" radius="0.1315"/>
      </geometry>
    </collision>
  </link>
  <joint name="left_wheel_joint" type="fixed">
    <origin rpy="0 0 0" xyz="0 0 0"/>
    <parent link="left_hubcap"/>
    <child link="left_wheel"/>
  </joint>
  <gazebo reference="left_wheel">
    <material value="Gazebo/Black"/>
  </gazebo>
  <!--Right Wheel and hub-->
  <link name="right_hubcap">
    <inertial>
      <mass value="0.08"/>
      <origin xyz="0 0 0"/>
      <inertia ixx="0.012411765597" ixy="0" ixz="0" iyy="0.015218160428" iyz="0" izz="0.011763977943"/>
    </inertial>
    <visual>
      <origin rpy="0 0 0" xyz="0 0 0"/>
      <geometry>
        <mesh filename="package://champ_description/meshes/p3dx_meshes/hubcap.stl"/>
      </geometry>
      <material name="HubcapWhite">
        <color rgba="1.0 1.0 1.0 1.0"/>
      </material>
    </visual>
    <collision>
      <origin rpy="0 0 0" xyz="0 0 0"/>
      <geometry>
        <mesh filename="package://champ_description/meshes/p3dx_meshes/hubcap.stl"/>
      </geometry>
    </collision>
  </link>
  <joint name="right_hub_joint" type="fixed">
    <origin rpy="0 0 0" xyz="0.034 -0.35 -0.0835"/>
    <!--<anchor xyz="0 0 0"/>
	        <limit effort="100" velocity="100" />
	        <joint_properties damping="0.0" friction="0.0" />-->
    <parent link="base_center"/>
    <child link="right_hubcap"/>
    <axis xyz="0 1 0"/>
  </joint>
  <link name="right_wheel">
    <inertial>
      <mass value="1.25"/>
      <origin xyz="0 0 0"/>
      <inertia ixx="0.012411765597" ixy="0" ixz="0" iyy="0.015218160428" iyz="0" izz="0.011763977943"/>
    </inertial>
    <visual>
      <origin rpy="0 0 0" xyz="0 0 0"/>
      <geometry>
        <mesh filename="package://champ_description/meshes/p3dx_meshes/wheel.stl"/>
      </geometry>
      <material name="WheelBlack">
        <color rgba="0.117 0.117 0.117 1"/>
      </material>
    </visual>
    <collision>
      <origin rpy="-1.57079635 0 0" xyz="0 0 0"/>
      <geometry>
        <cylinder length="0.065" radius="0.1315"/>
      </geometry>
    </collision>
  </link>
  <joint name="right_wheel_joint" type="fixed">
    <origin rpy="0 0 0" xyz="0 0 0"/>
    <parent link="right_hubcap"/>
    <child link="right_wheel"/>
  </joint>
  <gazebo reference="right_wheel">
    <material value="Gazebo/Black"/>
  </gazebo>
</robot>

