<?xml version="1.0"?>

<robot name="powerbot"
	xmlns:sensor="http://playerstage.sourceforge.net/gazebo/xmlschema/#sensor"
	xmlns:controller="http://playerstage.sourceforge.net/gazebo/xmlschema/#controller"
	xmlns:interface="http://playerstage.sourceforge.net/gazebo/xmlschema/#interface"
	xmlns:xacro="http://ros.org/wiki/xacro">


 <!-- robot name -->
  <xacro:macro name="powerbot" params="prefix parent_link xyz rpy">
    <joint name ="${prefix}/world_joint" type="planar">
      <parent link="${parent_link}"/>
      <child link="base_center"/>
      <origin xyz="${xyz}" rpy="${rpy}"/>
    </joint>
  </xacro:macro>

  <!-- Include powerbot wheels -->
  <xacro:include filename="$(find champ_description)/urdf/powerbot/powerbot_wheel.xacro"/>

  <!-- where to find all meshes -->
  <xacro:property name="mesh_directory" value="package://champ_description/meshes/p3dx_meshes"/>

  <!--bcz = base_center z value -->
  <xacro:property name="bcz" value="0.1315"/> <!-- 0.148 -->


<!-- Brown arm plate -->
<link name="arm_plate">
	<inertial>
		<mass value="0.01"/>	
		<origin xyz="2 0 0"/>
		<inertia ixx="1" ixy="0" ixz="0" iyy="1" iyz="0" izz="1"/>
	</inertial>
	<visual>			
		<geometry>
			<box size="0.45 0.75 0.05"/>
		</geometry>
		<origin xyz="0.2 0 0.03" rpy="0 0 0"/>
		<material name="brown">
			<color rgba="0.8 0.4 0.3 1"/>
		</material>
	</visual>
</link>

<joint name="arm_plate_joint" type="fixed">
	<parent link="top_plate"/>
	<child link="arm_plate"/>
	<origin xyz="0 0 0"/>
</joint>


<!-- Top -->
	<joint name="base_top_joint" type="fixed">
		<!--origin xyz="-0.045 0 0.325" rpy="0 0 0"/-->
		<origin xyz="-0.045 0 ${bcz + 0.177}" rpy="0 0 0"/>
		<parent link="base_center"/>
		<child link="top_plate"/>
	</joint>

	<link name="top_plate">
		<visual>
			<inertial>
				<mass value="0.01"/>	
				<origin xyz="0 0 0"/>
				<inertia ixx="1" ixy="0" ixz="0"
					 iyy="1" iyz="0"
	 				izz="1"/>
			</inertial>
			<origin xyz="0 0 0" rpy="0 0 0"/>
			<geometry name="top_geom">
				<mesh filename="${mesh_directory}/top.stl" scale="2 2 2"/>
			</geometry>

			<material name="TopBlack">
					<color rgba="0.038 0.038 0.038 1.0"/>
			</material>
		</visual>
	</link>
	<gazebo reference="top_plate">
		<material value="Gazebo/Black"/>
	</gazebo>

<!-- Chassis -->
	<link name="base_center">
		<visual name="base_visual">
			<origin xyz="-0.045 0 ${bcz}" rpy="0 0 0"/>
			<geometry name="pioneer_geom">
				<mesh filename="${mesh_directory}/chassis.stl"  scale="2 2 2"/>
			</geometry>
			<material name="ChassisYellow">
				<color rgba="0.715 0.583 0.210 1.0"/>
			</material>
		</visual>
		<collision>
			<origin xyz="0 0 0" rpy="0 0 0"/>
				<geometry>
					<mesh filename="${mesh_directory}/chassis.stl"  scale="2 2 2"/>
				</geometry>
		</collision>
	</link>
	<gazebo reference="base_center">
		<material value="Gazebo/Red"/>
	</gazebo>
<!-- Swivel2 -->

	<link name="swivel2">
		<inertial>
			<mass value="0.1"/>	
			<origin xyz="0 0 0"/>
			<inertia ixx="0.01" ixy="0" ixz="0"
				 iyy="0.01" iyz="0" izz="0.01"/>
  	 	</inertial>
	<visual name="base_visual">
		<origin xyz="-0.26 -0.25 -0.08" rpy="0 0 0"/>
		<geometry name="pioneer_geom">
			<mesh filename="${mesh_directory}/swivel.stl" scale="1.5 1.5 1.5"/>
		</geometry>
		<material name="swivel">
			<color rgba="0.5 0.5 0.5 1"/>
		</material>
	</visual>
	<collision>
		<origin xyz="0 0 0" rpy="0 0 0"/>
		<geometry>
			<box size="0.05 0.05 0.05"/>
		</geometry>
	</collision>
	</link>
	<gazebo reference="swivel2">
		<material value="Gazebo/Grey"/>
	</gazebo>
	<joint name="base_swivel_joint2" type="continuous">
		<!--origin xyz="0.045 0 0.055" rpy="0 0 0"/-->
		<origin xyz="0.045 0 ${bcz - 0.093}" rpy="0 0 0"/>
		<anchor xyz="0 0 0"/>
    	<limit effort="100" velocity="100" k_velocity="0" />
    	<joint_properties damping="0.0" friction="0.0" />
		<parent link="base_center"/>
		<child link="swivel2"/>
	</joint>

<!-- Center Wheel + Hubcap -->
	<link name="center_hubcap2">
		<inertial>
			<mass value="0.01"/>	
			<origin xyz="0 0 0"/>
			<inertia ixx="0.012411765597" ixy="-0.000711733678" ixz="0.00050272983"
				 iyy="0.015218160428" iyz="-0.000004273467" izz="0.011763977943"/>
  	 	</inertial>
	<visual name="base_visual">
		<origin xyz="-0.26 -0.25 -0.08" rpy="0 0 0"/>
		<geometry name="pioneer_geom">
			<mesh filename="${mesh_directory}/center_hubcap.stl" scale="1.5 1.5 1.5"/>
		</geometry>
		<material name="swivel">
			<color rgba="0.5 0.5 0.5 1"/>
		</material>
	</visual>
	<collision>
		<origin xyz="0 0 0" rpy="0 0 0"/>
		<geometry>
			<box size="0.05 0.05 0.05"/>
		</geometry>
	</collision>
	</link>
	<gazebo reference="center_hubcap2">
		<material value="Gazebo/Grey"/>
	</gazebo>

	<joint name="swivel_hubcap_joint2" type="continuous">
		<origin xyz="-0.026 0 -0.016" rpy="0 0 0"/>
		<axis xyz="0 1 0"/>
		<anchor xyz="0 0 0"/>
    <limit effort="100" velocity="100" k_velocity="0" />
    <joint_properties damping="0.0" friction="0.0" />
	  <parent link="swivel2"/>
		<child link="center_wheel2"/>
	</joint>

	<link name="center_wheel2">
		<inertial>
			<mass value="0.1"/>	
			<origin xyz="0 0 0"/>
			<inertia ixx="0.012411765597" ixy="-0.000711733678" ixz="0.00050272983"
				 iyy="0.015218160428" iyz="-0.000004273467" izz="0.011763977943"/>
  	 	</inertial>
	<visual name="base_visual">
		<origin xyz="-0.26 -0.25 -0.08" rpy="0 0 0"/>
		<geometry name="pioneer_geom">
			<mesh filename="${mesh_directory}/center_wheel.stl" scale="1.5 1.5 1.5"/>
		</geometry>
		<material name="WheelBlack">
			<color rgba="0.117 0.117 0.117 1"/>
		</material>
	</visual>
	<collision>
		<origin xyz="0 0 0" rpy=" 0 0 0"/>
		<geometry>
			<mesh filename="${mesh_directory}/center_wheel.stl" scale="1.5 1.5 1.5"/>
			<cylinder radius="0.0375" length="0.01"/>
		</geometry>
	</collision>
	</link>
	<gazebo reference="left_hub2">
		<material value="Gazebo/Yellow"/>
	</gazebo>

	<joint name="center_wheel_joint2" type="fixed">
		<origin xyz="-0.0035 0 -0.001" rpy="0 0 0"/>
		<parent link="center_wheel2"/>
		<child link="center_hubcap2"/>
	</joint>



  <!-- Swivel -->

	<link name="swivel">
		<inertial>
			<mass value="0.1"/>	
			<origin xyz="0 0 0"/>
			<inertia ixx="0.01" ixy="0" ixz="0"
				 iyy="0.01" iyz="0" izz="0.01"/>
  	 	</inertial>
	<visual name="base_visual">
		<origin xyz="-0.26 0.25 -0.08" rpy="0 0 0"/>
		<geometry name="pioneer_geom">
			<mesh filename="${mesh_directory}/swivel.stl" scale="1.5 1.5 1.5"/>
		</geometry>
		<material name="swivel">
			<color rgba="0.5 0.5 0.5 1"/>
		</material>
	</visual>
	<collision>
		<origin xyz="0 0 0" rpy="0 0 0"/>
		<geometry>
			<box size="0.05 0.05 0.05"/>
		</geometry>
	</collision>
	</link>
	<gazebo reference="swivel">
		<material value="Gazebo/Grey"/>
	</gazebo>
	<joint name="base_swivel_joint" type="continuous">
		<!--origin xyz="0.045 0 0.055" rpy="0 0 0"/-->
		<origin xyz="0.045 0 ${bcz - 0.093}" rpy="0 0 0"/>
		<anchor xyz="0 0 0"/>
    	<limit effort="100" velocity="100" k_velocity="0" />
    	<joint_properties damping="0.0" friction="0.0" />
		<parent link="base_center"/>
		<child link="swivel"/>
	</joint>

<!-- Center Wheel + Hubcap -->
	<link name="center_hubcap">
		<inertial>
			<mass value="0.01"/>	
			<origin xyz="0 0 0"/>
			<inertia ixx="0.012411765597" ixy="-0.000711733678" ixz="0.00050272983"
				 iyy="0.015218160428" iyz="-0.000004273467" izz="0.011763977943"/>
  	 	</inertial>
	<visual name="base_visual">
		<origin xyz="-0.26 0.25 -0.08" rpy="0 0 0"/>
		<geometry name="pioneer_geom">
			<mesh filename="${mesh_directory}/center_hubcap.stl" scale="1.5 1.5 1.5"/>
		</geometry>
		<material name="swivel">
			<color rgba="0.5 0.5 0.5 1"/>
		</material>
	</visual>
	<collision>
		<origin xyz="0 0 0" rpy="0 0 0"/>
		<geometry>
			<box size="0.05 0.05 0.05"/>
		</geometry>
	</collision>
	</link>
	<gazebo reference="center_hubcap">
		<material value="Gazebo/Grey"/>
	</gazebo>

	<joint name="swivel_hubcap_joint" type="continuous">
		<origin xyz="-0.026 0 -0.016" rpy="0 0 0"/>
		<axis xyz="0 1 0"/>
		<anchor xyz="0 0 0"/>
    <limit effort="100" velocity="100" k_velocity="0" />
    <joint_properties damping="0.0" friction="0.0" />
	  <parent link="swivel"/>
		<child link="center_wheel"/>
	</joint>

	<link name="center_wheel">
		<inertial>
			<mass value="0.1"/>	
			<origin xyz="0 0 0"/>
			<inertia ixx="0.012411765597" ixy="-0.000711733678" ixz="0.00050272983"
				 iyy="0.015218160428" iyz="-0.000004273467" izz="0.011763977943"/>
  	 	</inertial>
	<visual name="base_visual">
		<origin xyz="-0.26 0.25 -0.08" rpy="0 0 0"/>
		<geometry name="pioneer_geom">
			<mesh filename="${mesh_directory}/center_wheel.stl" scale="1.5 1.5 1.5"/>
		</geometry>
		<material name="WheelBlack">
			<color rgba="0.117 0.117 0.117 1"/>
		</material>
	</visual>
	<collision>
		<origin xyz="0 0 0" rpy=" 0 0 0"/>
		<geometry>
			<mesh filename="${mesh_directory}/center_wheel.stl" scale="1.5 1.5 1.5"/>
			<cylinder radius="0.0375" length="0.01"/>
		</geometry>
	</collision>
	</link>
	<gazebo reference="left_hub">
		<material value="Gazebo/Yellow"/>
	</gazebo>

	<joint name="center_wheel_joint" type="fixed">
		<origin xyz="-0.0035 0 -0.001" rpy="0 0 0"/>
		<parent link="center_wheel"/>
		<child link="center_hubcap"/>
	</joint>

	
	<!--Wheels-->


	<link name="left_hub">
		<visual>
			<origin xyz="0 0 0" rpy="0 0 0"/>
			<geometry>
				<mesh filename="${mesh_directory}/left_hubcap.stl" scale="1.5 1.5 1.5"/>
			</geometry>
			<material name="HubcapWhite">
				<color rgba="1.0 1.0 1.0 1.0"/>
			</material>
		</visual>
	</link>

	<joint name="left_hub_joint" type="fixed">
		<!--origin xyz="0.1 0.30 0.04" rpy="0 0 0"/-->
		<origin xyz="0.1 0.30 ${bcz - 0.108}" rpy="0 0 0"/>
		<parent link="base_center"/>
		<child link="left_hub"/>
		<axis xyz="0 1 0"/>
	</joint>

	<link name="left_wheel_joint">
		<visual>
			<origin xyz="0 0 0" rpy="0 0 0"/>
			<geometry>
				<mesh filename="${mesh_directory}/left_wheel.stl" scale="1.5 1.5 1.5"/>
			</geometry>
			<material name="WheelBlack">
				<color rgba="0.117 0.117 0.117 1"/>
			</material>
		</visual>
	</link>

	<joint name="left_wheel_joint" type="fixed">
		<origin xyz="0 0 0" rpy="0 0 0"/>
		<parent link="left_hub"/>
		<child link="left_wheel_joint"/>
	</joint>
	
	<gazebo reference="left_wheel_joint">
		<material value="Gazebo/Black"/>
	</gazebo>

	<link name="right_hub">
		<visual>
			<origin xyz="0 0 0" rpy="0 0 0"/>
			<geometry>
				<mesh filename="${mesh_directory}/right_hubcap.stl" scale="1.5 1.5 1.5"/>
			</geometry>
			<material name="HubcapWhite">
				<color rgba="1.0 1.0 1.0 1.0"/>
			</material>
		</visual>
	</link>
	<gazebo reference="right_hub">
		<material value="Gazebo/Yellow"/>
	</gazebo>

	<joint name="right_hub_joint" type="fixed">
		<!--origin xyz="0.1 -0.30 0.04" rpy="0 0 0"/-->
		<origin xyz="0.1 -0.30 ${bcz - 0.108}" rpy="0 0 0"/>
		<parent link="base_center"/>
		<child link="right_hub"/>
		<axis xyz="0 1 0"/>
	</joint>

	<link name="right_wheel_joint">
		<visual>
			<origin xyz="0 0 0" rpy="0 0 0"/>
			<geometry>
				<mesh filename="${mesh_directory}/right_wheel.stl" scale="1.5 1.5 1.5"/>
			</geometry>
			<material name="WheelBlack">
				<color rgba="0.117 0.117 0.117 1"/>
			</material>
		</visual>
	</link>

	<joint name="right_wheel_joint" type="fixed">
		<origin xyz="0 0 0" rpy="0 0 0"/>
		<parent link="right_hub"/>
		<child link="right_wheel_joint"/>
	</joint>
	<gazebo reference="right_wheel_joint">
		<material value="Gazebo/Black"/>
	</gazebo>

<!-- Front + Back Sonar -->
	<link name="front_sonar">
		<inertial>
			<mass value="0.0001"/>	
			<origin xyz="0 0 0"/>
			<inertia ixx="1" ixy="0" ixz="0"
				 iyy="1" iyz="0" izz="1"/>
		</inertial>
		<visual name="base_visual">
			<origin xyz="-0.17 0 0.065" rpy="0 0 0"/>
			<geometry name="pioneer_geom">
				<mesh filename="${mesh_directory}/front_sonar.stl" scale="2 2 2"/>
			</geometry>
			<material name="SonarBrown">
				<color rgba="0.206 0.166 0.006 1.0"/>
			</material>
		</visual>
		<collision>
			<origin xyz="0 0 0" rpy="0 0 0"/>
			<geometry>
				<mesh filename="${mesh_directory}/front_sonar.stl" scale="2 2 2"/>
			</geometry>
		</collision>
	</link>

	<gazebo reference="front_sonar">
		<material value="Gazebo/Yellow"/>
	</gazebo>

	<joint name="base_front_joint" type="fixed">
		<!--origin xyz="-0.198 0 0.208" rpy="0 0 0"/-->
		<origin xyz="-0.198 0 ${bcz + 0.06}" rpy="0 0 0"/>
		<parent link="base_center"/>
		<child link="front_sonar"/>
	</joint>

	<link name="back_sonar">
		<inertial>
			<mass value="0.0001"/>	
			<origin xyz="0 0 0"/>
			<inertia ixx="1" ixy="0" ixz="0"
				 iyy="1" iyz="0" izz="1"/>
		</inertial>
		<visual name="back_sonar_vis">
			<origin xyz="0.17 0 0.064" rpy="0 0 0"/>
			<geometry name="pioneer_geom">
				<mesh filename="${mesh_directory}/back_sonar.stl" scale="2 2 2"/>
			</geometry>
			<material name="SonarBrown">
				<color rgba="0.206 0.166 0.006 1.0"/>
			</material>
		</visual>
		<collision>
			<origin xyz="0 0 0" rpy="0 0 0"/>
			<geometry>
				<mesh filename="${mesh_directory}/back_sonar.stl" scale="2 2 2"/>
			</geometry>
		</collision>
	</link>

	<gazebo reference="back_sonar">
		<material value="Gazebo/Yellow"/>
	</gazebo>

	<joint name="base_back_joint" type="fixed">
		<!--origin xyz="0.109 0 0.209" rpy="0 0 0"/-->
		<origin xyz="0.109 0 ${bcz + 0.061}" rpy="0 0 0"/>
		<parent link="base_center"/>
		<child link="back_sonar"/>
	</joint>

<xacro:macro name="p3at_gazebo_ext">

<gazebo>
  <plugin name="skid_steer_drive_controller" filename="libgazebo_ros_skid_steer_drive.so">
    <updateRate>100.0</updateRate>
    <robotNamespace>/</robotNamespace>
    <leftJoint>base_right_wheel_joint</leftJoint>
    <rightJoint>base_left_wheel_joint</rightJoint>
    <wheelSeparation>0.39</wheelSeparation>
    <wheelDiameter>0.15</wheelDiameter>
    <robotBaseFrame>base_center</robotBaseFrame>
    <torque>200</torque>
    <topicName>cmd_vel</topicName>
  </plugin>
</gazebo>

</xacro:macro>

</robot>
