<sdf version='1.6'>
  <world name='default'>
    <light name='sun' type='directional'>
      <cast_shadows>1</cast_shadows>
      <pose frame=''>0 0 10 0 -0 0</pose>
      <diffuse>0.8 0.8 0.8 1</diffuse>
      <specular>0.1 0.1 0.1 1</specular>
      <attenuation>
        <range>1000</range>
        <constant>0.9</constant>
        <linear>0.01</linear>
        <quadratic>0.001</quadratic>
      </attenuation>
      <direction>-0.5 0.5 -1</direction>
    </light>
    <model name='ground_plane'>
      <static>1</static>
      <link name='link'>
        <collision name='collision'>
          <geometry>
            <plane>
              <normal>0 0 1</normal>
              <size>100 100</size>
            </plane>
          </geometry>
          <surface>
            <friction>
              <ode>
                <mu>100</mu>
                <mu2>50</mu2>
              </ode>
              <torsional>
                <ode/>
              </torsional>
            </friction>
            <contact>
              <ode/>
            </contact>
            <bounce/>
          </surface>
          <max_contacts>10</max_contacts>
        </collision>
        <visual name='visual'>
          <cast_shadows>0</cast_shadows>
          <geometry>
            <plane>
              <normal>0 0 1</normal>
              <size>100 100</size>
            </plane>
          </geometry>
          <material>
            <script>
              <uri>file://media/materials/scripts/gazebo.material</uri>
              <name>Gazebo/Grey</name>
            </script>
          </material>
        </visual>
        <self_collide>0</self_collide>
        <kinematic>0</kinematic>
        <gravity>1</gravity>
      </link>
    </model>
    <physics name='default_physics' default='0' type='ode'>
      <max_step_size>0.01</max_step_size>
      <real_time_factor>1</real_time_factor>
      <real_time_update_rate>100</real_time_update_rate>
    </physics>
    <gravity>0 0 -9.8</gravity>
    <magnetic_field>6e-06 2.3e-05 -4.2e-05</magnetic_field>
    <atmosphere type='adiabatic'/>
    <scene>
      <ambient>0.4 0.4 0.4 1</ambient>
      <background>0.7 0.7 0.7 1</background>
      <shadows>1</shadows>
    </scene>
    <spherical_coordinates>
      <surface_model>EARTH_WGS84</surface_model>
      <latitude_deg>0</latitude_deg>
      <longitude_deg>0</longitude_deg>
      <elevation>0</elevation>
      <heading_deg>0</heading_deg>
    </spherical_coordinates>
    <state world_name='default'>
      <sim_time>1507 140000000</sim_time>
      <real_time>978 100063947</real_time>
      <wall_time>1509616010 372035315</wall_time>
      <iterations>97717</iterations>
      <model name='ground_plane'>
        <pose frame=''>0 0 0 0 -0 0</pose>
        <scale>1 1 1</scale>
        <link name='link'>
          <pose frame=''>0 0 0 0 -0 0</pose>
          <velocity>0 0 0 0 -0 0</velocity>
          <acceleration>0 0 0 0 -0 0</acceleration>
          <wrench>0 0 0 0 -0 0</wrench>
        </link>
      </model>
      <model name='wam_powerbot'>
        <pose frame=''>-0.009341 -0.004444 0.143368 -3e-06 -0.00076 0.033241</pose>
        <scale>1 1 1</scale>
        <link name='base_center'>
          <pose frame=''>-0.009341 -0.004444 0.143368 -3e-06 -0.00076 0.033241</pose>
          <velocity>-0.01413 -0.00256 -0.016372 0.017839 -0.098385 7e-06</velocity>
          <acceleration>-2.5359 -0.702607 -2.92897 -3.00368 0.691082 -0.013484</acceleration>
          <wrench>-307.554 -85.2122 -355.226 0 -0 0</wrench>
        </link>
        <link name='wam/bhand/finger_1/dist_link'>
          <pose frame=''>0.545439 -0.017878 0.061159 0.402621 1.449 -2.02292</pose>
          <velocity>-0.061307 0.006417 -0.005973 0.009776 -0.008799 0.001027</velocity>
          <acceleration>-2.38681 0.019596 9.07871 0.773827 -0.724475 0.929635</acceleration>
          <wrench>-0.17365 0.001426 0.660512 0 -0 0</wrench>
        </link>
        <link name='wam/bhand/finger_1/med_link'>
          <pose frame=''>0.579997 -0.048809 0.113555 -1.40895 0.804168 2.40122</pose>
          <velocity>-0.062179 0.006454 -0.006287 0.001482 -0.015989 0.002256</velocity>
          <acceleration>-2.45754 0.035021 8.96829 -2.97823 -1.03095 -1.46757</acceleration>
          <wrench>-0.152709 0.002176 0.55728 0 -0 0</wrench>
        </link>
        <link name='wam/bhand/finger_1/prox_link'>
          <pose frame=''>0.616084 -0.084953 0.145854 -3.02953 -0.02807 2.281</pose>
          <velocity>-0.062938 0.007169 -0.003754 -0.017558 -0.032449 0.005086</velocity>
          <acceleration>-2.5061 0.074278 9.17389 -2.62154 -0.934202 -2.11485</acceleration>
          <wrench>-0.353586 0.01048 1.29434 0 -0 0</wrench>
        </link>
        <link name='wam/bhand/finger_2/dist_link'>
          <pose frame=''>0.690466 -0.028344 0.030899 1.55979 0.308875 -2.59142</pose>
          <velocity>-0.060342 0.005093 -0.002024 -0.019355 -0.012285 0.00197</velocity>
          <acceleration>-2.37892 -0.015317 9.3034 0.087362 -0.239077 0.066797</acceleration>
          <wrench>-0.173076 -0.001114 0.67686 0 -0 0</wrench>
        </link>
        <link name='wam/bhand/finger_2/med_link'>
          <pose frame=''>0.692372 -0.028021 0.100845 -1.02283 1.55068 1.1014</pose>
          <velocity>-0.061696 0.006241 -0.00279 -0.015923 -0.017931 0.001903</velocity>
          <acceleration>-2.41541 -0.025155 9.15645 0.338757 -0.671794 0.113582</acceleration>
          <wrench>-0.150091 -0.001563 0.568973 0 -0 0</wrench>
        </link>
        <link name='wam/bhand/finger_2/prox_link'>
          <pose frame=''>0.653664 -0.052434 0.140298 -3.13105 0.115289 0.55474</pose>
          <velocity>-0.062366 0.006695 -0.002531 -0.014284 -0.020586 0.001864</velocity>
          <acceleration>-2.40081 -0.02546 9.31456 -0.314572 0.72661 0.078346</acceleration>
          <wrench>-0.33873 -0.003592 1.31419 0 -0 0</wrench>
        </link>
        <link name='wam/bhand/finger_3/dist_link'>
          <pose frame=''>0.657239 -0.112505 0.038399 1.69812 0.497079 2.34507</pose>
          <velocity>-0.062081 0.005669 -0.00208 0.003002 -0.005964 -0.014934</velocity>
          <acceleration>-2.62137 -0.145441 9.23944 -1.22311 0.617576 -2.97899</acceleration>
          <wrench>-0.190715 -0.010581 0.672206 0 -0 0</wrench>
        </link>
        <link name='wam/bhand/finger_3/med_link'>
          <pose frame=''>0.663984 -0.108331 0.108062 -2.91993 1.45613 -2.20521</pose>
          <velocity>-0.062429 0.005722 0.00058 -0.003394 -0.011166 -0.014043</velocity>
          <acceleration>-2.64857 -0.152592 9.75991 -1.30592 -0.015667 1.54629</acceleration>
          <wrench>-0.164579 -0.009482 0.606471 0 -0 0</wrench>
        </link>
        <link name='wam/forearm_link'>
          <pose frame=''>0.642422 -0.066658 0.547849 1.5587 -0.139401 2.99509</pose>
          <velocity>-0.066304 0.003554 0.015064 0.011748 -0.02124 0.034289</velocity>
          <acceleration>-1.72851 -0.712687 12.961 -0.332248 -0.873714 2.24391</acceleration>
          <wrench>-0.864543 -0.356463 6.48268 0 -0 0</wrench>
        </link>
        <link name='wam/shoulder_pitch_link'>
          <pose frame=''>0.164768 0.001404 0.816365 1.57362 1.15417 3.00172</pose>
          <velocity>-0.086963 -0.013709 -0.002254 -0.035022 -0.261986 0.034338</velocity>
          <acceleration>-10.714 -2.48178 0.145433 -1.19719 -0.070773 0.453933</acceleration>
          <wrench>-41.5159 -9.61676 0.563543 0 -0 0</wrench>
        </link>
        <link name='wam/shoulder_yaw_link'>
          <pose frame=''>0.164832 0.001387 0.816521 0.000153 -0.001115 -0.142855</pose>
          <velocity>-0.085433 -0.013884 0.001328 0.01709 -0.106842 0.024737</velocity>
          <acceleration>-8.90028 -2.16863 -0.30347 0.257587 -0.651817 2.28098</acceleration>
          <wrench>-44.5014 -10.8431 -1.51735 0 -0 0</wrench>
        </link>
        <link name='wam/upper_arm_link'>
          <pose frame=''>0.164603 0.00143 0.815521 3.11256 1.14599 2.96696</pose>
          <velocity>-0.090793 -0.013322 -0.021672 0.001344 -0.081011 0.034504</velocity>
          <acceleration>-5.15751 -1.48378 8.63998 1.70028 0.239568 1.94427</acceleration>
          <wrench>-11.3583 -3.26769 19.0277 0 -0 0</wrench>
        </link>
        <link name='wam/wrist_palm_link'>
          <pose frame=''>0.645407 -0.063513 0.244045 -3.11265 0.111861 0.713354</pose>
          <velocity>-0.063526 0.008395 0.000655 -0.01805 -0.014035 -0.013197</velocity>
          <acceleration>-2.41487 -0.014003 10.002 0.796671 0.805465 -2.6583</acceleration>
          <wrench>-1.42138 -0.008242 5.88713 0 -0 0</wrench>
        </link>
        <link name='wam/wrist_pitch_link'>
          <pose frame=''>0.645506 -0.063498 0.244213 1.68291 0.005527 1.97366</pose>
          <velocity>-0.063701 0.007982 0.005281 0.000753 -0.011213 0.000889</velocity>
          <acceleration>-2.61046 -0.099954 11.0521 2.28962 0.585022 1.18896</acceleration>
          <wrench>-1.35215 -0.051774 5.72468 0 -0 0</wrench>
        </link>
        <link name='wam/wrist_yaw_link'>
          <pose frame=''>0.645628 -0.06346 0.244263 -3.02886 -0.082046 1.96363</pose>
          <velocity>-0.063172 0.007803 0.00877 0.005752 -0.032614 -0.00056</velocity>
          <acceleration>-2.56972 -0.210192 11.7819 -0.106718 0.309353 1.10831</acceleration>
          <wrench>-2.70787 -0.221492 12.4153 0 -0 0</wrench>
        </link>
      </model>
      <light name='sun'>
        <pose frame=''>0 0 10 0 -0 0</pose>
      </light>
    </state>
    <gui fullscreen='0'>
      <camera name='user_camera'>
        <pose frame=''>-0.20525 -1.84023 0.605124 0 0.10544 1.35515</pose>
        <view_controller>orbit</view_controller>
        <projection_type>perspective</projection_type>
      </camera>
    </gui>
    <model name='wam_powerbot'>
      <link name='base_center'>
        <pose frame=''>0 0 0 0 -0 0</pose>
        <inertial>
          <pose frame=''>-0.042604 1e-06 0.069887 0 -0 0</pose>
          <mass>121.28</mass>
          <inertia>
            <ixx>3.19895</ixx>
            <ixy>-5.46967e-05</ixy>
            <ixz>-0.083771</ixz>
            <iyy>3.27371</iyy>
            <iyz>-7.94819e-05</iyz>
            <izz>3.17692</izz>
          </inertia>
        </inertial>
        <collision name='base_center_collision'>
          <pose frame=''>-0.045 0 0.067 0 -0 0</pose>
          <geometry>
            <mesh>
              <scale>1 1 1</scale>
              <uri>/home/sicelukwanda/catkin_ws/src/champ_description/meshes/p3dx_meshes/chassis.stl</uri>
            </mesh>
          </geometry>
          <surface>
            <contact>
              <ode/>
            </contact>
            <friction>
              <ode/>
              <torsional>
                <ode/>
              </torsional>
            </friction>
            <bounce/>
          </surface>
          <max_contacts>10</max_contacts>
        </collision>
        <collision name='base_center_fixed_joint_lump__top_plate_collision_1'>
          <pose frame=''>-0.045 0 0.277 0 -0 0</pose>
          <geometry>
            <mesh>
              <scale>1 1 1</scale>
              <uri>/home/sicelukwanda/catkin_ws/src/champ_description/meshes/p3dx_meshes/top.stl</uri>
            </mesh>
          </geometry>
          <surface>
            <contact>
              <ode/>
            </contact>
            <friction>
              <ode/>
              <torsional>
                <ode/>
              </torsional>
            </friction>
            <bounce/>
          </surface>
          <max_contacts>10</max_contacts>
        </collision>
        <collision name='base_center_fixed_joint_lump__arm_plate_collision_2'>
          <pose frame=''>0.155 0 0.307 0 -0 0</pose>
          <geometry>
            <box>
              <size>0.45 0.75 0.05</size>
            </box>
          </geometry>
          <max_contacts>10</max_contacts>
          <surface>
            <contact>
              <ode/>
            </contact>
            <bounce/>
            <friction>
              <torsional>
                <ode/>
              </torsional>
              <ode/>
            </friction>
          </surface>
        </collision>
        <collision name='base_center_fixed_joint_lump__wam/base_link_collision_3'>
          <pose frame=''>0.175 0 0.327 0 -0 0</pose>
          <geometry>
            <mesh>
              <scale>1 1 1</scale>
              <uri>/home/sicelukwanda/catkin_ws/src/champ_description/meshes/sw_meshes/base_link_convex.dae</uri>
            </mesh>
          </geometry>
          <max_contacts>10</max_contacts>
          <surface>
            <contact>
              <ode/>
            </contact>
            <bounce/>
            <friction>
              <torsional>
                <ode/>
              </torsional>
              <ode/>
            </friction>
          </surface>
        </collision>
        <collision name='base_center_fixed_joint_lump__camera_link_collision_4'>
          <pose frame=''>0.358359 0.000907 0.459741 0.020264 0.315979 0.013426</pose>
          <geometry>
            <box>
              <size>0.073 0.276 0.072</size>
            </box>
          </geometry>
          <surface>
            <contact>
              <ode/>
            </contact>
            <friction>
              <ode/>
              <torsional>
                <ode/>
              </torsional>
            </friction>
            <bounce/>
          </surface>
          <max_contacts>10</max_contacts>
        </collision>
        <visual name='base_center_fixed_joint_lump__base_visual_visual'>
          <pose frame=''>-0.045 0 0.067 0 -0 0</pose>
          <geometry>
            <mesh>
              <scale>1 1 1</scale>
              <uri>/home/sicelukwanda/catkin_ws/src/champ_description/meshes/p3dx_meshes/chassis.stl</uri>
            </mesh>
          </geometry>
        </visual>
        <visual name='base_center_fixed_joint_lump__top_plate_visual_1'>
          <pose frame=''>-0.045 0 0.277 0 -0 0</pose>
          <geometry>
            <mesh>
              <scale>1 1 1</scale>
              <uri>/home/sicelukwanda/catkin_ws/src/champ_description/meshes/p3dx_meshes/top.stl</uri>
            </mesh>
          </geometry>
          <material>
            <script>
              <name>Gazebo/Black</name>
              <uri>file://media/materials/scripts/gazebo.material</uri>
            </script>
          </material>
        </visual>
        <visual name='base_center_fixed_joint_lump__arm_plate_visual_2'>
          <pose frame=''>0.155 0 0.307 0 -0 0</pose>
          <geometry>
            <box>
              <size>0.45 0.75 0.05</size>
            </box>
          </geometry>
        </visual>
        <visual name='base_center_fixed_joint_lump__wam/base_link_visual_3'>
          <pose frame=''>0.175 0 0.327 0 -0 0</pose>
          <geometry>
            <mesh>
              <scale>1 1 1</scale>
              <uri>/home/sicelukwanda/catkin_ws/src/champ_description/meshes/sw_meshes/base_link_fine.stl</uri>
            </mesh>
          </geometry>
        </visual>
        <visual name='base_center_fixed_joint_lump__camera_link_visual_4'>
          <pose frame=''>0.345322 0.004151 0.468271 0.020264 0.315979 0.013426</pose>
          <geometry>
            <mesh>
              <scale>1 1 1</scale>
              <uri>/home/sicelukwanda/catkin_ws/src/champ_description/meshes/sensors/xtion_pro_camera.dae</uri>
            </mesh>
          </geometry>
          <material>
            <script>
              <uri>__default__</uri>
              <name>__default__</name>
            </script>
          </material>
        </visual>
        <velocity_decay/>
        <velocity_decay/>
        <gravity>1</gravity>
        <velocity_decay/>
        <self_collide>0</self_collide>
        <sensor name='camera' type='depth'>
          <always_on>1</always_on>
          <update_rate>20</update_rate>
          <camera name='__default__'>
            <horizontal_fov>1.0472</horizontal_fov>
            <image>
              <format>B8G8R8</format>
              <width>640</width>
              <height>480</height>
            </image>
            <clip>
              <near>0.05</near>
              <far>8</far>
            </clip>
          </camera>
          <plugin name='kinect_camera_controller' filename='libgazebo_ros_openni_kinect.so'>
            <robotNamespace>/wam_powerbot</robotNamespace>
            <cameraName>camera</cameraName>
            <alwaysOn>true</alwaysOn>
            <updateRate>10</updateRate>
            <imageTopicName>rgb/image_raw</imageTopicName>
            <depthImageTopicName>depth/image_raw</depthImageTopicName>
            <pointCloudTopicName>depth/points</pointCloudTopicName>
            <cameraInfoTopicName>rgb/camera_info</cameraInfoTopicName>
            <depthImageCameraInfoTopicName>depth/camera_info</depthImageCameraInfoTopicName>
            <frameName>camera_depth_optical_frame</frameName>
            <baseline>0.1</baseline>
            <distortion_k1>0.0</distortion_k1>
            <distortion_k2>0.0</distortion_k2>
            <distortion_k3>0.0</distortion_k3>
            <distortion_t1>0.0</distortion_t1>
            <distortion_t2>0.0</distortion_t2>
            <pointCloudCutoff>0.4</pointCloudCutoff>
          </plugin>
          <pose frame=''>0.358359 0.000907 0.459741 0.020264 0.315979 0.013426</pose>
        </sensor>
        <kinematic>0</kinematic>
      </link>
      <link name='wam/shoulder_yaw_link'>
        <pose frame=''>0.175 0 0.673 0 -0 0</pose>
        <inertial>
          <pose frame=''>-0.004434 -0.000665 -0.128904 0 -0 0</pose>
          <mass>5</mass>
          <inertia>
            <ixx>0.13488</ixx>
            <ixy>-0.00012485</ixy>
            <ixz>0.00213041</ixz>
            <iyy>0.0904633</iyy>
            <iyz>-0.00068555</iyz>
            <izz>0.113284</izz>
          </inertia>
        </inertial>
        <collision name='wam/shoulder_yaw_link_collision'>
          <pose frame=''>0 0 0 0 -0 0</pose>
          <geometry>
            <mesh>
              <scale>1 1 1</scale>
              <uri>/home/sicelukwanda/catkin_ws/src/champ_description/meshes/sw_meshes/shoulder_link_convex_decomposition.dae</uri>
            </mesh>
          </geometry>
          <max_contacts>10</max_contacts>
          <surface>
            <contact>
              <ode/>
            </contact>
            <bounce/>
            <friction>
              <torsional>
                <ode/>
              </torsional>
              <ode/>
            </friction>
          </surface>
        </collision>
        <visual name='wam/shoulder_yaw_link_visual'>
          <pose frame=''>0 0 0 0 -0 0</pose>
          <geometry>
            <mesh>
              <scale>1 1 1</scale>
              <uri>/home/sicelukwanda/catkin_ws/src/champ_description/meshes/sw_meshes/shoulder_link_fine.stl</uri>
            </mesh>
          </geometry>
        </visual>
        <self_collide>0</self_collide>
        <kinematic>0</kinematic>
        <gravity>1</gravity>
      </link>
      <joint name='wam/base_yaw_joint' type='revolute'>
        <child>wam/shoulder_yaw_link</child>
        <parent>base_center</parent>
        <axis>
          <xyz>0 0 1</xyz>
          <limit>
            <lower>-2.6</lower>
            <upper>2.6</upper>
            <effort>60</effort>
            <velocity>2</velocity>
          </limit>
          <dynamics>
            <damping>1.98</damping>
            <friction>0</friction>
            <spring_reference>0</spring_reference>
            <spring_stiffness>0</spring_stiffness>
          </dynamics>
          <use_parent_model_frame>1</use_parent_model_frame>
        </axis>
        <physics>
          <provide_feedback>1</provide_feedback>
          <ode>
            <provide_feedback>1</provide_feedback>
            <implicit_spring_damper>1</implicit_spring_damper>
            <cfm_damping>1</cfm_damping>
            <limit>
              <cfm>0</cfm>
              <erp>0.2</erp>
            </limit>
          </ode>
        </physics>
      </joint>
      <link name='wam/shoulder_pitch_link'>
        <pose frame=''>0.175 0 0.673 -1.5708 0 0</pose>
        <inertial>
          <pose frame=''>-0.00237 -0.015421 0.031056 0 -0 0</pose>
          <mass>3.87494</mass>
          <inertia>
            <ixx>0.0214096</ixx>
            <ixy>-2.461e-05</ixy>
            <ixz>0.00027172</ixz>
            <iyy>0.0155891</iyy>
            <iyz>0.0018192</iyz>
            <izz>0.0137787</izz>
          </inertia>
        </inertial>
        <collision name='wam/shoulder_pitch_link_collision'>
          <pose frame=''>0 0 0 0 -0 0</pose>
          <geometry>
            <mesh>
              <scale>1 1 1</scale>
              <uri>/home/sicelukwanda/catkin_ws/src/champ_description/meshes/sw_meshes/shoulder_pitch_link_convex.dae</uri>
            </mesh>
          </geometry>
          <max_contacts>10</max_contacts>
          <surface>
            <contact>
              <ode/>
            </contact>
            <bounce/>
            <friction>
              <torsional>
                <ode/>
              </torsional>
              <ode/>
            </friction>
          </surface>
        </collision>
        <visual name='wam/shoulder_pitch_link_visual'>
          <pose frame=''>0 0 0 0 -0 0</pose>
          <geometry>
            <mesh>
              <scale>1 1 1</scale>
              <uri>/home/sicelukwanda/catkin_ws/src/champ_description/meshes/sw_meshes/shoulder_pitch_link_fine.stl</uri>
            </mesh>
          </geometry>
        </visual>
        <self_collide>0</self_collide>
        <kinematic>0</kinematic>
        <gravity>1</gravity>
      </link>
      <joint name='wam/shoulder_pitch_joint' type='revolute'>
        <child>wam/shoulder_pitch_link</child>
        <parent>wam/shoulder_yaw_link</parent>
        <axis>
          <xyz>0 1 0</xyz>
          <limit>
            <lower>-1.985</lower>
            <upper>1.985</upper>
            <effort>60</effort>
            <velocity>2</velocity>
          </limit>
          <dynamics>
            <damping>0.55</damping>
            <friction>0</friction>
            <spring_reference>0</spring_reference>
            <spring_stiffness>0</spring_stiffness>
          </dynamics>
          <use_parent_model_frame>1</use_parent_model_frame>
        </axis>
        <physics>
          <provide_feedback>1</provide_feedback>
          <ode>
            <provide_feedback>1</provide_feedback>
            <implicit_spring_damper>1</implicit_spring_damper>
            <cfm_damping>1</cfm_damping>
            <limit>
              <cfm>0</cfm>
              <erp>0.2</erp>
            </limit>
          </ode>
        </physics>
      </joint>
      <link name='wam/upper_arm_link'>
        <pose frame=''>0.175 0 0.673 0 -0 0</pose>
        <inertial>
          <pose frame=''>0.006833 3.3e-05 0.392492 0 -0 0</pose>
          <mass>2.20228</mass>
          <inertia>
            <ixx>0.0591108</ixx>
            <ixy>-7.38e-06</ixy>
            <ixz>-0.00249612</ixz>
            <iyy>0.0592704</iyy>
            <iyz>1.767e-05</iyz>
            <izz>0.0032455</izz>
          </inertia>
        </inertial>
        <collision name='wam/upper_arm_link_collision'>
          <pose frame=''>0 0 0 0 -0 0</pose>
          <geometry>
            <mesh>
              <scale>1 1 1</scale>
              <uri>/home/sicelukwanda/catkin_ws/src/champ_description/meshes/sw_meshes/upper_arm_link_convex_decomposition.dae</uri>
            </mesh>
          </geometry>
          <max_contacts>10</max_contacts>
          <surface>
            <contact>
              <ode/>
            </contact>
            <bounce/>
            <friction>
              <torsional>
                <ode/>
              </torsional>
              <ode/>
            </friction>
          </surface>
        </collision>
        <visual name='wam/upper_arm_link_visual'>
          <pose frame=''>0 0 0 0 -0 0</pose>
          <geometry>
            <mesh>
              <scale>1 1 1</scale>
              <uri>/home/sicelukwanda/catkin_ws/src/champ_description/meshes/sw_meshes/upper_arm_link_fine.stl</uri>
            </mesh>
          </geometry>
        </visual>
        <self_collide>0</self_collide>
        <kinematic>0</kinematic>
        <gravity>1</gravity>
      </link>
      <joint name='wam/shoulder_yaw_joint' type='revolute'>
        <child>wam/upper_arm_link</child>
        <parent>wam/shoulder_pitch_link</parent>
        <axis>
          <xyz>0 0 1</xyz>
          <limit>
            <lower>-2.8</lower>
            <upper>2.8</upper>
            <effort>45</effort>
            <velocity>2</velocity>
          </limit>
          <dynamics>
            <damping>1.65</damping>
            <friction>0</friction>
            <spring_reference>0</spring_reference>
            <spring_stiffness>0</spring_stiffness>
          </dynamics>
          <use_parent_model_frame>1</use_parent_model_frame>
        </axis>
        <physics>
          <provide_feedback>1</provide_feedback>
          <ode>
            <provide_feedback>1</provide_feedback>
            <implicit_spring_damper>1</implicit_spring_damper>
            <cfm_damping>1</cfm_damping>
            <limit>
              <cfm>0</cfm>
              <erp>0.2</erp>
            </limit>
          </ode>
        </physics>
      </joint>
      <link name='wam/forearm_link'>
        <pose frame=''>0.22 0 1.223 -1.5708 0 0</pose>
        <inertial>
          <pose frame=''>-0.040015 -0.142717 -0.000229 0 -0 0</pose>
          <mass>0.500168</mass>
          <inertia>
            <ixx>0.0149167</ixx>
            <ixy>0.00150604</ixy>
            <ixz>1.741e-05</ixz>
            <iyy>0.00294463</iyy>
            <iyz>2.109e-05</iyz>
            <izz>0.0148299</izz>
          </inertia>
        </inertial>
        <collision name='wam/forearm_link_collision'>
          <pose frame=''>0 0 0 0 -0 0</pose>
          <geometry>
            <mesh>
              <scale>1 1 1</scale>
              <uri>/home/sicelukwanda/catkin_ws/src/champ_description/meshes/sw_meshes/elbow_link_convex.dae</uri>
            </mesh>
          </geometry>
          <max_contacts>10</max_contacts>
          <surface>
            <contact>
              <ode/>
            </contact>
            <bounce/>
            <friction>
              <torsional>
                <ode/>
              </torsional>
              <ode/>
            </friction>
          </surface>
        </collision>
        <collision name='wam/forearm_link_collision_1'>
          <pose frame=''>-0.045 -0.073 0 1.5708 -0 0</pose>
          <geometry>
            <mesh>
              <scale>1 1 1</scale>
              <uri>/home/sicelukwanda/catkin_ws/src/champ_description/meshes/sw_meshes/forearm_link_convex_decomposition.dae</uri>
            </mesh>
          </geometry>
          <max_contacts>10</max_contacts>
          <surface>
            <contact>
              <ode/>
            </contact>
            <bounce/>
            <friction>
              <torsional>
                <ode/>
              </torsional>
              <ode/>
            </friction>
          </surface>
        </collision>
        <visual name='wam/forearm_link_visual'>
          <pose frame=''>0 0 0 0 -0 0</pose>
          <geometry>
            <mesh>
              <scale>1 1 1</scale>
              <uri>/home/sicelukwanda/catkin_ws/src/champ_description/meshes/sw_meshes/elbow_link_fine.stl</uri>
            </mesh>
          </geometry>
        </visual>
        <visual name='wam/forearm_link_visual_1'>
          <pose frame=''>-0.045 -0.073 0 1.5708 -0 0</pose>
          <geometry>
            <mesh>
              <scale>1 1 1</scale>
              <uri>/home/sicelukwanda/catkin_ws/src/champ_description/meshes/sw_meshes/forearm_link_fine.stl</uri>
            </mesh>
          </geometry>
        </visual>
        <self_collide>0</self_collide>
        <kinematic>0</kinematic>
        <gravity>1</gravity>
      </link>
      <joint name='wam/elbow_pitch_joint' type='revolute'>
        <child>wam/forearm_link</child>
        <parent>wam/upper_arm_link</parent>
        <axis>
          <xyz>0 1 0</xyz>
          <limit>
            <lower>-0.9</lower>
            <upper>3.14159</upper>
            <effort>30</effort>
            <velocity>2</velocity>
          </limit>
          <dynamics>
            <damping>0.88</damping>
            <friction>0</friction>
            <spring_reference>0</spring_reference>
            <spring_stiffness>0</spring_stiffness>
          </dynamics>
          <use_parent_model_frame>1</use_parent_model_frame>
        </axis>
        <physics>
          <provide_feedback>1</provide_feedback>
          <ode>
            <provide_feedback>1</provide_feedback>
            <implicit_spring_damper>1</implicit_spring_damper>
            <cfm_damping>1</cfm_damping>
            <limit>
              <cfm>0</cfm>
              <erp>0.2</erp>
            </limit>
          </ode>
        </physics>
      </joint>
      <link name='wam/wrist_yaw_link'>
        <pose frame=''>0.175 -0 1.523 0 -0 0</pose>
        <inertial>
          <pose frame=''>8.9e-05 0.004358 -0.005112 0 -0 0</pose>
          <mass>1.05376</mass>
          <inertia>
            <ixx>5.029e-05</ixx>
            <ixy>2e-07</ixy>
            <ixz>7.582e-05</ixz>
            <iyy>7.582e-05</iyy>
            <iyz>-3.59e-06</iyz>
            <izz>6.27e-05</izz>
          </inertia>
        </inertial>
        <collision name='wam/wrist_yaw_link_collision'>
          <pose frame=''>0 0 0 0 -0 0</pose>
          <geometry>
            <mesh>
              <scale>1 1 1</scale>
              <uri>/home/sicelukwanda/catkin_ws/src/champ_description/meshes/sw_meshes/wrist_yaw_link_convex_decomposition.dae</uri>
            </mesh>
          </geometry>
          <max_contacts>10</max_contacts>
          <surface>
            <contact>
              <ode/>
            </contact>
            <bounce/>
            <friction>
              <torsional>
                <ode/>
              </torsional>
              <ode/>
            </friction>
          </surface>
        </collision>
        <visual name='wam/wrist_yaw_link_visual'>
          <pose frame=''>0 0 0 0 -0 0</pose>
          <geometry>
            <mesh>
              <scale>1 1 1</scale>
              <uri>/home/sicelukwanda/catkin_ws/src/champ_description/meshes/sw_meshes/wrist_yaw_link_fine.stl</uri>
            </mesh>
          </geometry>
        </visual>
        <self_collide>0</self_collide>
        <kinematic>0</kinematic>
        <gravity>1</gravity>
      </link>
      <joint name='wam/wrist_yaw_joint' type='revolute'>
        <child>wam/wrist_yaw_link</child>
        <parent>wam/forearm_link</parent>
        <axis>
          <xyz>0 0 1</xyz>
          <limit>
            <lower>-4.55</lower>
            <upper>1.25</upper>
            <effort>10</effort>
            <velocity>2</velocity>
          </limit>
          <dynamics>
            <damping>0.55</damping>
            <friction>0</friction>
            <spring_reference>0</spring_reference>
            <spring_stiffness>0</spring_stiffness>
          </dynamics>
          <use_parent_model_frame>1</use_parent_model_frame>
        </axis>
        <physics>
          <provide_feedback>1</provide_feedback>
          <ode>
            <provide_feedback>1</provide_feedback>
            <implicit_spring_damper>1</implicit_spring_damper>
            <cfm_damping>1</cfm_damping>
            <limit>
              <cfm>0</cfm>
              <erp>0.2</erp>
            </limit>
          </ode>
        </physics>
      </joint>
      <link name='wam/wrist_pitch_link'>
        <pose frame=''>0.175 -0 1.523 -1.5708 0 0</pose>
        <inertial>
          <pose frame=''>-0.000123 -0.024683 -0.017032 0 -0 0</pose>
          <mass>0.517974</mass>
          <inertia>
            <ixx>0.00055516</ixx>
            <ixy>6.1e-07</ixy>
            <ixz>-7.4e-07</ixz>
            <iyy>0.00024367</iyy>
            <iyz>-4.59e-05</iyz>
            <izz>0.00045358</izz>
          </inertia>
        </inertial>
        <collision name='wam/wrist_pitch_link_collision'>
          <pose frame=''>0 0 0 0 -0 0</pose>
          <geometry>
            <mesh>
              <scale>1 1 1</scale>
              <uri>/home/sicelukwanda/catkin_ws/src/champ_description/meshes/sw_meshes/wrist_pitch_link_convex_decomposition.dae</uri>
            </mesh>
          </geometry>
          <max_contacts>10</max_contacts>
          <surface>
            <contact>
              <ode/>
            </contact>
            <bounce/>
            <friction>
              <torsional>
                <ode/>
              </torsional>
              <ode/>
            </friction>
          </surface>
        </collision>
        <visual name='wam/wrist_pitch_link_visual'>
          <pose frame=''>0 0 0 0 -0 0</pose>
          <geometry>
            <mesh>
              <scale>1 1 1</scale>
              <uri>/home/sicelukwanda/catkin_ws/src/champ_description/meshes/sw_meshes/wrist_pitch_link_fine.stl</uri>
            </mesh>
          </geometry>
        </visual>
        <self_collide>0</self_collide>
        <kinematic>0</kinematic>
        <gravity>1</gravity>
      </link>
      <joint name='wam/wrist_pitch_joint' type='revolute'>
        <child>wam/wrist_pitch_link</child>
        <parent>wam/wrist_yaw_link</parent>
        <axis>
          <xyz>0 1 0</xyz>
          <limit>
            <lower>-1.5707</lower>
            <upper>1.5707</upper>
            <effort>10</effort>
            <velocity>2</velocity>
          </limit>
          <dynamics>
            <damping>0.11</damping>
            <friction>0</friction>
            <spring_reference>0</spring_reference>
            <spring_stiffness>0</spring_stiffness>
          </dynamics>
          <use_parent_model_frame>1</use_parent_model_frame>
        </axis>
        <physics>
          <provide_feedback>1</provide_feedback>
          <ode>
            <provide_feedback>1</provide_feedback>
            <implicit_spring_damper>1</implicit_spring_damper>
            <cfm_damping>1</cfm_damping>
            <limit>
              <cfm>0</cfm>
              <erp>0.2</erp>
            </limit>
          </ode>
        </physics>
      </joint>
      <link name='wam/wrist_palm_link'>
        <pose frame=''>0.175 -0 1.523 0 -0 0</pose>
        <inertial>
          <pose frame=''>-4.4e-05 0.004333 0.090805 0 -0 0</pose>
          <mass>0.588594</mass>
          <inertia>
            <ixx>0.00261788</ixx>
            <ixy>-3.7692e-08</ixy>
            <ixz>-4.18824e-05</ixz>
            <iyy>0.00255462</iyy>
            <iyz>-1.48293e-05</iyz>
            <izz>0.00231087</izz>
          </inertia>
        </inertial>
        <collision name='wam/wrist_palm_link_collision'>
          <pose frame=''>0 0 0 0 -0 0</pose>
          <geometry>
            <mesh>
              <scale>1 1 1</scale>
              <uri>/home/sicelukwanda/catkin_ws/src/champ_description/meshes/sw_meshes/wrist_palm_link_convex.dae</uri>
            </mesh>
          </geometry>
          <max_contacts>10</max_contacts>
          <surface>
            <contact>
              <ode/>
            </contact>
            <bounce/>
            <friction>
              <torsional>
                <ode/>
              </torsional>
              <ode/>
            </friction>
          </surface>
        </collision>
        <collision name='wam/wrist_palm_link_fixed_joint_lump__wam/bhand/bhand_palm_link_collision_1'>
          <pose frame=''>0 0 0.06 0 -0 0</pose>
          <geometry>
            <mesh>
              <scale>1 1 1</scale>
              <uri>/home/sicelukwanda/catkin_ws/src/champ_description/meshes/sw_meshes/bhand/bhand_palm_link_convex_decomposition.dae</uri>
            </mesh>
          </geometry>
          <surface>
            <contact>
              <ode/>
            </contact>
            <friction>
              <ode>
                <mu>0.8</mu>
                <mu2>0.8</mu2>
              </ode>
              <torsional>
                <ode/>
              </torsional>
            </friction>
            <bounce/>
          </surface>
          <max_contacts>10</max_contacts>
        </collision>
        <visual name='wam/wrist_palm_link_visual'>
          <pose frame=''>0 0 0 0 -0 0</pose>
          <geometry>
            <mesh>
              <scale>1 1 1</scale>
              <uri>/home/sicelukwanda/catkin_ws/src/champ_description/meshes/sw_meshes/wrist_palm_link_fine.stl</uri>
            </mesh>
          </geometry>
        </visual>
        <visual name='wam/wrist_palm_link_fixed_joint_lump__wam/bhand/bhand_palm_link_visual_1'>
          <pose frame=''>0 0 0.06 0 -0 0</pose>
          <geometry>
            <mesh>
              <scale>1 1 1</scale>
              <uri>/home/sicelukwanda/catkin_ws/src/champ_description/meshes/sw_meshes/bhand/bhand_palm_fine.stl</uri>
            </mesh>
          </geometry>
          <material>
            <script>
              <uri>__default__</uri>
              <name>__default__</name>
            </script>
          </material>
        </visual>
        <gravity>1</gravity>
        <velocity_decay/>
        <self_collide>0</self_collide>
        <kinematic>0</kinematic>
      </link>
      <joint name='wam/palm_yaw_joint' type='revolute'>
        <child>wam/wrist_palm_link</child>
        <parent>wam/wrist_pitch_link</parent>
        <axis>
          <xyz>0 0 1</xyz>
          <limit>
            <lower>-3</lower>
            <upper>3</upper>
            <effort>10</effort>
            <velocity>2</velocity>
          </limit>
          <dynamics>
            <damping>0.11</damping>
            <friction>0</friction>
            <spring_reference>0</spring_reference>
            <spring_stiffness>0</spring_stiffness>
          </dynamics>
          <use_parent_model_frame>1</use_parent_model_frame>
        </axis>
        <physics>
          <provide_feedback>1</provide_feedback>
          <ode>
            <provide_feedback>1</provide_feedback>
            <implicit_spring_damper>1</implicit_spring_damper>
            <cfm_damping>1</cfm_damping>
            <limit>
              <cfm>0</cfm>
              <erp>0.2</erp>
            </limit>
          </ode>
        </physics>
      </joint>
      <link name='wam/bhand/finger_1/prox_link'>
        <pose frame=''>0.15 -0 1.6245 0 0 -1.5708</pose>
        <inertial>
          <pose frame=''>0.023133 0.000786 0.000528 0 -0 0</pose>
          <mass>0.14109</mass>
          <inertia>
            <ixx>0.04872</ixx>
            <ixy>1.7103e-06</ixy>
            <ixz>3.4041e-08</ixz>
            <iyy>0.076588</iyy>
            <iyz>2.3133e-08</iyz>
            <izz>0.077733</izz>
          </inertia>
        </inertial>
        <collision name='wam/bhand/finger_1/prox_link_collision'>
          <pose frame=''>0 0 0 0 -0 0</pose>
          <geometry>
            <mesh>
              <scale>1 1 1</scale>
              <uri>/home/sicelukwanda/catkin_ws/src/champ_description/meshes/sw_meshes/bhand/bhand_finger_prox_link_convex_decomposition.dae</uri>
            </mesh>
          </geometry>
          <surface>
            <contact>
              <ode/>
            </contact>
            <friction>
              <ode>
                <mu>0.8</mu>
                <mu2>0.8</mu2>
              </ode>
              <torsional>
                <ode/>
              </torsional>
            </friction>
            <bounce/>
          </surface>
          <max_contacts>10</max_contacts>
        </collision>
        <visual name='wam/bhand/finger_1/prox_link_visual'>
          <pose frame=''>0 0 0 0 -0 0</pose>
          <geometry>
            <mesh>
              <scale>1 1 1</scale>
              <uri>/home/sicelukwanda/catkin_ws/src/champ_description/meshes/sw_meshes/bhand/bhand_finger_prox_link_fine.stl</uri>
            </mesh>
          </geometry>
          <material>
            <script>
              <uri>__default__</uri>
              <name>__default__</name>
            </script>
          </material>
        </visual>
        <gravity>1</gravity>
        <velocity_decay/>
        <self_collide>0</self_collide>
        <kinematic>0</kinematic>
      </link>
      <joint name='wam/bhand/finger_1/prox_joint' type='revolute'>
        <child>wam/bhand/finger_1/prox_link</child>
        <parent>wam/wrist_palm_link</parent>
        <axis>
          <xyz>0 0 -1</xyz>
          <limit>
            <lower>0</lower>
            <upper>3.14159</upper>
            <effort>5</effort>
            <velocity>5</velocity>
          </limit>
          <dynamics>
            <damping>0.11</damping>
            <friction>0</friction>
            <spring_reference>0</spring_reference>
            <spring_stiffness>0</spring_stiffness>
          </dynamics>
          <use_parent_model_frame>1</use_parent_model_frame>
        </axis>
        <physics>
          <provide_feedback>1</provide_feedback>
          <ode>
            <provide_feedback>1</provide_feedback>
            <implicit_spring_damper>1</implicit_spring_damper>
            <cfm_damping>1</cfm_damping>
            <limit>
              <cfm>0</cfm>
              <erp>0.2</erp>
            </limit>
          </ode>
        </physics>
      </joint>
      <link name='wam/bhand/finger_1/med_link'>
        <pose frame=''>0.15 -0.05 1.6584 1.5708 0 -1.5708</pose>
        <inertial>
          <pose frame=''>0.023133 0.000786 0.000528 0 -0 0</pose>
          <mass>0.062139</mass>
          <inertia>
            <ixx>0.04872</ixx>
            <ixy>1.7103e-06</ixy>
            <ixz>3.4041e-08</ixz>
            <iyy>0.07658</iyy>
            <iyz>2.3133e-08</iyz>
            <izz>0.077733</izz>
          </inertia>
        </inertial>
        <collision name='wam/bhand/finger_1/med_link_collision'>
          <pose frame=''>0 0 0 0 -0 0</pose>
          <geometry>
            <mesh>
              <scale>1 1 1</scale>
              <uri>/home/sicelukwanda/catkin_ws/src/champ_description/meshes/sw_meshes/bhand/bhand_finger_med_link_convex.dae</uri>
            </mesh>
          </geometry>
          <surface>
            <contact>
              <ode/>
            </contact>
            <friction>
              <ode>
                <mu>0.8</mu>
                <mu2>0.8</mu2>
              </ode>
              <torsional>
                <ode/>
              </torsional>
            </friction>
            <bounce/>
          </surface>
          <max_contacts>10</max_contacts>
        </collision>
        <visual name='wam/bhand/finger_1/med_link_visual'>
          <pose frame=''>0 0 0 0 -0 0</pose>
          <geometry>
            <mesh>
              <scale>1 1 1</scale>
              <uri>/home/sicelukwanda/catkin_ws/src/champ_description/meshes/sw_meshes/bhand/bhand_finger_med_link_fine.stl</uri>
            </mesh>
          </geometry>
          <material>
            <script>
              <uri>__default__</uri>
              <name>__default__</name>
            </script>
          </material>
        </visual>
        <gravity>1</gravity>
        <velocity_decay/>
        <self_collide>0</self_collide>
        <kinematic>0</kinematic>
      </link>
      <joint name='wam/bhand/finger_1/med_joint' type='revolute'>
        <child>wam/bhand/finger_1/med_link</child>
        <parent>wam/bhand/finger_1/prox_link</parent>
        <axis>
          <xyz>-1 0 0</xyz>
          <limit>
            <lower>0</lower>
            <upper>2.44346</upper>
            <effort>5</effort>
            <velocity>5</velocity>
          </limit>
          <dynamics>
            <damping>0.11</damping>
            <friction>0</friction>
            <spring_reference>0</spring_reference>
            <spring_stiffness>0</spring_stiffness>
          </dynamics>
          <use_parent_model_frame>1</use_parent_model_frame>
        </axis>
        <physics>
          <provide_feedback>1</provide_feedback>
          <ode>
            <provide_feedback>1</provide_feedback>
            <implicit_spring_damper>1</implicit_spring_damper>
            <cfm_damping>1</cfm_damping>
            <limit>
              <cfm>0</cfm>
              <erp>0.2</erp>
            </limit>
          </ode>
        </physics>
      </joint>
      <link name='wam/bhand/finger_1/dist_link'>
        <pose frame=''>0.15 -0.11994 1.6614 1.5708 -0.785398 -1.5708</pose>
        <inertial>
          <pose frame=''>0.034545 0.000597 0.000239 0 -0 0</pose>
          <mass>0.072754</mass>
          <inertia>
            <ixx>0.10474</ixx>
            <ixy>3.37034e-06</ixy>
            <ixz>4.05938e-07</ixz>
            <iyy>0.116753</iyy>
            <iyz>-7.86846e-09</iyz>
            <izz>0.110038</izz>
          </inertia>
        </inertial>
        <collision name='wam/bhand/finger_1/dist_link_collision'>
          <pose frame=''>0 0 0 0 0 -0.785398</pose>
          <geometry>
            <mesh>
              <scale>1 1 1</scale>
              <uri>/home/sicelukwanda/catkin_ws/src/champ_description/meshes/sw_meshes/bhand/bhand_finger_dist_link_convex.dae</uri>
            </mesh>
          </geometry>
          <surface>
            <contact>
              <ode/>
            </contact>
            <friction>
              <ode>
                <mu>0.8</mu>
                <mu2>0.8</mu2>
              </ode>
              <torsional>
                <ode/>
              </torsional>
            </friction>
            <bounce/>
          </surface>
          <max_contacts>10</max_contacts>
        </collision>
        <visual name='wam/bhand/finger_1/dist_link_visual'>
          <pose frame=''>0 0 0 0 0 -0.785398</pose>
          <geometry>
            <mesh>
              <scale>1 1 1</scale>
              <uri>/home/sicelukwanda/catkin_ws/src/champ_description/meshes/sw_meshes/bhand/bhand_finger_dist_link_fine.stl</uri>
            </mesh>
          </geometry>
          <material>
            <script>
              <uri>__default__</uri>
              <name>__default__</name>
            </script>
          </material>
        </visual>
        <gravity>1</gravity>
        <velocity_decay/>
        <self_collide>1</self_collide>
        <kinematic>0</kinematic>
      </link>
      <joint name='wam/bhand/finger_1/dist_joint' type='revolute'>
        <child>wam/bhand/finger_1/dist_link</child>
        <parent>wam/bhand/finger_1/med_link</parent>
        <axis>
          <xyz>-1 0 0</xyz>
          <limit>
            <lower>0</lower>
            <upper>0.837758</upper>
            <effort>5</effort>
            <velocity>5</velocity>
          </limit>
          <dynamics>
            <damping>0.11</damping>
            <friction>0</friction>
            <spring_reference>0</spring_reference>
            <spring_stiffness>0</spring_stiffness>
          </dynamics>
          <use_parent_model_frame>1</use_parent_model_frame>
        </axis>
        <physics>
          <provide_feedback>1</provide_feedback>
          <ode>
            <provide_feedback>1</provide_feedback>
            <implicit_spring_damper>1</implicit_spring_damper>
            <cfm_damping>1</cfm_damping>
            <limit>
              <cfm>0</cfm>
              <erp>0.2</erp>
            </limit>
          </ode>
        </physics>
      </joint>
      <link name='wam/bhand/finger_2/prox_link'>
        <pose frame=''>0.2 -0 1.6245 0 0 -1.5708</pose>
        <inertial>
          <pose frame=''>0.023133 0.000786 0.000528 0 -0 0</pose>
          <mass>0.14109</mass>
          <inertia>
            <ixx>0.04872</ixx>
            <ixy>1.7103e-06</ixy>
            <ixz>3.4041e-08</ixz>
            <iyy>0.076588</iyy>
            <iyz>2.3133e-08</iyz>
            <izz>0.077733</izz>
          </inertia>
        </inertial>
        <collision name='wam/bhand/finger_2/prox_link_collision'>
          <pose frame=''>0 0 0 0 -0 0</pose>
          <geometry>
            <mesh>
              <scale>1 1 1</scale>
              <uri>/home/sicelukwanda/catkin_ws/src/champ_description/meshes/sw_meshes/bhand/bhand_finger_prox_link_convex_decomposition.dae</uri>
            </mesh>
          </geometry>
          <surface>
            <contact>
              <ode/>
            </contact>
            <friction>
              <ode>
                <mu>0.8</mu>
                <mu2>0.8</mu2>
              </ode>
              <torsional>
                <ode/>
              </torsional>
            </friction>
            <bounce/>
          </surface>
          <max_contacts>10</max_contacts>
        </collision>
        <visual name='wam/bhand/finger_2/prox_link_visual'>
          <pose frame=''>0 0 0 0 -0 0</pose>
          <geometry>
            <mesh>
              <scale>1 1 1</scale>
              <uri>/home/sicelukwanda/catkin_ws/src/champ_description/meshes/sw_meshes/bhand/bhand_finger_prox_link_fine.stl</uri>
            </mesh>
          </geometry>
          <material>
            <script>
              <uri>__default__</uri>
              <name>__default__</name>
            </script>
          </material>
        </visual>
        <gravity>1</gravity>
        <velocity_decay/>
        <self_collide>0</self_collide>
        <kinematic>0</kinematic>
      </link>
      <joint name='wam/bhand/finger_2/prox_joint' type='revolute'>
        <child>wam/bhand/finger_2/prox_link</child>
        <parent>wam/wrist_palm_link</parent>
        <axis>
          <xyz>0 0 1</xyz>
          <limit>
            <lower>0</lower>
            <upper>3.14159</upper>
            <effort>5</effort>
            <velocity>5</velocity>
          </limit>
          <dynamics>
            <damping>0.11</damping>
            <friction>0</friction>
            <spring_reference>0</spring_reference>
            <spring_stiffness>0</spring_stiffness>
          </dynamics>
          <use_parent_model_frame>1</use_parent_model_frame>
        </axis>
        <physics>
          <provide_feedback>1</provide_feedback>
          <ode>
            <provide_feedback>1</provide_feedback>
            <implicit_spring_damper>1</implicit_spring_damper>
            <cfm_damping>1</cfm_damping>
            <limit>
              <cfm>0</cfm>
              <erp>0.2</erp>
            </limit>
          </ode>
        </physics>
      </joint>
      <link name='wam/bhand/finger_2/med_link'>
        <pose frame=''>0.2 -0.05 1.6584 1.5708 0 -1.5708</pose>
        <inertial>
          <pose frame=''>0.023133 0.000786 0.000528 0 -0 0</pose>
          <mass>0.062139</mass>
          <inertia>
            <ixx>0.04872</ixx>
            <ixy>1.7103e-06</ixy>
            <ixz>3.4041e-08</ixz>
            <iyy>0.07658</iyy>
            <iyz>2.3133e-08</iyz>
            <izz>0.077733</izz>
          </inertia>
        </inertial>
        <collision name='wam/bhand/finger_2/med_link_collision'>
          <pose frame=''>0 0 0 0 -0 0</pose>
          <geometry>
            <mesh>
              <scale>1 1 1</scale>
              <uri>/home/sicelukwanda/catkin_ws/src/champ_description/meshes/sw_meshes/bhand/bhand_finger_med_link_convex.dae</uri>
            </mesh>
          </geometry>
          <surface>
            <contact>
              <ode/>
            </contact>
            <friction>
              <ode>
                <mu>0.8</mu>
                <mu2>0.8</mu2>
              </ode>
              <torsional>
                <ode/>
              </torsional>
            </friction>
            <bounce/>
          </surface>
          <max_contacts>10</max_contacts>
        </collision>
        <visual name='wam/bhand/finger_2/med_link_visual'>
          <pose frame=''>0 0 0 0 -0 0</pose>
          <geometry>
            <mesh>
              <scale>1 1 1</scale>
              <uri>/home/sicelukwanda/catkin_ws/src/champ_description/meshes/sw_meshes/bhand/bhand_finger_med_link_fine.stl</uri>
            </mesh>
          </geometry>
          <material>
            <script>
              <uri>__default__</uri>
              <name>__default__</name>
            </script>
          </material>
        </visual>
        <gravity>1</gravity>
        <velocity_decay/>
        <self_collide>0</self_collide>
        <kinematic>0</kinematic>
      </link>
      <joint name='wam/bhand/finger_2/med_joint' type='revolute'>
        <child>wam/bhand/finger_2/med_link</child>
        <parent>wam/bhand/finger_2/prox_link</parent>
        <axis>
          <xyz>-1 0 0</xyz>
          <limit>
            <lower>0</lower>
            <upper>2.44346</upper>
            <effort>5</effort>
            <velocity>5</velocity>
          </limit>
          <dynamics>
            <damping>0.11</damping>
            <friction>0</friction>
            <spring_reference>0</spring_reference>
            <spring_stiffness>0</spring_stiffness>
          </dynamics>
          <use_parent_model_frame>1</use_parent_model_frame>
        </axis>
        <physics>
          <provide_feedback>1</provide_feedback>
          <ode>
            <provide_feedback>1</provide_feedback>
            <implicit_spring_damper>1</implicit_spring_damper>
            <cfm_damping>1</cfm_damping>
            <limit>
              <cfm>0</cfm>
              <erp>0.2</erp>
            </limit>
          </ode>
        </physics>
      </joint>
      <link name='wam/bhand/finger_2/dist_link'>
        <pose frame=''>0.2 -0.11994 1.6614 1.5708 -0.785398 -1.5708</pose>
        <inertial>
          <pose frame=''>0.034545 0.000597 0.000239 0 -0 0</pose>
          <mass>0.072754</mass>
          <inertia>
            <ixx>0.10474</ixx>
            <ixy>3.37034e-06</ixy>
            <ixz>4.05938e-07</ixz>
            <iyy>0.116753</iyy>
            <iyz>-7.86846e-09</iyz>
            <izz>0.110038</izz>
          </inertia>
        </inertial>
        <collision name='wam/bhand/finger_2/dist_link_collision'>
          <pose frame=''>0 0 0 0 0 -0.785398</pose>
          <geometry>
            <mesh>
              <scale>1 1 1</scale>
              <uri>/home/sicelukwanda/catkin_ws/src/champ_description/meshes/sw_meshes/bhand/bhand_finger_dist_link_convex.dae</uri>
            </mesh>
          </geometry>
          <surface>
            <contact>
              <ode/>
            </contact>
            <friction>
              <ode>
                <mu>0.8</mu>
                <mu2>0.8</mu2>
              </ode>
              <torsional>
                <ode/>
              </torsional>
            </friction>
            <bounce/>
          </surface>
          <max_contacts>10</max_contacts>
        </collision>
        <visual name='wam/bhand/finger_2/dist_link_visual'>
          <pose frame=''>0 0 0 0 0 -0.785398</pose>
          <geometry>
            <mesh>
              <scale>1 1 1</scale>
              <uri>/home/sicelukwanda/catkin_ws/src/champ_description/meshes/sw_meshes/bhand/bhand_finger_dist_link_fine.stl</uri>
            </mesh>
          </geometry>
          <material>
            <script>
              <uri>__default__</uri>
              <name>__default__</name>
            </script>
          </material>
        </visual>
        <gravity>1</gravity>
        <velocity_decay/>
        <self_collide>1</self_collide>
        <kinematic>0</kinematic>
      </link>
      <joint name='wam/bhand/finger_2/dist_joint' type='revolute'>
        <child>wam/bhand/finger_2/dist_link</child>
        <parent>wam/bhand/finger_2/med_link</parent>
        <axis>
          <xyz>-1 0 0</xyz>
          <limit>
            <lower>0</lower>
            <upper>0.837758</upper>
            <effort>5</effort>
            <velocity>5</velocity>
          </limit>
          <dynamics>
            <damping>0.11</damping>
            <friction>0</friction>
            <spring_reference>0</spring_reference>
            <spring_stiffness>0</spring_stiffness>
          </dynamics>
          <use_parent_model_frame>1</use_parent_model_frame>
        </axis>
        <physics>
          <provide_feedback>1</provide_feedback>
          <ode>
            <provide_feedback>1</provide_feedback>
            <implicit_spring_damper>1</implicit_spring_damper>
            <cfm_damping>1</cfm_damping>
            <limit>
              <cfm>0</cfm>
              <erp>0.2</erp>
            </limit>
          </ode>
        </physics>
      </joint>
      <link name='wam/bhand/finger_3/med_link'>
        <pose frame=''>0.175 0.05 1.6584 1.5708 -0 1.5708</pose>
        <inertial>
          <pose frame=''>0.023133 0.000786 0.000528 0 -0 0</pose>
          <mass>0.062139</mass>
          <inertia>
            <ixx>0.04872</ixx>
            <ixy>1.7103e-06</ixy>
            <ixz>3.4041e-08</ixz>
            <iyy>0.07658</iyy>
            <iyz>2.3133e-08</iyz>
            <izz>0.077733</izz>
          </inertia>
        </inertial>
        <collision name='wam/bhand/finger_3/med_link_collision'>
          <pose frame=''>0 0 0 0 -0 0</pose>
          <geometry>
            <mesh>
              <scale>1 1 1</scale>
              <uri>/home/sicelukwanda/catkin_ws/src/champ_description/meshes/sw_meshes/bhand/bhand_finger_med_link_convex.dae</uri>
            </mesh>
          </geometry>
          <surface>
            <contact>
              <ode/>
            </contact>
            <friction>
              <ode>
                <mu>0.8</mu>
                <mu2>0.8</mu2>
              </ode>
              <torsional>
                <ode/>
              </torsional>
            </friction>
            <bounce/>
          </surface>
          <max_contacts>10</max_contacts>
        </collision>
        <visual name='wam/bhand/finger_3/med_link_visual'>
          <pose frame=''>0 0 0 0 -0 0</pose>
          <geometry>
            <mesh>
              <scale>1 1 1</scale>
              <uri>/home/sicelukwanda/catkin_ws/src/champ_description/meshes/sw_meshes/bhand/bhand_finger_med_link_fine.stl</uri>
            </mesh>
          </geometry>
          <material>
            <script>
              <uri>__default__</uri>
              <name>__default__</name>
            </script>
          </material>
        </visual>
        <gravity>1</gravity>
        <velocity_decay/>
        <self_collide>0</self_collide>
        <kinematic>0</kinematic>
      </link>
      <joint name='wam/bhand/finger_3/med_joint' type='revolute'>
        <child>wam/bhand/finger_3/med_link</child>
        <parent>wam/wrist_palm_link</parent>
        <axis>
          <xyz>1 0 0</xyz>
          <limit>
            <lower>0</lower>
            <upper>2.44346</upper>
            <effort>5</effort>
            <velocity>5</velocity>
          </limit>
          <dynamics>
            <damping>0.11</damping>
            <friction>0</friction>
            <spring_reference>0</spring_reference>
            <spring_stiffness>0</spring_stiffness>
          </dynamics>
          <use_parent_model_frame>1</use_parent_model_frame>
        </axis>
        <physics>
          <provide_feedback>1</provide_feedback>
          <ode>
            <provide_feedback>1</provide_feedback>
            <implicit_spring_damper>1</implicit_spring_damper>
            <cfm_damping>1</cfm_damping>
            <limit>
              <cfm>0</cfm>
              <erp>0.2</erp>
            </limit>
          </ode>
        </physics>
      </joint>
      <link name='wam/bhand/finger_3/dist_link'>
        <pose frame=''>0.175 0.11994 1.6614 1.5708 -0.785398 1.5708</pose>
        <inertial>
          <pose frame=''>0.034545 0.000597 0.000239 0 -0 0</pose>
          <mass>0.072754</mass>
          <inertia>
            <ixx>0.10474</ixx>
            <ixy>3.37034e-06</ixy>
            <ixz>4.05938e-07</ixz>
            <iyy>0.116753</iyy>
            <iyz>-7.86846e-09</iyz>
            <izz>0.110038</izz>
          </inertia>
        </inertial>
        <collision name='wam/bhand/finger_3/dist_link_collision'>
          <pose frame=''>0 0 0 0 0 -0.785398</pose>
          <geometry>
            <mesh>
              <scale>1 1 1</scale>
              <uri>/home/sicelukwanda/catkin_ws/src/champ_description/meshes/sw_meshes/bhand/bhand_finger_dist_link_convex.dae</uri>
            </mesh>
          </geometry>
          <surface>
            <contact>
              <ode/>
            </contact>
            <friction>
              <ode>
                <mu>0.8</mu>
                <mu2>0.8</mu2>
              </ode>
              <torsional>
                <ode/>
              </torsional>
            </friction>
            <bounce/>
          </surface>
          <max_contacts>10</max_contacts>
        </collision>
        <visual name='wam/bhand/finger_3/dist_link_visual'>
          <pose frame=''>0 0 0 0 0 -0.785398</pose>
          <geometry>
            <mesh>
              <scale>1 1 1</scale>
              <uri>/home/sicelukwanda/catkin_ws/src/champ_description/meshes/sw_meshes/bhand/bhand_finger_dist_link_fine.stl</uri>
            </mesh>
          </geometry>
          <material>
            <script>
              <uri>__default__</uri>
              <name>__default__</name>
            </script>
          </material>
        </visual>
        <gravity>1</gravity>
        <velocity_decay/>
        <self_collide>1</self_collide>
        <kinematic>0</kinematic>
      </link>
      <joint name='wam/bhand/finger_3/dist_joint' type='revolute'>
        <child>wam/bhand/finger_3/dist_link</child>
        <parent>wam/bhand/finger_3/med_link</parent>
        <axis>
          <xyz>1 0 0</xyz>
          <limit>
            <lower>0</lower>
            <upper>0.837758</upper>
            <effort>5</effort>
            <velocity>5</velocity>
          </limit>
          <dynamics>
            <damping>0.11</damping>
            <friction>0</friction>
            <spring_reference>0</spring_reference>
            <spring_stiffness>0</spring_stiffness>
          </dynamics>
          <use_parent_model_frame>1</use_parent_model_frame>
        </axis>
        <physics>
          <provide_feedback>1</provide_feedback>
          <ode>
            <provide_feedback>1</provide_feedback>
            <implicit_spring_damper>1</implicit_spring_damper>
            <cfm_damping>1</cfm_damping>
            <limit>
              <cfm>0</cfm>
              <erp>0.2</erp>
            </limit>
          </ode>
        </physics>
      </joint>
      <plugin name='differential_drive_controller' filename='libgazebo_ros_diff_drive.so'>
        <legacyMode>false</legacyMode>
        <alwaysOn>true</alwaysOn>
        <updateRate>100.0</updateRate>
        <leftJoint>base_left_wheel_joint</leftJoint>
        <rightJoint>base_right_wheel_joint</rightJoint>
        <wheelSeparation>0.42</wheelSeparation>
        <wheelDiameter>0.263</wheelDiameter>
        <wheelTorque>5</wheelTorque>
        <wheelAcceleration>0</wheelAcceleration>
        <robotNamespace>wam_powerbot</robotNamespace>
        <commandTopic>cmd_vel</commandTopic>
        <odometryTopic>odom</odometryTopic>
        <odometrySource>world</odometrySource>
        <odometryFrame>odom</odometryFrame>
        <robotBaseFrame>base_center</robotBaseFrame>
        <publishTf>1</publishTf>
        <publishWheelTF>false</publishWheelTF>
        <publishWheelJointState>false</publishWheelJointState>
        <rosDebugLevel>Warn</rosDebugLevel>
      </plugin>
      <plugin name='ground_truth_odometry' filename='libgazebo_ros_p3d.so'>
        <alwaysOn>true</alwaysOn>
        <updateRate>100.0</updateRate>
        <bodyName>base_center</bodyName>
        <topicName>base_pose_ground_truth</topicName>
        <gaussianNoise>0.01</gaussianNoise>
        <frameName>world</frameName>
        <xyzOffsets>0 0 0</xyzOffsets>
        <rpyOffsets>0 0 0</rpyOffsets>
        <robotNamespace>/</robotNamespace>
      </plugin>
      <static>0</static>
      <plugin name='gazebo_ros_control' filename='libgazebo_ros_control.so'>
        <robotNamespace>/wam_powerbot</robotNamespace>
      </plugin>
      <pose frame=''>0 0 0 0 -0 0</pose>
    </model>
  </world>
</sdf>
