<?xml version="1.0"?>

<robot name="wam"
	xmlns:sensor="http://playerstage.sourceforge.net/gazebo/xmlschema/#sensor"
	xmlns:controller="http://playerstage.sourceforge.net/gazebo/xmlschema/#controller"
	xmlns:interface="http://playerstage.sourceforge.net/gazebo/xmlschema/#interface"
	xmlns:xacro="http://ros.org/wiki/xacro">


<!-- ArmStuff -->


<link name="world"/>

  <joint name="wam_joint_footprint" type="fixed">
    <origin rpy="0 0 0" xyz="0.22 0 0.346"/>
    <child link="wam_link_base"/>
    <parent link="world"/>
  </joint>
  <gazebo reference="wam_joint_footprint">
    <selfCollide>true</selfCollide>
    <material>Gazebo/Grey</material>
  </gazebo>

	<link name="wam_link_base">
		<inertial>
			<mass value="20"/>
			<origin xyz="0.0 0.0 0.0"/>
			<inertia ixx="1.0" ixy="0.0" ixz="0.0" iyy="1.0" iyz="0.0" izz="1.0"/>
		</inertial>
		<visual>
			<origin rpy="0 0 0" xyz="0 0 0"/>
			<geometry>
				<mesh filename="package://wam_description/mesh/wambase.stl" scale="1.0 1.0 1.0"/>
			</geometry>
			<material name="Grey">
				<color rgba="0.75 0.75 0.75 1.0"/>
			</material>
		</visual>
		<collision>
			<origin rpy="0 0 0" xyz="0.0 0.0 0.0"/>
			<geometry>
				<mesh filename="package://wam_description/mesh/wambase.stl" scale="1.0 1.0 1.0"/>
			</geometry>
			<contact_coefficients kd="1.0" kp="1000.0" mu="0"/>
		</collision>
	</link>

  <link name="wam_link_1">
    <inertial>
      <mass value="8.3936"/>
      <origin rpy="0 0 0" xyz="0.0 0.0 0.0"/>
      <inertia ixx="1.0" ixy="0.0" ixz="0.0" iyy="1.0" iyz="0.0" izz="1.0"/>
    </inertial>
    <visual>
      <origin rpy="0 0 0" xyz="0.0 0.0 0.0"/>
      <geometry name="wam_link_1_visual">
        <mesh filename="package://wam_description/mesh/wam1.stl" scale="1.0 1.0 1.0"/>
      </geometry>
      <material name="Grey">
        <color rgba="0.75 0.75 0.75 1.0"/>
      </material>
    </visual>
    <collision>
      <origin rpy="0 0 0" xyz="0.0 0.0 0.0"/>
      <geometry name="wam_link_1_collision">
        <mesh filename="package://wam_description/mesh/wam1.stl" scale="1.0 1.0 1.0"/>
        <!--                <box size="0.20 0.40 0.40"/> -->
      </geometry>
      <contact_coefficients kd="1.0" kp="1000.0" mu="0"/>
    </collision>
  </link>
  <gazebo reference="wam_link_1">
    <material>Gazebo/Grey</material>
    <selfCollide>true</selfCollide>
  </gazebo>
  <joint name="wam_joint_1" type="revolute">
    <parent link="wam_link_base"/>
    <child link="wam_link_1"/>
    <origin rpy="0 0 0" xyz="0.0 0.0 0.0"/>
    <axis xyz="0 0 1"/>
    <limit effort="30" lower="-2.6" upper="2.6" velocity="2.0"/>
    <!-- <safety_controller k_velocity="0.5"/> -->
    <dynamics damping="100"/>
  </joint>
  <transmission name="j1_transmission" type="pr2_mechanism_model/SimpleTransmission">
    <actuator name="j1"/>
    <joint name="wam_joint_1"/>
    <mechanicalReduction>1</mechanicalReduction>
    <motorTorqueConstant>1</motorTorqueConstant>
    <!-- <pulsesPerRevolution>90000</pulsesPerRevolution> -->
  </transmission>
  <link name="wam_link_2">
    <inertial>
      <mass value="4.8487"/>
      <origin rpy="0 0 0" xyz="0 0 0"/>
      <inertia ixx="1.0" ixy="0.0" ixz="0.0" iyy="1.0" iyz="0.0" izz="1.0"/>
    </inertial>
    <visual>
      <origin rpy="0 0 0" xyz="0.0 0.0 0.0"/>
      <geometry name="wam_link_2_visual">
        <mesh filename="package://wam_description/mesh/wam2.stl" scale="1.0 1.0 1.0"/>
      </geometry>
      <material name="Grey">
        <color rgba="0.75 0.75 0.75 1.0"/>
      </material>
    </visual>
    <collision>
      <origin rpy="0 0 0" xyz="0.0 0.0 0.0"/>
      <geometry name="wam_link_2_collision">
        <mesh filename="package://wam_description/mesh/wam2.stl" scale="1.0 1.0 1.0"/>
        <!--                <box size="0.10 0.10 0.10"/> -->
      </geometry>
      <contact_coefficients kd="1.0" kp="1000.0" mu="0"/>
    </collision>
  </link>
  <gazebo reference="wam_link_2">
    <material>Gazebo/Grey</material>
    <selfCollide>true</selfCollide>
  </gazebo>
  <joint name="wam_joint_2" type="revolute">
    <parent link="wam_link_1"/>
    <child link="wam_link_2"/>
    <origin rpy="0 0 0" xyz="0.0 0.0 0.0"/>
    <axis xyz="0 1 0"/>
    <limit effort="30" lower="-2.0" upper="2.0" velocity="2.0"/>
    <!-- <safety_controller k_velocity="0.5"/> -->
    <dynamics damping="100"/>
  </joint>
  <transmission name="j2_transmission" type="pr2_mechanism_model/SimpleTransmission">
    <actuator name="j2"/>
    <joint name="wam_joint_2"/>
    <mechanicalReduction>1</mechanicalReduction>
    <motorTorqueConstant>1</motorTorqueConstant>
    <!-- <pulsesPerRevolution>90000</pulsesPerRevolution> -->
  </transmission>
  <link name="wam_link_3">
    <inertial>
      <mass value="1.7251"/>
      <origin rpy="0 0 0" xyz="0 0 0.225"/>
      <inertia ixx="1.0" ixy="0.0" ixz="0.0" iyy="1.0" iyz="0.0" izz="1.0"/>
    </inertial>
    <visual>
      <origin rpy="0 0 0" xyz="0.0 0.0 0.0"/>
      <geometry name="wam_link_3_visual">
        <mesh filename="package://wam_description/mesh/wam3.stl" scale="1.0 1.0 1.0"/>
      </geometry>
      <material name="Grey">
        <color rgba="0.75 0.75 0.75 1.0"/>
      </material>
    </visual>
    <collision>
      <origin rpy="0 0 0" xyz="0.0 0.0 0.0"/>
      <geometry name="wam_link_3_collision">
        <mesh filename="package://wam_description/mesh/wam3.stl" scale="1.0 1.0 1.0"/>
        <!--                <box size="0.10 0.10 0.10"/> -->
      </geometry>
      <contact_coefficients kd="1.0" kp="1000.0" mu="0"/>
    </collision>
  </link>
  <gazebo reference="wam_link_3">
    <material>Gazebo/Grey</material>
    <selfCollide>true</selfCollide>
  </gazebo>
  <joint name="wam_joint_3" type="revolute">
    <parent link="wam_link_2"/>
    <child link="wam_link_3"/>
    <origin rpy="0 0 0" xyz="0.0 0.0 0.0"/>
    <axis xyz="0 0 1"/>
    <limit effort="30" lower="-2.8" upper="2.8" velocity="2.0"/>
    <!-- <safety_controller k_velocity="0.5"/> -->
    <dynamics damping="100"/>
  </joint>
  <transmission name="j3_transmission" type="pr2_mechanism_model/SimpleTransmission">
    <actuator name="j3"/>
    <joint name="wam_joint_3"/>
    <mechanicalReduction>1</mechanicalReduction>
    <motorTorqueConstant>1</motorTorqueConstant>
    <!-- <pulsesPerRevolution>90000</pulsesPerRevolution> -->
  </transmission>
  <link name="wam_link_4">
    <inertial>
      <mass value="2.0824"/>
      <origin rpy="0 0 0" xyz="-0.045 -0.15 0"/>
      <inertia ixx="1.0" ixy="0.0" ixz="0.0" iyy="1.0" iyz="0.0" izz="1.0"/>
    </inertial>
    <visual>
      <origin rpy="0 0 0" xyz="0.0 0.0 0.0"/>
      <geometry name="wam_link_4_visual">
        <mesh filename="package://wam_description/mesh/wam4.stl" scale="1.0 1.0 1.0"/>
      </geometry>
      <material name="Grey">
        <color rgba="0.75 0.75 0.75 1.0"/>
      </material>
    </visual>
    <collision>
      <origin rpy="0 0 0" xyz="0.0 0.0 0.0"/>
      <geometry name="wam_link_4_collision">
        <mesh filename="package://wam_description/mesh/wam4.stl" scale="1.0 1.0 1.0"/>
        <!--                <box size="0.10 0.10 0.10"/> -->
      </geometry>
      <contact_coefficients kd="1.0" kp="1000.0" mu="0"/>
    </collision>
  </link>
  <gazebo reference="wam_link_4">
    <material>Gazebo/Grey</material>
    <selfCollide>true</selfCollide>
  </gazebo>
  <joint name="wam_joint_4" type="revolute">
    <parent link="wam_link_3"/>
    <child link="wam_link_4"/>
    <origin rpy="-1.57079632679 0 0" xyz="0.045 0.0 0.55"/>
    <axis xyz="0 0 1"/>
    <limit effort="35" lower="-0.9" upper="3.14159265359" velocity="2.0"/>
    <!-- <safety_controller k_velocity="0.5"/> -->
    <dynamics damping="100"/>
  </joint>
  <transmission name="j4_transmission" type="pr2_mechanism_model/SimpleTransmission">
    <actuator name="j4"/>
    <joint name="wam_joint_4"/>
    <mechanicalReduction>1</mechanicalReduction>
    <motorTorqueConstant>1</motorTorqueConstant>
    <!-- <pulsesPerRevolution>90000</pulsesPerRevolution> -->
  </transmission>
  <link name="wam_link_5">
    <inertial>
      <mass value="0.3067"/>
      <origin rpy="0 0 0" xyz="0 0 0"/>
      <inertia ixx="1.0" ixy="0.0" ixz="0.0" iyy="1.0" iyz="0.0" izz="1.0"/>
    </inertial>
    <visual>
      <origin rpy="0 0 0" xyz="0.0 0.0 0.0"/>
      <geometry name="wam_link_5_visual">
        <mesh filename="package://wam_description/mesh/wam5.stl" scale="1.0 1.0 1.0"/>
      </geometry>
      <material name="Grey">
        <color rgba="0.75 0.75 0.75 1.0"/>
      </material>
    </visual>
    <collision>
      <origin rpy="0 0 0" xyz="0.0 0.0 0.0"/>
      <geometry name="wam_link_5_collision">
        <mesh filename="package://wam_description/mesh/wam5.stl" scale="1.0 1.0 1.0"/>
        <!--                <box size="0.10 0.10 0.10"/> -->
      </geometry>
      <contact_coefficients kd="1.0" kp="1000.0" mu="0"/>
    </collision>
  </link>
  <gazebo reference="wam_link_5">
    <material>Gazebo/Grey</material>
    <selfCollide>true</selfCollide>
  </gazebo>
  <joint name="wam_joint_5" type="revolute">
    <parent link="wam_link_4"/>
    <child link="wam_link_5"/>
    <origin rpy="1.57079632679 0 0" xyz="-0.045 -0.3 0.0"/>
    <axis xyz="0 0 1"/>
    <limit effort="30" lower="-4.76" upper="1.24" velocity="2.0"/>
    <!-- <safety_controller k_velocity="0.5"/> -->
    <dynamics damping="100"/>
  </joint>
  <transmission name="j5_transmission" type="pr2_mechanism_model/SimpleTransmission">
    <actuator name="j5"/>
    <joint name="wam_joint_5"/>
    <mechanicalReduction>1</mechanicalReduction>
    <motorTorqueConstant>1</motorTorqueConstant>
    <!-- <pulsesPerRevolution>90000</pulsesPerRevolution> -->
  </transmission>
  <link name="wam_link_6">
    <inertial>
      <mass value="0.4278"/>
      <origin rpy="0 0 0" xyz="0 0 0"/>
      <inertia ixx="1.0" ixy="0.0" ixz="0.0" iyy="1.0" iyz="0.0" izz="1.0"/>
    </inertial>
    <visual>
      <origin rpy="0 0 0" xyz="0.0 0.0 0.0"/>
      <geometry name="wam_link_6_visual">
        <mesh filename="package://wam_description/mesh/wam6.stl" scale="1.0 1.0 1.0"/>
      </geometry>
      <material name="Grey">
        <color rgba="0.75 0.75 0.75 1.0"/>
      </material>
    </visual>
    <collision>
      <origin rpy="0 0 0" xyz="0.0 0.0 0.0"/>
      <geometry name="wam_link_6_collision">
        <mesh filename="package://wam_description/mesh/wam6.stl" scale="1.0 1.0 1.0"/>
        <!--                <box size="0.10 0.10 0.10"/> -->
      </geometry>
      <contact_coefficients kd="1.0" kp="1000.0" mu="0"/>
    </collision>
  </link>
  <gazebo reference="wam_link_6">
    <material>Gazebo/Grey</material>
    <selfCollide>true</selfCollide>
  </gazebo>
  <joint name="wam_joint_6" type="revolute">
    <parent link="wam_link_5"/>
    <child link="wam_link_6"/>
    <origin rpy="-1.57079632679 0 0" xyz="0.0 0.0 0.0"/>
    <axis xyz="0 0 1"/>
    <limit effort="30" lower="-1.6" upper="1.6" velocity="2.0"/>
    <!-- <safety_controller k_velocity="0.5"/> -->
    <dynamics damping="100"/>
  </joint>
  <transmission name="j6_transmission" type="pr2_mechanism_model/SimpleTransmission">
    <actuator name="j6"/>
    <joint name="wam_joint_6"/>
    <mechanicalReduction>1</mechanicalReduction>
    <motorTorqueConstant>1</motorTorqueConstant>
    <!-- <pulsesPerRevolution>90000</pulsesPerRevolution> -->
  </transmission>
  <link name="wam_link_7">
    <inertial>
      <mass value="0.0557"/>
      <origin rpy="0 0 0" xyz="0 0 0"/>
      <inertia ixx="1.0" ixy="0.0" ixz="0.0" iyy="1.0" iyz="0.0" izz="1.0"/>
    </inertial>
    <visual>
      <origin rpy="0 0 0" xyz="0.0 0.0 0.0"/>
      <geometry name="wam_link_7_visual">
        <mesh filename="package://wam_description/mesh/wam7.stl" scale="1.0 1.0 1.0"/>
      </geometry>
      <material name="Grey">
        <color rgba="0.75 0.75 0.75 1.0"/>
      </material>
    </visual>
    <collision>
      <origin rpy="0 0 0" xyz="0.0 0.0 0.0"/>
      <geometry name="wam_link_7_collision">
        <mesh filename="package://wam_description/mesh/wam7.stl" scale="1.0 1.0 1.0"/>
        <!--                <box size="0.10 0.10 0.10"/> -->
      </geometry>
      <contact_coefficients kd="1.0" kp="1000.0" mu="0"/>
    </collision>
  </link>
  <gazebo reference="wam_link_7">
    <material>Gazebo/Grey</material>
    <selfCollide>true</selfCollide>
  </gazebo>
  <joint name="wam_joint_7" type="revolute">
    <parent link="wam_link_6"/>
    <child link="wam_link_7"/>
    <origin rpy="1.57079632679 0 0" xyz="0.0 0.0 0.0"/>
    <axis xyz="0 0 1"/>
    <limit effort="30" lower="-3.0" upper="3.0" velocity="2.0"/>
    <!-- <safety_controller k_velocity="0.5"/> -->
    <dynamics damping="100"/>
  </joint>
  <transmission name="j7_transmission" type="pr2_mechanism_model/SimpleTransmission">
    <actuator name="j7"/>
    <joint name="wam_joint_7"/>
    <mechanicalReduction>1</mechanicalReduction>
    <motorTorqueConstant>1</motorTorqueConstant>
    <!-- <pulsesPerRevolution>90000</pulsesPerRevolution> -->
  </transmission>
  <link name="wam_link_tcp"/>
  <joint name="wam_joint_tcp" type="fixed">
    <parent link="wam_link_7"/>
    <child link="wam_link_tcp"/>
    <origin rpy="0 0 0" xyz="0.0 0.0 0.06"/>
  </joint>
  <link name="bhand_base_link">
    <visual>
      <origin rpy="0 0 0" xyz="0 0 0"/>
      <geometry>
        <mesh filename="package://wam_description/mesh/bh_base.stl"/>
      </geometry>
      <material name="Grey">
        <color rgba="0.5 0.5 0.5 1.0"/>
      </material>
    </visual>
    <collision>
      <origin rpy="0 0 0" xyz="0 0 0"/>
      <geometry>
        <mesh filename="package://wam_description/mesh/bh_base.stl"/>
      </geometry>
      <contact_coefficients kd="1.0" kp="1000.0" mu="0"/>
    </collision>
  </link>
  <joint name="bhand_joint_fixed" type="fixed">
    <parent link="wam_link_7"/>
    <child link="bhand_base_link"/>
    <origin rpy="0 0 0" xyz="0 0 0"/>
    <axis xyz="0 0 1"/>
    <limit effort="30" lower="0.0" upper="3.14159265359" velocity="2.0"/>
  </joint>
  <link name="bhand_finger1_link_1">
    <visual>
      <origin rpy="0 0 0" xyz="0 0 0"/>
      <geometry>
        <mesh filename="package://wam_description/mesh/bh_link1.stl"/>
      </geometry>
      <material name="Grey">
        <color rgba="0.5 0.5 0.5 1.0"/>
      </material>
    </visual>
    <collision>
      <origin rpy="0 0 0" xyz="0 0 0"/>
      <geometry>
        <mesh filename="package://wam_description/mesh/bh_link1.stl"/>
      </geometry>
    </collision>
  </link>
  <joint name="bhand_spread" type="revolute">
    <parent link="bhand_base_link"/>
    <child link="bhand_finger1_link_1"/>
    <origin rpy="0 0 0" xyz="0 -0.025 0.133"/>
    <axis xyz="0 0 -1"/>
    <limit effort="30" lower="0.0" upper="3.14159265359" velocity="2.0"/>
  </joint>
  <link name="bhand_finger2_link_1">
    <visual>
      <origin rpy="0 0 0" xyz="0 0 0"/>
      <geometry>
        <mesh filename="package://wam_description/mesh/bh_link1.stl"/>
      </geometry>
      <material name="Grey">
        <color rgba="0.5 0.5 0.5 1.0"/>
      </material>
    </visual>
    <collision>
      <origin rpy="0 0 0" xyz="0 0 0"/>
      <geometry>
        <mesh filename="package://wam_description/mesh/bh_link1.stl"/>
      </geometry>
    </collision>
  </link>
  <joint name="bhand_spread_finger2" type="revolute">
    <parent link="bhand_base_link"/>
    <child link="bhand_finger2_link_1"/>
    <origin rpy="0 0 0" xyz="0 0.025 0.133"/>
    <axis xyz="0 0 1"/>
    <limit effort="30" lower="0.0" upper="3.14159265359" velocity="2.0"/>
    <mimic joint="bhand_spread" multiplier="1.0" offset="0"/>
  </joint>
  <link name="bhand_finger3_link_1">
    <visual>
      <origin rpy="0 0 0" xyz="0 0 0"/>
      <geometry>
        <mesh filename="package://wam_description/mesh/bh_link1.stl"/>
      </geometry>
      <material name="Grey">
        <color rgba="0.5 0.5 0.5 1.0"/>
      </material>
    </visual>
    <collision>
      <origin rpy="0 0 0" xyz="0 0 0"/>
      <geometry>
        <mesh filename="package://wam_description/mesh/bh_link1.stl"/>
      </geometry>
    </collision>
  </link>
  <joint name="bhand_finger3_joint_1" type="fixed">
    <parent link="bhand_base_link"/>
    <child link="bhand_finger3_link_1"/>
    <origin rpy="0 0 3.14159265359" xyz="0 0 0.133"/>
  </joint>
  <link name="bhand_finger1_link_2">
    <visual>
      <origin rpy="0 0 0" xyz="0 0 0"/>
      <geometry>
        <mesh filename="package://wam_description/mesh/bh_link2.stl"/>
      </geometry>
      <material name="Grey">
        <color rgba="0.5 0.5 0.5 1.0"/>
      </material>
    </visual>
    <collision>
      <origin rpy="0 0 0" xyz="0 0 0"/>
      <geometry>
        <mesh filename="package://wam_description/mesh/bh_link2.stl"/>
      </geometry>
    </collision>
  </link>
  <joint name="bhand_finger1" type="revolute">
    <parent link="bhand_finger1_link_1"/>
    <child link="bhand_finger1_link_2"/>
    <origin rpy="1.57079632679 0 0" xyz="0.050 0 0"/>
    <axis xyz="0 0 1"/>
    <limit effort="30" lower="0.0" upper="2.44346095279" velocity="2.0"/>
  </joint>
  <link name="bhand_finger1_link_3">
    <visual>
      <origin rpy="0 0 0" xyz="0 0 0"/>
      <geometry>
        <mesh filename="package://wam_description/mesh/bh_link3.stl"/>
      </geometry>
      <material name="Grey">
        <color rgba="0.5 0.5 0.5 1.0"/>
      </material>
    </visual>
    <collision>
      <origin rpy="0 0 0" xyz="0 0 0"/>
      <geometry>
        <mesh filename="package://wam_description/mesh/bh_link3.stl"/>
      </geometry>
    </collision>
  </link>
  <joint name="bhand_finger1_joint_3" type="revolute">
    <parent link="bhand_finger1_link_2"/>
    <child link="bhand_finger1_link_3"/>
    <origin rpy="0 0 0.733038285838" xyz="0.070 0 0"/>
    <axis xyz="0 0 1"/>
    <limit effort="30" lower="0" upper="0.837758040957" velocity="2.0"/>
    <mimic joint="bhand_finger1" multiplier="0.342857142857" offset="0"/>
  </joint>
  <link name="bhand_finger2_link_2">
    <visual>
      <origin rpy="0 0 0" xyz="0 0 0"/>
      <geometry>
        <mesh filename="package://wam_description/mesh/bh_link2.stl"/>
      </geometry>
      <material name="Grey">
        <color rgba="0.5 0.5 0.5 1.0"/>
      </material>
    </visual>
    <collision>
      <origin rpy="0 0 0" xyz="0 0 0"/>
      <geometry>
        <mesh filename="package://wam_description/mesh/bh_link2.stl"/>
      </geometry>
    </collision>
  </link>
  <joint name="bhand_finger2" type="revolute">
    <parent link="bhand_finger2_link_1"/>
    <child link="bhand_finger2_link_2"/>
    <origin rpy="1.57079632679 0 0" xyz="0.050 0 0"/>
    <axis xyz="0 0 1"/>
    <limit effort="30" lower="0.0" upper="2.44346095279" velocity="2.0"/>
  </joint>
  <link name="bhand_finger2_link_3">
    <visual>
      <origin rpy="0 0 0" xyz="0 0 0"/>
      <geometry>
        <mesh filename="package://wam_description/mesh/bh_link3.stl"/>
      </geometry>
      <material name="Grey">
        <color rgba="0.5 0.5 0.5 1.0"/>
      </material>
    </visual>
    <collision>
      <origin rpy="0 0 0" xyz="0 0 0"/>
      <geometry>
        <mesh filename="package://wam_description/mesh/bh_link3.stl"/>
      </geometry>
    </collision>
  </link>
  <joint name="bhand_finger2_joint_3" type="revolute">
    <parent link="bhand_finger2_link_2"/>
    <child link="bhand_finger2_link_3"/>
    <origin rpy="0 0 0.733038285838" xyz="0.070 0 0"/>
    <axis xyz="0 0 1"/>
    <limit effort="30" lower="0" upper="0.837758040957" velocity="2.0"/>
    <mimic joint="bhand_finger2" multiplier="0.342857142857" offset="0"/>
  </joint>
  <link name="bhand_finger3_link_2">
    <visual>
      <origin rpy="0 0 0" xyz="0 0 0"/>
      <geometry>
        <mesh filename="package://wam_description/mesh/bh_link2.stl"/>
      </geometry>
      <material name="Grey">
        <color rgba="0.5 0.5 0.5 1.0"/>
      </material>
    </visual>
    <collision>
      <origin rpy="0 0 0" xyz="0 0 0"/>
      <geometry>
        <mesh filename="package://wam_description/mesh/bh_link2.stl"/>
      </geometry>
    </collision>
  </link>
  <joint name="bhand_finger3" type="revolute">
    <parent link="bhand_finger3_link_1"/>
    <child link="bhand_finger3_link_2"/>
    <origin rpy="1.57079632679 0 0" xyz="0.050 0 0"/>
    <axis xyz="0 0 1"/>
    <limit effort="30" lower="0.0" upper="2.44346095279" velocity="2.0"/>
  </joint>
  <link name="bhand_finger3_link_3">
    <visual>
      <origin rpy="0 0 0" xyz="0 0 0"/>
      <geometry>
        <mesh filename="package://wam_description/mesh/bh_link3.stl"/>
      </geometry>
      <material name="Grey">
        <color rgba="0.5 0.5 0.5 1.0"/>
      </material>
    </visual>
    <collision>
      <origin rpy="0 0 0" xyz="0 0 0"/>
      <geometry>
        <mesh filename="package://wam_description/mesh/bh_link3.stl"/>
      </geometry>
    </collision>
  </link>
  <joint name="bhand_finger3_joint_3" type="revolute">
    <parent link="bhand_finger3_link_2"/>
    <child link="bhand_finger3_link_3"/>
    <origin rpy="0 0 0.733038285838" xyz="0.070 0 0"/>
    <axis xyz="0 0 1"/>
    <limit effort="30" lower="0" upper="0.837758040957" velocity="2.0"/>
    <mimic joint="bhand_finger3" multiplier="0.342857142857" offset="0"/>
  </joint>
	
  
    <!-- 
  <gazebo>
this publishes empty joint_states due to no transmission, but
         triggering robot_state_puublisher to publish tf between fixed joints in erratic,
         (e.g. base_laser_link for the base_scan frame)
    <controller:gazebo_ros_controller_manager name="gazebo_ros_controller_manager" plugin="libgazebo_ros_controller_manager.so">
      <alwaysOn>true</alwaysOn>
      <updateRate>1000.0</updateRate>
      <interface:audio name="gazebo_ros_controller_manager_dummy_iface"/>
    </controller:gazebo_ros_controller_manager>
</gazebo> 
-->
  
<gazebo>
  <plugin name="gazebo_ros_control" filename="libgazebo_ros_control.so">
    <robotNamespace>/wam</robotNamespace>
  </plugin>
</gazebo>
</robot>
