<?xml version="1.0"?>

<robot name="wam_powerbot"
	xmlns:sensor="http://playerstage.sourceforge.net/gazebo/xmlschema/#sensor"
	xmlns:controller="http://playerstage.sourceforge.net/gazebo/xmlschema/#controller"
	xmlns:interface="http://playerstage.sourceforge.net/gazebo/xmlschema/#interface"
	xmlns:xacro="http://ros.org/wiki/xacro">


  <xacro:include filename="$(find urdf_pkg)/defs/powerbot_wheel.xacro"/>

  <joint name="kinect_joint" type="fixed">
    <origin rpy="0.000324167225049 -0.13482796641 -0.0053822279229" xyz="0.368545706539 -0.00238212947356 0.462414206512"/>
    <parent link="base_center"/>
    <child link="kinect_link"/>
  </joint>
  <link name="kinect_link">
    <inertial>
      <mass value="0.200"/>
      <origin rpy="0 0 0" xyz="0 0 0"/>
      <inertia ixx="0.00058083" ixy="0" ixz="0" iyy="0.000030833" iyz="0" izz="0.00059083"/>
    </inertial>
    <visual>
      <origin rpy="0 0 0" xyz="0 0 0"/>
      <geometry>
        <mesh filename="package://urdf_pkg/meshes/asus_camera/asus_camera_simple.dae"/>
      </geometry>
    </visual>
    <collision>
      <origin rpy="0 0 0" xyz="0 0 0"/>
      <geometry>
        <box size="0.035 0.185 0.025"/>
      </geometry>
    </collision>
  </link>
  <joint name="kinect_depth_joint" type="fixed">
    <origin rpy="0 0 0" xyz="0.0 0.049 0.0"/>
    <parent link="kinect_link"/>
    <child link="kinect_depth_frame"/>
  </joint>
  <link name="kinect_depth_frame"/>
  <joint name="kinect_depth_optical_joint" type="fixed">
    <origin rpy="-1.57079632679 0.0 -1.57079632679" xyz="0 0 0"/>
    <parent link="kinect_depth_frame"/>
    <child link="kinect_depth_optical_frame"/>
  </joint>
  <link name="kinect_depth_optical_frame"/>
  <joint name="kinect_rgb_joint" type="fixed">
    <origin rpy="0 0 0" xyz="0.0 0.022 0.0"/>
    <parent link="kinect_link"/>
    <child link="kinect_rgb_frame"/>
  </joint>
  <link name="kinect_rgb_frame"/>
  <joint name="kinect_rgb_optical_joint" type="fixed">
    <origin rpy="-1.57079632679 0.0 -1.57079632679" xyz="0 0 0"/>
    <parent link="kinect_rgb_frame"/>
    <child link="kinect_rgb_optical_frame"/>
  </joint>
  <link name="kinect_rgb_optical_frame"/>
  <!-- Chassis -->
  <link name="base_center">
    <visual name="base_visual">
      <origin rpy="0 0 0" xyz="-0.045 0 0.148"/>
      <geometry name="pioneer_geom">
        <mesh filename="package://urdf_pkg/meshes/p3dx_meshes/chassis.stl" scale="2 2 2"/>
      </geometry>
      <material name="ChassisYellow">
        <color rgba="0.715 0.583 0.210 1.0"/>
      </material>
    </visual>
  </link>
  <gazebo reference="base_center">
    <material value="Gazebo/Red"/>
  </gazebo>
  <!-- Top -->
  <joint name="base_top_joint" type="fixed">
    <origin rpy="0 0 0" xyz="-0.045 0 0.325"/>
    <parent link="base_center"/>
    <child link="top_plate"/>
  </joint>
  <link name="top_plate">
    <visual>
      <inertial>
        <mass value="0.01"/>
        <origin xyz="0 0 0"/>
        <inertia ixx="1" ixy="0" ixz="0" iyy="1" iyz="0" izz="1"/>
      </inertial>
      <origin rpy="0 0 0" xyz="0 0 0"/>
      <geometry name="top_geom">
        <mesh filename="package://urdf_pkg/meshes/p3dx_meshes/top.stl" scale="2 2 2"/>
      </geometry>
      <material name="TopBlack">
        <color rgba="0.038 0.038 0.038 1.0"/>
      </material>
    </visual>
  </link>
  <gazebo reference="top_plate">
    <material value="Gazebo/Black"/>
  </gazebo>	
<!-- ArmStuff -->

<link name="arm_plate">
	<inertial>
		<mass value="0.01"/>	
		<origin xyz="0 0 0"/>
		<inertia ixx="1" ixy="0" ixz="0" iyy="1" iyz="0" izz="1"/>
	</inertial>
	<visual>			
		<geometry>
			<box size="0.45 0.75 0.05"/>
		</geometry>
		<origin xyz="0.2 0 0.03" rpy="0 0 0"/>
		<material name="brown">
			<color rgba="0.8 0.4 0.3 1"/>
		</material>
	</visual>
</link>

<joint name="arm_plate_joint" type="fixed">
	<parent link="top_plate"/>
	<child link="arm_plate"/>
	<origin xyz="0 0 0"/>
</joint>

	<link name="wam_link_base">
		<inertial>
			<mass value="20"/>
			<origin xyz="0.0 0.0 0.0"/>
			<inertia ixx="1.0" ixy="0.0" ixz="0.0" iyy="1.0" iyz="0.0" izz="1.0"/>
		</inertial>
		<visual>
			<origin rpy="0 0 0" xyz="0 0 0"/>
			<geometry>
				<mesh filename="package://wam_description/mesh/wambase.stl" scale="1.0 1.0 1.0"/>
			</geometry>
			<material name="Grey">
				<color rgba="0.75 0.75 0.75 1.0"/>
			</material>
		</visual>
		<collision>
			<origin rpy="0 0 0" xyz="0.0 0.0 0.0"/>
			<geometry>
				<mesh filename="package://wam_description/mesh/wambase.stl" scale="1.0 1.0 1.0"/>
			</geometry>
			<contact_coefficients kd="1.0" kp="1000.0" mu="0"/>
		</collision>
	</link>
  <joint name="wam_joint_footprint" type="fixed">
    <origin rpy="0 0 0" xyz="0.22 0 0.346"/>
    <child link="wam_link_base"/>
    <parent link="arm_plate"/>
  </joint>
  <gazebo reference="wam_joint_footprint">
    <selfCollide>true</selfCollide>
    <material>Gazebo/Grey</material>
  </gazebo>
  <link name="wam_link_1">
    <inertial>
      <mass value="8.3936"/>
      <origin rpy="0 0 0" xyz="0.0 0.0 0.0"/>
      <inertia ixx="1.0" ixy="0.0" ixz="0.0" iyy="1.0" iyz="0.0" izz="1.0"/>
    </inertial>
    <visual>
      <origin rpy="0 0 0" xyz="0.0 0.0 0.0"/>
      <geometry name="wam_link_1_visual">
        <mesh filename="package://wam_description/mesh/wam1.stl" scale="1.0 1.0 1.0"/>
      </geometry>
      <material name="Grey">
        <color rgba="0.75 0.75 0.75 1.0"/>
      </material>
    </visual>
    <collision>
      <origin rpy="0 0 0" xyz="0.0 0.0 0.0"/>
      <geometry name="wam_link_1_collision">
        <mesh filename="package://wam_description/mesh/wam1.stl" scale="1.0 1.0 1.0"/>
        <!--                <box size="0.20 0.40 0.40"/> -->
      </geometry>
      <contact_coefficients kd="1.0" kp="1000.0" mu="0"/>
    </collision>
  </link>
  <gazebo reference="wam_link_1">
    <material>Gazebo/Grey</material>
    <selfCollide>true</selfCollide>
  </gazebo>
  <joint name="wam_joint_1" type="revolute">
    <parent link="wam_link_base"/>
    <child link="wam_link_1"/>
    <origin rpy="0 0 0" xyz="0.0 0.0 0.0"/>
    <axis xyz="0 0 1"/>
    <limit effort="30" lower="-2.6" upper="2.6" velocity="2.0"/>
    <!-- <safety_controller k_velocity="0.5"/> -->
    <dynamics damping="100"/>
  </joint>
  <transmission name="j1_transmission" type="pr2_mechanism_model/SimpleTransmission">
    <actuator name="j1"/>
    <joint name="wam_joint_1"/>
    <mechanicalReduction>1</mechanicalReduction>
    <motorTorqueConstant>1</motorTorqueConstant>
    <!-- <pulsesPerRevolution>90000</pulsesPerRevolution> -->
  </transmission>
  <link name="wam_link_2">
    <inertial>
      <mass value="4.8487"/>
      <origin rpy="0 0 0" xyz="0 0 0"/>
      <inertia ixx="1.0" ixy="0.0" ixz="0.0" iyy="1.0" iyz="0.0" izz="1.0"/>
    </inertial>
    <visual>
      <origin rpy="0 0 0" xyz="0.0 0.0 0.0"/>
      <geometry name="wam_link_2_visual">
        <mesh filename="package://wam_description/mesh/wam2.stl" scale="1.0 1.0 1.0"/>
      </geometry>
      <material name="Grey">
        <color rgba="0.75 0.75 0.75 1.0"/>
      </material>
    </visual>
    <collision>
      <origin rpy="0 0 0" xyz="0.0 0.0 0.0"/>
      <geometry name="wam_link_2_collision">
        <mesh filename="package://wam_description/mesh/wam2.stl" scale="1.0 1.0 1.0"/>
        <!--                <box size="0.10 0.10 0.10"/> -->
      </geometry>
      <contact_coefficients kd="1.0" kp="1000.0" mu="0"/>
    </collision>
  </link>
  <gazebo reference="wam_link_2">
    <material>Gazebo/Grey</material>
    <selfCollide>true</selfCollide>
  </gazebo>
  <joint name="wam_joint_2" type="revolute">
    <parent link="wam_link_1"/>
    <child link="wam_link_2"/>
    <origin rpy="0 0 0" xyz="0.0 0.0 0.0"/>
    <axis xyz="0 1 0"/>
    <limit effort="30" lower="-2.0" upper="2.0" velocity="2.0"/>
    <!-- <safety_controller k_velocity="0.5"/> -->
    <dynamics damping="100"/>
  </joint>
  <transmission name="j2_transmission" type="pr2_mechanism_model/SimpleTransmission">
    <actuator name="j2"/>
    <joint name="wam_joint_2"/>
    <mechanicalReduction>1</mechanicalReduction>
    <motorTorqueConstant>1</motorTorqueConstant>
    <!-- <pulsesPerRevolution>90000</pulsesPerRevolution> -->
  </transmission>
  <link name="wam_link_3">
    <inertial>
      <mass value="1.7251"/>
      <origin rpy="0 0 0" xyz="0 0 0.225"/>
      <inertia ixx="1.0" ixy="0.0" ixz="0.0" iyy="1.0" iyz="0.0" izz="1.0"/>
    </inertial>
    <visual>
      <origin rpy="0 0 0" xyz="0.0 0.0 0.0"/>
      <geometry name="wam_link_3_visual">
        <mesh filename="package://wam_description/mesh/wam3.stl" scale="1.0 1.0 1.0"/>
      </geometry>
      <material name="Grey">
        <color rgba="0.75 0.75 0.75 1.0"/>
      </material>
    </visual>
    <collision>
      <origin rpy="0 0 0" xyz="0.0 0.0 0.0"/>
      <geometry name="wam_link_3_collision">
        <mesh filename="package://wam_description/mesh/wam3.stl" scale="1.0 1.0 1.0"/>
        <!--                <box size="0.10 0.10 0.10"/> -->
      </geometry>
      <contact_coefficients kd="1.0" kp="1000.0" mu="0"/>
    </collision>
  </link>
  <gazebo reference="wam_link_3">
    <material>Gazebo/Grey</material>
    <selfCollide>true</selfCollide>
  </gazebo>
  <joint name="wam_joint_3" type="revolute">
    <parent link="wam_link_2"/>
    <child link="wam_link_3"/>
    <origin rpy="0 0 0" xyz="0.0 0.0 0.0"/>
    <axis xyz="0 0 1"/>
    <limit effort="30" lower="-2.8" upper="2.8" velocity="2.0"/>
    <!-- <safety_controller k_velocity="0.5"/> -->
    <dynamics damping="100"/>
  </joint>
  <transmission name="j3_transmission" type="pr2_mechanism_model/SimpleTransmission">
    <actuator name="j3"/>
    <joint name="wam_joint_3"/>
    <mechanicalReduction>1</mechanicalReduction>
    <motorTorqueConstant>1</motorTorqueConstant>
    <!-- <pulsesPerRevolution>90000</pulsesPerRevolution> -->
  </transmission>
  <link name="wam_link_4">
    <inertial>
      <mass value="2.0824"/>
      <origin rpy="0 0 0" xyz="-0.045 -0.15 0"/>
      <inertia ixx="1.0" ixy="0.0" ixz="0.0" iyy="1.0" iyz="0.0" izz="1.0"/>
    </inertial>
    <visual>
      <origin rpy="0 0 0" xyz="0.0 0.0 0.0"/>
      <geometry name="wam_link_4_visual">
        <mesh filename="package://wam_description/mesh/wam4.stl" scale="1.0 1.0 1.0"/>
      </geometry>
      <material name="Grey">
        <color rgba="0.75 0.75 0.75 1.0"/>
      </material>
    </visual>
    <collision>
      <origin rpy="0 0 0" xyz="0.0 0.0 0.0"/>
      <geometry name="wam_link_4_collision">
        <mesh filename="package://wam_description/mesh/wam4.stl" scale="1.0 1.0 1.0"/>
        <!--                <box size="0.10 0.10 0.10"/> -->
      </geometry>
      <contact_coefficients kd="1.0" kp="1000.0" mu="0"/>
    </collision>
  </link>
  <gazebo reference="wam_link_4">
    <material>Gazebo/Grey</material>
    <selfCollide>true</selfCollide>
  </gazebo>
  <joint name="wam_joint_4" type="revolute">
    <parent link="wam_link_3"/>
    <child link="wam_link_4"/>
    <origin rpy="-1.57079632679 0 0" xyz="0.045 0.0 0.55"/>
    <axis xyz="0 0 1"/>
    <limit effort="35" lower="-0.9" upper="3.14159265359" velocity="2.0"/>
    <!-- <safety_controller k_velocity="0.5"/> -->
    <dynamics damping="100"/>
  </joint>
  <transmission name="j4_transmission" type="pr2_mechanism_model/SimpleTransmission">
    <actuator name="j4"/>
    <joint name="wam_joint_4"/>
    <mechanicalReduction>1</mechanicalReduction>
    <motorTorqueConstant>1</motorTorqueConstant>
    <!-- <pulsesPerRevolution>90000</pulsesPerRevolution> -->
  </transmission>
  <link name="wam_link_5">
    <inertial>
      <mass value="0.3067"/>
      <origin rpy="0 0 0" xyz="0 0 0"/>
      <inertia ixx="1.0" ixy="0.0" ixz="0.0" iyy="1.0" iyz="0.0" izz="1.0"/>
    </inertial>
    <visual>
      <origin rpy="0 0 0" xyz="0.0 0.0 0.0"/>
      <geometry name="wam_link_5_visual">
        <mesh filename="package://wam_description/mesh/wam5.stl" scale="1.0 1.0 1.0"/>
      </geometry>
      <material name="Grey">
        <color rgba="0.75 0.75 0.75 1.0"/>
      </material>
    </visual>
    <collision>
      <origin rpy="0 0 0" xyz="0.0 0.0 0.0"/>
      <geometry name="wam_link_5_collision">
        <mesh filename="package://wam_description/mesh/wam5.stl" scale="1.0 1.0 1.0"/>
        <!--                <box size="0.10 0.10 0.10"/> -->
      </geometry>
      <contact_coefficients kd="1.0" kp="1000.0" mu="0"/>
    </collision>
  </link>
  <gazebo reference="wam_link_5">
    <material>Gazebo/Grey</material>
    <selfCollide>true</selfCollide>
  </gazebo>
  <joint name="wam_joint_5" type="revolute">
    <parent link="wam_link_4"/>
    <child link="wam_link_5"/>
    <origin rpy="1.57079632679 0 0" xyz="-0.045 -0.3 0.0"/>
    <axis xyz="0 0 1"/>
    <limit effort="30" lower="-4.76" upper="1.24" velocity="2.0"/>
    <!-- <safety_controller k_velocity="0.5"/> -->
    <dynamics damping="100"/>
  </joint>
  <transmission name="j5_transmission" type="pr2_mechanism_model/SimpleTransmission">
    <actuator name="j5"/>
    <joint name="wam_joint_5"/>
    <mechanicalReduction>1</mechanicalReduction>
    <motorTorqueConstant>1</motorTorqueConstant>
    <!-- <pulsesPerRevolution>90000</pulsesPerRevolution> -->
  </transmission>
  <link name="wam_link_6">
    <inertial>
      <mass value="0.4278"/>
      <origin rpy="0 0 0" xyz="0 0 0"/>
      <inertia ixx="1.0" ixy="0.0" ixz="0.0" iyy="1.0" iyz="0.0" izz="1.0"/>
    </inertial>
    <visual>
      <origin rpy="0 0 0" xyz="0.0 0.0 0.0"/>
      <geometry name="wam_link_6_visual">
        <mesh filename="package://wam_description/mesh/wam6.stl" scale="1.0 1.0 1.0"/>
      </geometry>
      <material name="Grey">
        <color rgba="0.75 0.75 0.75 1.0"/>
      </material>
    </visual>
    <collision>
      <origin rpy="0 0 0" xyz="0.0 0.0 0.0"/>
      <geometry name="wam_link_6_collision">
        <mesh filename="package://wam_description/mesh/wam6.stl" scale="1.0 1.0 1.0"/>
        <!--                <box size="0.10 0.10 0.10"/> -->
      </geometry>
      <contact_coefficients kd="1.0" kp="1000.0" mu="0"/>
    </collision>
  </link>
  <gazebo reference="wam_link_6">
    <material>Gazebo/Grey</material>
    <selfCollide>true</selfCollide>
  </gazebo>
  <joint name="wam_joint_6" type="revolute">
    <parent link="wam_link_5"/>
    <child link="wam_link_6"/>
    <origin rpy="-1.57079632679 0 0" xyz="0.0 0.0 0.0"/>
    <axis xyz="0 0 1"/>
    <limit effort="30" lower="-1.6" upper="1.6" velocity="2.0"/>
    <!-- <safety_controller k_velocity="0.5"/> -->
    <dynamics damping="100"/>
  </joint>
  <transmission name="j6_transmission" type="pr2_mechanism_model/SimpleTransmission">
    <actuator name="j6"/>
    <joint name="wam_joint_6"/>
    <mechanicalReduction>1</mechanicalReduction>
    <motorTorqueConstant>1</motorTorqueConstant>
    <!-- <pulsesPerRevolution>90000</pulsesPerRevolution> -->
  </transmission>
  <link name="wam_link_7">
    <inertial>
      <mass value="0.0557"/>
      <origin rpy="0 0 0" xyz="0 0 0"/>
      <inertia ixx="1.0" ixy="0.0" ixz="0.0" iyy="1.0" iyz="0.0" izz="1.0"/>
    </inertial>
    <visual>
      <origin rpy="0 0 0" xyz="0.0 0.0 0.0"/>
      <geometry name="wam_link_7_visual">
        <mesh filename="package://wam_description/mesh/wam7.stl" scale="1.0 1.0 1.0"/>
      </geometry>
      <material name="Grey">
        <color rgba="0.75 0.75 0.75 1.0"/>
      </material>
    </visual>
    <collision>
      <origin rpy="0 0 0" xyz="0.0 0.0 0.0"/>
      <geometry name="wam_link_7_collision">
        <mesh filename="package://wam_description/mesh/wam7.stl" scale="1.0 1.0 1.0"/>
        <!--                <box size="0.10 0.10 0.10"/> -->
      </geometry>
      <contact_coefficients kd="1.0" kp="1000.0" mu="0"/>
    </collision>
  </link>
  <gazebo reference="wam_link_7">
    <material>Gazebo/Grey</material>
    <selfCollide>true</selfCollide>
  </gazebo>
  <joint name="wam_joint_7" type="revolute">
    <parent link="wam_link_6"/>
    <child link="wam_link_7"/>
    <origin rpy="1.57079632679 0 0" xyz="0.0 0.0 0.0"/>
    <axis xyz="0 0 1"/>
    <limit effort="30" lower="-3.0" upper="3.0" velocity="2.0"/>
    <!-- <safety_controller k_velocity="0.5"/> -->
    <dynamics damping="100"/>
  </joint>
  <transmission name="j7_transmission" type="pr2_mechanism_model/SimpleTransmission">
    <actuator name="j7"/>
    <joint name="wam_joint_7"/>
    <mechanicalReduction>1</mechanicalReduction>
    <motorTorqueConstant>1</motorTorqueConstant>
    <!-- <pulsesPerRevolution>90000</pulsesPerRevolution> -->
  </transmission>
  <link name="wam_link_tcp"/>
  <joint name="wam_joint_tcp" type="fixed">
    <parent link="wam_link_7"/>
    <child link="wam_link_tcp"/>
    <origin rpy="0 0 0" xyz="0.0 0.0 0.06"/>
  </joint>
  <link name="bhand_base_link">
    <visual>
      <origin rpy="0 0 0" xyz="0 0 0"/>
      <geometry>
        <mesh filename="package://wam_description/mesh/bh_base.stl"/>
      </geometry>
      <material name="Grey">
        <color rgba="0.5 0.5 0.5 1.0"/>
      </material>
    </visual>
    <collision>
      <origin rpy="0 0 0" xyz="0 0 0"/>
      <geometry>
        <mesh filename="package://wam_description/mesh/bh_base.stl"/>
      </geometry>
      <contact_coefficients kd="1.0" kp="1000.0" mu="0"/>
    </collision>
  </link>
  <joint name="bhand_joint_fixed" type="fixed">
    <parent link="wam_link_7"/>
    <child link="bhand_base_link"/>
    <origin rpy="0 0 0" xyz="0 0 0"/>
    <axis xyz="0 0 1"/>
    <limit effort="30" lower="0.0" upper="3.14159265359" velocity="2.0"/>
  </joint>
  <link name="bhand_finger1_link_1">
    <visual>
      <origin rpy="0 0 0" xyz="0 0 0"/>
      <geometry>
        <mesh filename="package://wam_description/mesh/bh_link1.stl"/>
      </geometry>
      <material name="Grey">
        <color rgba="0.5 0.5 0.5 1.0"/>
      </material>
    </visual>
    <collision>
      <origin rpy="0 0 0" xyz="0 0 0"/>
      <geometry>
        <mesh filename="package://wam_description/mesh/bh_link1.stl"/>
      </geometry>
    </collision>
  </link>
  <joint name="bhand_spread" type="revolute">
    <parent link="bhand_base_link"/>
    <child link="bhand_finger1_link_1"/>
    <origin rpy="0 0 0" xyz="0 -0.025 0.133"/>
    <axis xyz="0 0 -1"/>
    <limit effort="30" lower="0.0" upper="3.14159265359" velocity="2.0"/>
  </joint>
  <link name="bhand_finger2_link_1">
    <visual>
      <origin rpy="0 0 0" xyz="0 0 0"/>
      <geometry>
        <mesh filename="package://wam_description/mesh/bh_link1.stl"/>
      </geometry>
      <material name="Grey">
        <color rgba="0.5 0.5 0.5 1.0"/>
      </material>
    </visual>
    <collision>
      <origin rpy="0 0 0" xyz="0 0 0"/>
      <geometry>
        <mesh filename="package://wam_description/mesh/bh_link1.stl"/>
      </geometry>
    </collision>
  </link>
  <joint name="bhand_spread_finger2" type="revolute">
    <parent link="bhand_base_link"/>
    <child link="bhand_finger2_link_1"/>
    <origin rpy="0 0 0" xyz="0 0.025 0.133"/>
    <axis xyz="0 0 1"/>
    <limit effort="30" lower="0.0" upper="3.14159265359" velocity="2.0"/>
    <mimic joint="bhand_spread" multiplier="1.0" offset="0"/>
  </joint>
  <link name="bhand_finger3_link_1">
    <visual>
      <origin rpy="0 0 0" xyz="0 0 0"/>
      <geometry>
        <mesh filename="package://wam_description/mesh/bh_link1.stl"/>
      </geometry>
      <material name="Grey">
        <color rgba="0.5 0.5 0.5 1.0"/>
      </material>
    </visual>
    <collision>
      <origin rpy="0 0 0" xyz="0 0 0"/>
      <geometry>
        <mesh filename="package://wam_description/mesh/bh_link1.stl"/>
      </geometry>
    </collision>
  </link>
  <joint name="bhand_finger3_joint_1" type="fixed">
    <parent link="bhand_base_link"/>
    <child link="bhand_finger3_link_1"/>
    <origin rpy="0 0 3.14159265359" xyz="0 0 0.133"/>
  </joint>
  <link name="bhand_finger1_link_2">
    <visual>
      <origin rpy="0 0 0" xyz="0 0 0"/>
      <geometry>
        <mesh filename="package://wam_description/mesh/bh_link2.stl"/>
      </geometry>
      <material name="Grey">
        <color rgba="0.5 0.5 0.5 1.0"/>
      </material>
    </visual>
    <collision>
      <origin rpy="0 0 0" xyz="0 0 0"/>
      <geometry>
        <mesh filename="package://wam_description/mesh/bh_link2.stl"/>
      </geometry>
    </collision>
  </link>
  <joint name="bhand_finger1" type="revolute">
    <parent link="bhand_finger1_link_1"/>
    <child link="bhand_finger1_link_2"/>
    <origin rpy="1.57079632679 0 0" xyz="0.050 0 0"/>
    <axis xyz="0 0 1"/>
    <limit effort="30" lower="0.0" upper="2.44346095279" velocity="2.0"/>
  </joint>
  <link name="bhand_finger1_link_3">
    <visual>
      <origin rpy="0 0 0" xyz="0 0 0"/>
      <geometry>
        <mesh filename="package://wam_description/mesh/bh_link3.stl"/>
      </geometry>
      <material name="Grey">
        <color rgba="0.5 0.5 0.5 1.0"/>
      </material>
    </visual>
    <collision>
      <origin rpy="0 0 0" xyz="0 0 0"/>
      <geometry>
        <mesh filename="package://wam_description/mesh/bh_link3.stl"/>
      </geometry>
    </collision>
  </link>
  <joint name="bhand_finger1_joint_3" type="revolute">
    <parent link="bhand_finger1_link_2"/>
    <child link="bhand_finger1_link_3"/>
    <origin rpy="0 0 0.733038285838" xyz="0.070 0 0"/>
    <axis xyz="0 0 1"/>
    <limit effort="30" lower="0" upper="0.837758040957" velocity="2.0"/>
    <mimic joint="bhand_finger1" multiplier="0.342857142857" offset="0"/>
  </joint>
  <link name="bhand_finger2_link_2">
    <visual>
      <origin rpy="0 0 0" xyz="0 0 0"/>
      <geometry>
        <mesh filename="package://wam_description/mesh/bh_link2.stl"/>
      </geometry>
      <material name="Grey">
        <color rgba="0.5 0.5 0.5 1.0"/>
      </material>
    </visual>
    <collision>
      <origin rpy="0 0 0" xyz="0 0 0"/>
      <geometry>
        <mesh filename="package://wam_description/mesh/bh_link2.stl"/>
      </geometry>
    </collision>
  </link>
  <joint name="bhand_finger2" type="revolute">
    <parent link="bhand_finger2_link_1"/>
    <child link="bhand_finger2_link_2"/>
    <origin rpy="1.57079632679 0 0" xyz="0.050 0 0"/>
    <axis xyz="0 0 1"/>
    <limit effort="30" lower="0.0" upper="2.44346095279" velocity="2.0"/>
  </joint>
  <link name="bhand_finger2_link_3">
    <visual>
      <origin rpy="0 0 0" xyz="0 0 0"/>
      <geometry>
        <mesh filename="package://wam_description/mesh/bh_link3.stl"/>
      </geometry>
      <material name="Grey">
        <color rgba="0.5 0.5 0.5 1.0"/>
      </material>
    </visual>
    <collision>
      <origin rpy="0 0 0" xyz="0 0 0"/>
      <geometry>
        <mesh filename="package://wam_description/mesh/bh_link3.stl"/>
      </geometry>
    </collision>
  </link>
  <joint name="bhand_finger2_joint_3" type="revolute">
    <parent link="bhand_finger2_link_2"/>
    <child link="bhand_finger2_link_3"/>
    <origin rpy="0 0 0.733038285838" xyz="0.070 0 0"/>
    <axis xyz="0 0 1"/>
    <limit effort="30" lower="0" upper="0.837758040957" velocity="2.0"/>
    <mimic joint="bhand_finger2" multiplier="0.342857142857" offset="0"/>
  </joint>
  <link name="bhand_finger3_link_2">
    <visual>
      <origin rpy="0 0 0" xyz="0 0 0"/>
      <geometry>
        <mesh filename="package://wam_description/mesh/bh_link2.stl"/>
      </geometry>
      <material name="Grey">
        <color rgba="0.5 0.5 0.5 1.0"/>
      </material>
    </visual>
    <collision>
      <origin rpy="0 0 0" xyz="0 0 0"/>
      <geometry>
        <mesh filename="package://wam_description/mesh/bh_link2.stl"/>
      </geometry>
    </collision>
  </link>
  <joint name="bhand_finger3" type="revolute">
    <parent link="bhand_finger3_link_1"/>
    <child link="bhand_finger3_link_2"/>
    <origin rpy="1.57079632679 0 0" xyz="0.050 0 0"/>
    <axis xyz="0 0 1"/>
    <limit effort="30" lower="0.0" upper="2.44346095279" velocity="2.0"/>
  </joint>
  <link name="bhand_finger3_link_3">
    <visual>
      <origin rpy="0 0 0" xyz="0 0 0"/>
      <geometry>
        <mesh filename="package://wam_description/mesh/bh_link3.stl"/>
      </geometry>
      <material name="Grey">
        <color rgba="0.5 0.5 0.5 1.0"/>
      </material>
    </visual>
    <collision>
      <origin rpy="0 0 0" xyz="0 0 0"/>
      <geometry>
        <mesh filename="package://wam_description/mesh/bh_link3.stl"/>
      </geometry>
    </collision>
  </link>
  <joint name="bhand_finger3_joint_3" type="revolute">
    <parent link="bhand_finger3_link_2"/>
    <child link="bhand_finger3_link_3"/>
    <origin rpy="0 0 0.733038285838" xyz="0.070 0 0"/>
    <axis xyz="0 0 1"/>
    <limit effort="30" lower="0" upper="0.837758040957" velocity="2.0"/>
    <mimic joint="bhand_finger3" multiplier="0.342857142857" offset="0"/>
  </joint>
	
	
	
<!-- Swivel2 -->
	<joint name="base_swivel_joint2" type="continuous">
		<origin xyz="-0.185 0 0.055" rpy="0 0 0"/>
		<anchor xyz="0 0 0"/>
    	<limit effort="100" velocity="100" k_velocity="0" />
    	<joint_properties damping="0.0" friction="0.0" />
		<parent link="base_center"/>
		<child link="swivel2"/>
	</joint>
	<link name="swivel2">
		<inertial>
			<mass value="0.1"/>	
			<origin xyz="0 0 0"/>
			<inertia ixx="0.01" ixy="0" ixz="0"
				 iyy="0.01" iyz="0" izz="0.01"/>
  	 	</inertial>
	<visual name="base_visual">
		<origin xyz="0.16 -0.25 -0.18" rpy="0 0 0"/>
		<geometry name="pioneer_geom">
			<mesh filename="package://urdf_pkg/meshes/p3dx_meshes/swivel.stl" scale="1.5 1.5 1.5"/>
		</geometry>
		<material name="swivel">
			<color rgba="0.5 0.5 0.5 1"/>
		</material>
	</visual>
	<collision>
		<origin xyz="0 0 0" rpy="0 0 0"/>
		<geometry>
			<box size="0 0 0"/>
		</geometry>
	</collision>
	</link>
	<gazebo reference="swivel2">
		<material value="Gazebo/Grey"/>
	</gazebo>

<!-- Center Wheel + Hubcap -->
	<link name="center_hubcap2">
		<inertial>
			<mass value="0.01"/>	
			<origin xyz="0 0 0"/>
			<inertia ixx="0.012411765597" ixy="-0.000711733678" ixz="0.00050272983"
				 iyy="0.015218160428" iyz="-0.000004273467" izz="0.011763977943"/>
  	 	</inertial>
	<visual name="base_visual">
		<origin xyz="0.16 -0.25 -0.18" rpy="0 0 0"/>
		<geometry name="pioneer_geom">
			<mesh filename="package://urdf_pkg/meshes/p3dx_meshes/center_hubcap.stl" scale="1.5 1.5 1.5"/>
		</geometry>
		<material name="swivel">
			<color rgba="0.5 0.5 0.5 1"/>
		</material>
	</visual>
	<collision>
		<origin xyz="0 0 0" rpy="0 0 0"/>
		<geometry>
			<box size="0 0 0"/>
		</geometry>
	</collision>
	</link>
	<gazebo reference="center_hubcap2">
		<material value="Gazebo/Grey"/>
	</gazebo>

	<joint name="swivel_hubcap_joint2" type="continuous">
		<origin xyz="-0.026 0 -0.016" rpy="0 0 0"/>
		<axis xyz="0 1 0"/>
		<anchor xyz="0 0 0"/>
    <limit effort="100" velocity="100" k_velocity="0" />
    <joint_properties damping="0.0" friction="0.0" />
	  <parent link="swivel2"/>
		<child link="center_wheel2"/>
	</joint>

	<link name="center_wheel2">
		<inertial>
			<mass value="0.1"/>	
			<origin xyz="0 0 0"/>
			<inertia ixx="0.012411765597" ixy="-0.000711733678" ixz="0.00050272983"
				 iyy="0.015218160428" iyz="-0.000004273467" izz="0.011763977943"/>
  	 	</inertial>
	<visual name="base_visual">
		<origin xyz="0.16 -0.25 -0.18" rpy="0 0 0"/>
		<geometry name="pioneer_geom">
			<mesh filename="package://urdf_pkg/meshes/p3dx_meshes/center_wheel.stl" scale="1.5 1.5 1.5"/>
		</geometry>
		<material name="WheelBlack">
			<color rgba="0.117 0.117 0.117 1"/>
		</material>
	</visual>
	<collision>
		<origin xyz="0 0 0" rpy=" 0 0 0"/>
		<geometry>
			<mesh filename="package://urdf_pkg/meshes/p3dx_meshes/center_wheel.stl" scale="1.5 1.5 1.5"/>
			<cylinder radius="0.0375" length="0.01"/>
		</geometry>
	</collision>
	</link>
	<gazebo reference="left_hub2">
		<material value="Gazebo/Yellow"/>
	</gazebo>

	<joint name="center_wheel_joint2" type="fixed">
		<origin xyz="-0.0035 0 -0.001" rpy="0 0 0"/>
		<parent link="center_wheel2"/>
		<child link="center_hubcap2"/>
	</joint>



  <!-- Swivel -->
  <joint name="base_swivel_joint" type="continuous">
    <origin rpy="0 0 0" xyz="-0.185 0 0.055"/>
    <axis xyz="0 0 1"/>
    <anchor xyz="0 0 0"/>
    <limit effort="100" k_velocity="0" velocity="100"/>
    <joint_properties damping="0.0" friction="0.0"/>
    <parent link="base_center"/>
    <child link="swivel"/>
  </joint>
  <link name="swivel">
    <inertial>
      <mass value="0.1"/>
      <origin xyz="0 0 0"/>
      <inertia ixx="0.01" ixy="0" ixz="0" iyy="0.01" iyz="0" izz="0.01"/>
    </inertial>
    <visual name="base_visual">
      <origin rpy="0 0 0" xyz="0 0 0"/>
      <geometry name="pioneer_geom">
        <mesh filename="package://urdf_pkg/meshes/p3dx_meshes/swivel.stl"/>
      </geometry>
      <material name="swivel">
        <color rgba="0.5 0.5 0.5 1"/>
      </material>
    </visual>
    <collision>
      <origin rpy="0 0 0" xyz="0 0 0"/>
      <geometry>
        <box size="0 0 0"/>
      </geometry>
    </collision>
  </link>
  <gazebo reference="swivel">
    <material value="Gazebo/Grey"/>
  </gazebo>
  <!-- Center Wheel + Hubcap -->
  <link name="center_hubcap">
    <inertial>
      <mass value="0.01"/>
      <origin xyz="0 0 0"/>
      <inertia ixx="0.012411765597" ixy="-0.000711733678" ixz="0.00050272983" iyy="0.015218160428" iyz="-0.000004273467" izz="0.011763977943"/>
    </inertial>
    <visual name="base_visual">
      <origin rpy="0 0 0" xyz="0 0 0"/>
      <geometry name="pioneer_geom">
        <mesh filename="package://urdf_pkg/meshes/p3dx_meshes/center_hubcap.stl"/>
      </geometry>
      <material name="swivel">
        <color rgba="0.5 0.5 0.5 1"/>
      </material>
    </visual>
    <collision>
      <origin rpy="0 0 0" xyz="0 0 0"/>
      <geometry>
        <box size="0 0 0"/>
      </geometry>
    </collision>
  </link>
  <gazebo reference="center_hubcap">
    <material value="Gazebo/Grey"/>
  </gazebo>
  <joint name="swivel_hubcap_joint" type="continuous">
    <origin rpy="0 0 0" xyz="-0.026 0 -0.016"/>
    <axis xyz="0 1 0"/>
    <anchor xyz="0 0 0"/>
    <limit effort="100" k_velocity="0" velocity="100"/>
    <joint_properties damping="0.0" friction="0.0"/>
    <parent link="swivel"/>
    <child link="center_wheel"/>
  </joint>
  <link name="center_wheel">
    <inertial>
      <mass value="0.1"/>
      <origin xyz="0 0 0"/>
      <inertia ixx="0.012411765597" ixy="-0.000711733678" ixz="0.00050272983" iyy="0.015218160428" iyz="-0.000004273467" izz="0.011763977943"/>
    </inertial>
    <visual name="base_visual">
      <origin rpy="0 0 0" xyz="0 0 0"/>
      <geometry name="pioneer_geom">
        <mesh filename="package://urdf_pkg/meshes/p3dx_meshes/center_wheel.stl"/>
      </geometry>
      <material name="WheelBlack">
        <color rgba="0.117 0.117 0.117 1"/>
      </material>
    </visual>
    <collision>
      <origin rpy="-1.57079635 0 0" xyz="0 0 0"/>
      <geometry>
        <!--<mesh filename="package://p2os_urdf/meshes/p3dx_meshes/center_wheel.stl"/>-->
        <cylinder length="0.01" radius="0.0375"/>
      </geometry>
    </collision>
  </link>
  <joint name="center_wheel_joint" type="fixed">
    <origin rpy="0 0 0" xyz="-0.0035 0 -0.001"/>
    <parent link="center_wheel"/>
    <child link="center_hubcap"/>
  </joint>
  <gazebo reference="center_wheel">
    <material value="Gazebo/Black"/>
    <elem key="mu1" value="10.0"/>
    <elem key="mu2" value="10.0"/>
    <elem key="kp" value="1000000.0"/>
    <elem key="kd" value="1.0"/>
  </gazebo>
  <link name="p3dx_left_wheel">
    <inertial>
      <mass value="0.5"/>
      <origin xyz="0 0 0"/>
      <inertia ixx="0.012411765597" ixy="0" ixz="0" iyy="0.015218160428" iyz="0" izz="0.011763977943"/>
    </inertial>
    <visual name="base_visual">
      <origin rpy="0 0 0" xyz="0 0 0"/>
      <geometry name="pioneer_geom">
        <mesh filename="package://urdf_pkg/meshes/p3dx_meshes/left_wheel.stl"/>
      </geometry>
      <material name="WheelBlack">
        <color rgba="0.117 0.117 0.117 1"/>
      </material>
    </visual>
    <collision>
      <origin rpy="-1.57079635 0 0" xyz="0 0 0"/>
      <geometry>
        <!--<mesh filename="package://p2os_urdf/meshes/p3dx_meshes/${suffix}_wheel.stl"/>-->
        <cylinder length="0.01" radius="0.09"/>
      </geometry>
    </collision>
  </link>
  <joint name="base_left_hubcap_joint" type="fixed">
    <!--<origin xyz="0 ${reflect*0.158} 0.091" rpy="0 0 0"/>-->
    <origin rpy="0 0 0" xyz="0 0 0"/>
    <parent link="p3dx_left_wheel"/>
    <child link="p3dx_left_hubcap"/>
  </joint>
  <link name="p3dx_left_hubcap">
    <inertial>
      <mass value="0.01"/>
      <origin xyz="0 0 0"/>
      <inertia ixx="0.012411765597" ixy="0" ixz="0" iyy="0.015218160428" iyz="0" izz="0.011763977943"/>
    </inertial>
    <visual name="base_visual">
      <origin rpy="0 0 0" xyz="0 0 0"/>
      <geometry name="pioneer_geom">
        <mesh filename="package://urdf_pkg/meshes/p3dx_meshes/left_hubcap.stl"/>
      </geometry>
      <material name="HubcapWhite">
        <color rgba="1.0 1.0 1.0 1.0"/>
      </material>
    </visual>
    <collision>
      <origin rpy="0 0 0" xyz="0 0 0"/>
      <geometry>
        <box size="0 0 0"/>
      </geometry>
    </collision>
  </link>
  <transmission name="base_link_left_wheel_trans" type="pr2_mechanism_model/SimpleTransmission">
    <actuator name="base_left_wheel_motor"/>
    <joint name="base_left_wheel_joint"/>
    <mechanicalReduction>75.0676691729</mechanicalReduction>
  </transmission>
  <joint name="base_left_wheel_joint" type="continuous">
    <axis xyz="0 1 0"/>
    <anchor xyz="0 0 0"/>
    <limit effort="100" velocity="100"/>
    <joint_properties damping="0.0" friction="0.0"/>
    <origin rpy="0 0 0" xyz="0 0.158 0.091"/>
    <parent link="base_center"/>
    <child link="p3dx_left_wheel"/>
  </joint>
  <gazebo reference="p3dx_left_hubcap">
    <material value="Gazebo/Yellow"/>
  </gazebo>
  <gazebo reference="p3dx_left_wheel">
    <material value="Gazebo/Black"/>
    <elem key="mu1" value="0.5"/>
    <elem key="mu2" value="50.0"/>
    <elem key="kp" value="100000000.0"/>
    <elem key="kd" value="1.0"/>
  </gazebo>
  <link name="p3dx_right_wheel">
    <inertial>
      <mass value="0.5"/>
      <origin xyz="0 0 0"/>
      <inertia ixx="0.012411765597" ixy="0" ixz="0" iyy="0.015218160428" iyz="0" izz="0.011763977943"/>
    </inertial>
    <visual name="base_visual">
      <origin rpy="0 0 0" xyz="0 0 0"/>
      <geometry name="pioneer_geom">
        <mesh filename="package://urdf_pkg/meshes/p3dx_meshes/right_wheel.stl"/>
      </geometry>
      <material name="WheelBlack">
        <color rgba="0.117 0.117 0.117 1"/>
      </material>
    </visual>
    <collision>
      <origin rpy="-1.57079635 0 0" xyz="0 0 0"/>
      <geometry>
        <!--<mesh filename="package://p2os_urdf/meshes/p3dx_meshes/${suffix}_wheel.stl"/>-->
        <cylinder length="0.01" radius="0.09"/>
      </geometry>
    </collision>
  </link>
  <joint name="base_right_hubcap_joint" type="fixed">
    <!--<origin xyz="0 ${reflect*0.158} 0.091" rpy="0 0 0"/>-->
    <origin rpy="0 0 0" xyz="0 0 0"/>
    <parent link="p3dx_right_wheel"/>
    <child link="p3dx_right_hubcap"/>
  </joint>
  <link name="p3dx_right_hubcap">
    <inertial>
      <mass value="0.01"/>
      <origin xyz="0 0 0"/>
      <inertia ixx="0.012411765597" ixy="0" ixz="0" iyy="0.015218160428" iyz="0" izz="0.011763977943"/>
    </inertial>
    <visual name="base_visual">
      <origin rpy="0 0 0" xyz="0 0 0"/>
      <geometry name="pioneer_geom">
        <mesh filename="package://urdf_pkg/meshes/p3dx_meshes/right_hubcap.stl"/>
      </geometry>
      <material name="HubcapWhite">
        <color rgba="1.0 1.0 1.0 1.0"/>
      </material>
    </visual>
    <collision>
      <origin rpy="0 0 0" xyz="0 0 0"/>
      <geometry>
        <box size="0 0 0"/>
      </geometry>
    </collision>
  </link>
  <transmission name="base_link_right_wheel_trans" type="pr2_mechanism_model/SimpleTransmission">
    <actuator name="base_right_wheel_motor"/>
    <joint name="base_right_wheel_joint"/>
    <mechanicalReduction>-75.0676691729</mechanicalReduction>
  </transmission>
  <joint name="base_right_wheel_joint" type="continuous">
    <axis xyz="0 1 0"/>
    <anchor xyz="0 0 0"/>
    <limit effort="100" velocity="100"/>
    <joint_properties damping="0.0" friction="0.0"/>
    <origin rpy="0 0 0" xyz="0 -0.158 0.091"/>
    <parent link="base_center"/>
    <child link="p3dx_right_wheel"/>
  </joint>
  <gazebo reference="p3dx_right_hubcap">
    <material value="Gazebo/Yellow"/>
  </gazebo>
  <gazebo reference="p3dx_right_wheel">
    <material value="Gazebo/Black"/>
    <elem key="mu1" value="0.5"/>
    <elem key="mu2" value="50.0"/>
    <elem key="kp" value="100000000.0"/>
    <elem key="kd" value="1.0"/>
  </gazebo>
  <!-- Front + Back Sonar -->
  <link name="front_sonar">
    <inertial>
      <mass value="0.0001"/>
      <origin xyz="0 0 0"/>
      <inertia ixx="1" ixy="0" ixz="0" iyy="1" iyz="0" izz="1"/>
    </inertial>
    <visual name="base_visual">
      <origin rpy="0 0 0" xyz="0 0 0"/>
      <geometry name="pioneer_geom">
        <mesh filename="package://urdf_pkg/meshes/p3dx_meshes/front_sonar.stl"/>
      </geometry>
      <material name="SonarBrown">
        <color rgba="0.206 0.166 0.006 1.0"/>
      </material>
    </visual>
    <collision>
      <origin rpy="0 0 0" xyz="0 0 0"/>
      <geometry>
        <box size="0 0 0"/>
      </geometry>
    </collision>
  </link>
  <gazebo reference="front_sonar">
    <material value="Gazebo/Yellow"/>
  </gazebo>
  <joint name="base_front_joint" type="fixed">
    <origin rpy="0 0 0" xyz="-0.198 0 0.208"/>
    <parent link="base_center"/>
    <child link="front_sonar"/>
  </joint>
  <link name="back_sonar">
    <inertial>
      <mass value="0.0001"/>
      <origin xyz="0 0 0"/>
      <inertia ixx="1" ixy="0" ixz="0" iyy="1" iyz="0" izz="1"/>
    </inertial>
    <visual name="back_sonar_vis">
      <origin rpy="0 0 0" xyz="0 0 0"/>
      <geometry name="pioneer_geom">
        <mesh filename="package://urdf_pkg/meshes/p3dx_meshes/back_sonar.stl"/>
      </geometry>
      <material name="SonarBrown">
        <color rgba="0.206 0.166 0.006 1.0"/>
      </material>
    </visual>
    <collision>
      <origin rpy="0 0 0" xyz="0 0 0"/>
      <geometry>
        <box size="0 0 0"/>
      </geometry>
    </collision>
  </link>
  <gazebo reference="back_sonar">
    <material value="Gazebo/Yellow"/>
  </gazebo>
  <joint name="base_back_joint" type="fixed">
    <origin rpy="0 0 0" xyz="0.109 0 0.209"/>
    <parent link="base_center"/>
    <child link="back_sonar"/>
  </joint>
  <gazebo>
    <controller:differential_position2d name="controller1">
      <update>100</update>
      <leftJoint>base_right_wheel_joint</leftJoint>
      <rightJoint>base_left_wheel_joint</rightJoint>
      <wheelSeparation>0.39</wheelSeparation>
      <wheelDiameter>0.15</wheelDiameter>
      <torque>5</torque>
      <interface:position name="position_iface_0"/>
    </controller:differential_position2d>
    <controller:gazebo_ros_p3d name="p3d_base_controller" plugin="libgazebo_ros_p3d.so">
      <alwaysOn>true</alwaysOn>
      <updateRate>100.0</updateRate>
      <bodyName>base_center</bodyName>
      <topicName>base_pose_ground_truth</topicName>
      <gaussianNoise>0.01</gaussianNoise>
      <frameName>map</frameName>
      <xyzOffsets>0 0 0</xyzOffsets>
      <!-- initialize odometry for fake localization-->
      <rpyOffsets>0 0 0</rpyOffsets>
      <interface:position name="p3d_base_position"/>
    </controller:gazebo_ros_p3d>
    <!-- this publishes empty joint_states due to no transmission, but
         triggering robot_state_puublisher to publish tf between fixed joints in erratic,
         (e.g. base_laser_link for the base_scan frame) -->
    <controller:gazebo_ros_controller_manager name="gazebo_ros_controller_manager" plugin="libgazebo_ros_controller_manager.so">
      <alwaysOn>true</alwaysOn>
      <updateRate>1000.0</updateRate>
      <interface:audio name="gazebo_ros_controller_manager_dummy_iface"/>
    </controller:gazebo_ros_controller_manager>
  </gazebo>
</robot>
