<?xml version="1.0" ?>
<!-- =================================================================================== -->
<!-- |    This document was autogenerated by xacro from ./wam_powerbot.xacro           | -->
<!-- |    EDITING THIS FILE BY HAND IS NOT RECOMMENDED                                 | -->
<!-- =================================================================================== -->
<robot name="wam_powerbot" xmlns:controller="http://playerstage.sourceforge.net/gazebo/xmlschema/#controller" xmlns:interface="http://playerstage.sourceforge.net/gazebo/xmlschema/#interface" xmlns:sensor="http://playerstage.sourceforge.net/gazebo/xmlschema/#sensor" xmlns:xacro="http://ros.org/wiki/xacro">
  <!-- Hollow forearm macros -->
  <!--<xacro:macro name="wam_hollow_forearm" params="prefix">-->
  <!--<joint name="${prefix}/elbow_joint" type="revolute">-->
  <!--<parent link="${prefix}/upper_arm_link"/>-->
  <!--<child link="${prefix}/forearm_link"/>-->
  <!--<origin xyz="0.045 -0.55 0" rpy="${0.5 * PI} 0 0"/>-->
  <!--<axis xyz="0 1 0"/>-->
  <!--<limit effort="15" lower="-0.9" upper="${PI}" velocity="0.50"/>-->
  <!--[> <safety_controller k_position="100" k_velocity="3" soft_lower_limit="-100.0" soft_upper_limit="100.0" /> <]-->
  <!--<dynamics damping="0.1" friction="100.0"/>-->
  <!--</joint>-->
  <!--<link name="${prefix}/forearm_link" >-->
  <!--<inertial>-->
  <!--<origin xyz="0 0 0" />-->
  <!--<mass value="3.20016804" />-->
  <!--<origin xyz="-0.04001488 -.00022942 .13271662" rpy="0 0 0" />-->
  <!--<inertia  ixx="0.01491672" ixy="0.00001741"   ixz="-0.00150604"-->
  <!--iyy="0.01482988"   iyz="-0.00002109"-->
  <!--izz="0.00294463" />-->
  <!--</inertial>-->
  <!--<visual>-->
  <!--<material name="WAMGrey">-->
  <!--<color rgba="0.7 0.7 0.7 1.0"/>-->
  <!--</material>-->
  <!--<origin xyz="0 0 0" rpy="-${PI} 0 0" />-->
  <!--<geometry>-->
  <!--<mesh filename="${models_path}/meshes/wamForeArmLink4.DAE"/>-->
  <!--</geometry>-->
  <!--</visual>-->
  <!--<collision>-->
  <!--<origin xyz="0 0 0" rpy="-${PI} 0 0" />-->
  <!--<geometry>-->
  <!--<mesh filename="${models_path}/meshes/wamForeArmLink4.stl"/>-->
  <!--</geometry>-->
  <!--</collision>-->
  <!--</link>-->
  <!--</xacro:macro>-->
  <!--<xacro:macro name="wam_hollow_wrist" params="prefix">-->
  <!--<joint name="${prefix}/UpperWristJoint" type="fixed">-->
  <!--<parent link="${prefix}/ForeArmLink"/>-->
  <!--<child link="${prefix}/LowerWristPalmLink"/>-->
  <!--<origin xyz="-0.045 0 .35" rpy="-${0.5 * PI} 0 ${0.5 * PI}"/>-->
  <!--<axis xyz="0 -1 0"/>-->
  <!--<limit effort="5" lower="-4.8" upper="1.3" velocity="0.20"/>-->
  <!--[> <safety_controller k_position="100" k_velocity="3" soft_lower_limit="-100.0" soft_upper_limit="100.0" /> <]-->
  <!--<dynamics damping="0.1" friction="100.0"/>-->
  <!--</joint>-->
  <!--<link name="${prefix}/LowerWristPalmLink" >-->
  <!--<inertial>-->
  <!--<origin xyz="0.00008921 0.00511217 0.00435824" />-->
  <!--<mass value="1.12376019" />-->
  <!--<inertia  ixx="0.00005029" ixy="0.00000020"  ixz="0.00007582"-->
  <!--iyy="0.00007582"  iyz="-0.00000359"-->
  <!--izz="0.00006270" />-->
  <!--</inertial>-->
  <!--<visual>-->
  <!--<material name="WAMGrey">-->
  <!--<color rgba="0.7 0.7 0.7 1.0"/>-->
  <!--</material>-->
  <!--<origin xyz="0 0.02711 0" rpy="${PI} 0 0" />-->
  <!--<geometry>-->
  <!--<mesh filename="${models_path}/meshes/wamUpperWristYawLink.DAE"/>-->
  <!--</geometry>-->
  <!--</visual>-->
  <!--<collision>-->
  <!--<origin xyz="0 0.02711 0" rpy="${PI} 0 0" />-->
  <!--<geometry>-->
  <!--<mesh filename="${models_path}/meshes/wamUpperWristYawLink5.stl"/>-->
  <!--</geometry>-->
  <!--</collision>-->
  <!--</link>-->
  <!--</xacro:macro>-->
  <!-- Palm with ForceTorque macros -->
  <!--<xacro:macro name="LowerWristFT" params="prefix">-->
  <!--<joint name="${prefix}/LowerWristYawJoint" type="revolute">-->
  <!--<parent link="${prefix}/UpperWristPitchLink"/>-->
  <!--<child link="${prefix}/LowerWristYawLink"/>-->
  <!--<origin xyz="0 0 0.06713340" rpy="0 0 0"/>-->
  <!--<axis xyz="0 0 1"/>-->
  <!--<limit effort="5" lower="-2.95" upper="2.95" velocity="0.20"/>[> 2.95 is a limit taken in from 3 due to saftey and differences between arms. <]-->
  <!--[> <safety_controller k_position="100" k_velocity="3" soft_lower_limit="-100.0" soft_upper_limit="100.0" /> <]-->
  <!--<dynamics damping="0.1" friction="100.0"/>-->
  <!--</joint>-->
  <!--<link name="${prefix}/LowerWristYawLink" >-->
  <!--<inertial>-->
  <!--<origin xyz="-0.00000134 -0.00228167 -0.00000141" rpy="0 0 0" />-->
  <!--<mass value="0.17286134" />-->
  <!--<inertia  ixx="0.00010859" ixy="0.00000000"  ixz="-0.00000000"-->
  <!--iyy="0.00020683"  iyz="-0.0000000"-->
  <!--izz="0.00010851" />-->
  <!--</inertial>-->
  <!--<visual>-->
  <!--<material name="WAMGrey">-->
  <!--<color rgba="0.7 0.7 0.7 1.0"/>-->
  <!--</material>-->
  <!--<origin xyz="0 0 0" rpy="0 0 0" />-->
  <!--<geometry>-->
  <!--<mesh filename="${models_path}/meshes/forceTorqueSensor.DAE"/>-->
  <!--</geometry>-->
  <!--</visual>-->
  <!--<collision>-->
  <!--<origin xyz="0 0 0" rpy="0 0 0" />-->
  <!--<geometry>-->
  <!--<mesh filename="${models_path}/meshes/forceTorqueSensor.stl"/>-->
  <!--</geometry>-->
  <!--</collision>-->
  <!--</link>-->
  <!--</xacro:macro>-->
  <!-- Hollow forearm macros -->
  <!--<xacro:macro name="wam_hollow_forearm" params="prefix">-->
  <!--<joint name="${prefix}/elbow_joint" type="revolute">-->
  <!--<parent link="${prefix}/upper_arm_link"/>-->
  <!--<child link="${prefix}/forearm_link"/>-->
  <!--<origin xyz="0.045 -0.55 0" rpy="${0.5 * PI} 0 0"/>-->
  <!--<axis xyz="0 1 0"/>-->
  <!--<limit effort="15" lower="-0.9" upper="${PI}" velocity="0.50"/>-->
  <!--[> <safety_controller k_position="100" k_velocity="3" soft_lower_limit="-100.0" soft_upper_limit="100.0" /> <]-->
  <!--<dynamics damping="0.1" friction="100.0"/>-->
  <!--</joint>-->
  <!--<link name="${prefix}/forearm_link" >-->
  <!--<inertial>-->
  <!--<origin xyz="0 0 0" />-->
  <!--<mass value="3.20016804" />-->
  <!--<origin xyz="-0.04001488 -.00022942 .13271662" rpy="0 0 0" />-->
  <!--<inertia  ixx="0.01491672" ixy="0.00001741"   ixz="-0.00150604"-->
  <!--iyy="0.01482988"   iyz="-0.00002109"-->
  <!--izz="0.00294463" />-->
  <!--</inertial>-->
  <!--<visual>-->
  <!--<material name="WAMGrey">-->
  <!--<color rgba="0.7 0.7 0.7 1.0"/>-->
  <!--</material>-->
  <!--<origin xyz="0 0 0" rpy="-${PI} 0 0" />-->
  <!--<geometry>-->
  <!--<mesh filename="${models_path}/meshes/wamForeArmLink4.DAE"/>-->
  <!--</geometry>-->
  <!--</visual>-->
  <!--<collision>-->
  <!--<origin xyz="0 0 0" rpy="-${PI} 0 0" />-->
  <!--<geometry>-->
  <!--<mesh filename="${models_path}/meshes/wamForeArmLink4.stl"/>-->
  <!--</geometry>-->
  <!--</collision>-->
  <!--</link>-->
  <!--</xacro:macro>-->
  <!--<xacro:macro name="wam_hollow_wrist" params="prefix">-->
  <!--<joint name="${prefix}/UpperWristJoint" type="fixed">-->
  <!--<parent link="${prefix}/ForeArmLink"/>-->
  <!--<child link="${prefix}/LowerWristPalmLink"/>-->
  <!--<origin xyz="-0.045 0 .35" rpy="-${0.5 * PI} 0 ${0.5 * PI}"/>-->
  <!--<axis xyz="0 -1 0"/>-->
  <!--<limit effort="5" lower="-4.8" upper="1.3" velocity="0.20"/>-->
  <!--[> <safety_controller k_position="100" k_velocity="3" soft_lower_limit="-100.0" soft_upper_limit="100.0" /> <]-->
  <!--<dynamics damping="0.1" friction="100.0"/>-->
  <!--</joint>-->
  <!--<link name="${prefix}/LowerWristPalmLink" >-->
  <!--<inertial>-->
  <!--<origin xyz="0.00008921 0.00511217 0.00435824" />-->
  <!--<mass value="1.12376019" />-->
  <!--<inertia  ixx="0.00005029" ixy="0.00000020"  ixz="0.00007582"-->
  <!--iyy="0.00007582"  iyz="-0.00000359"-->
  <!--izz="0.00006270" />-->
  <!--</inertial>-->
  <!--<visual>-->
  <!--<material name="WAMGrey">-->
  <!--<color rgba="0.7 0.7 0.7 1.0"/>-->
  <!--</material>-->
  <!--<origin xyz="0 0.02711 0" rpy="${PI} 0 0" />-->
  <!--<geometry>-->
  <!--<mesh filename="${models_path}/meshes/wamUpperWristYawLink.DAE"/>-->
  <!--</geometry>-->
  <!--</visual>-->
  <!--<collision>-->
  <!--<origin xyz="0 0.02711 0" rpy="${PI} 0 0" />-->
  <!--<geometry>-->
  <!--<mesh filename="${models_path}/meshes/wamUpperWristYawLink5.stl"/>-->
  <!--</geometry>-->
  <!--</collision>-->
  <!--</link>-->
  <!--</xacro:macro>-->
  <!-- Palm with ForceTorque macros -->
  <!--<xacro:macro name="LowerWristFT" params="prefix">-->
  <!--<joint name="${prefix}/LowerWristYawJoint" type="revolute">-->
  <!--<parent link="${prefix}/UpperWristPitchLink"/>-->
  <!--<child link="${prefix}/LowerWristYawLink"/>-->
  <!--<origin xyz="0 0 0.06713340" rpy="0 0 0"/>-->
  <!--<axis xyz="0 0 1"/>-->
  <!--<limit effort="5" lower="-2.95" upper="2.95" velocity="0.20"/>[> 2.95 is a limit taken in from 3 due to saftey and differences between arms. <]-->
  <!--[> <safety_controller k_position="100" k_velocity="3" soft_lower_limit="-100.0" soft_upper_limit="100.0" /> <]-->
  <!--<dynamics damping="0.1" friction="100.0"/>-->
  <!--</joint>-->
  <!--<link name="${prefix}/LowerWristYawLink" >-->
  <!--<inertial>-->
  <!--<origin xyz="-0.00000134 -0.00228167 -0.00000141" rpy="0 0 0" />-->
  <!--<mass value="0.17286134" />-->
  <!--<inertia  ixx="0.00010859" ixy="0.00000000"  ixz="-0.00000000"-->
  <!--iyy="0.00020683"  iyz="-0.0000000"-->
  <!--izz="0.00010851" />-->
  <!--</inertial>-->
  <!--<visual>-->
  <!--<material name="WAMGrey">-->
  <!--<color rgba="0.7 0.7 0.7 1.0"/>-->
  <!--</material>-->
  <!--<origin xyz="0 0 0" rpy="0 0 0" />-->
  <!--<geometry>-->
  <!--<mesh filename="${models_path}/meshes/forceTorqueSensor.DAE"/>-->
  <!--</geometry>-->
  <!--</visual>-->
  <!--<collision>-->
  <!--<origin xyz="0 0 0" rpy="0 0 0" />-->
  <!--<geometry>-->
  <!--<mesh filename="${models_path}/meshes/forceTorqueSensor.stl"/>-->
  <!--</geometry>-->
  <!--</collision>-->
  <!--</link>-->
  <!--</xacro:macro>-->
  <!-- Materials -->
  <material name="WAMGrey">
    <color rgba="0.7 0.7 0.7 1.0"/>
  </material>
  <!--<xacro:include filename="$(find p2os_urdf)/defs/materials.xacro"/>-->
  <!-- 0.148 -->
  <!-- Brown arm plate -->
  <link name="arm_plate">
    <inertial>
      <mass value="0.01"/>
      <origin rpy="0 0 0" xyz="0.2 0 0.03"/>
      <inertia ixx="1" ixy="0" ixz="0" iyy="1" iyz="0" izz="1"/>
    </inertial>
    <visual>
      <geometry>
        <box size="0.45 0.75 0.05"/>
      </geometry>
      <origin rpy="0 0 0" xyz="0.2 0 0.03"/>
      <material name="brown">
        <color rgba="0.8 0.4 0.3 1"/>
      </material>
    </visual>
    <collision>
      <origin rpy="0 0 0" xyz="0.2 0 0.03"/>
      <geometry>
        <box size="0.45 0.75 0.05"/>
      </geometry>
    </collision>
  </link>
  <joint name="arm_plate_joint" type="fixed">
    <parent link="top_plate"/>
    <child link="arm_plate"/>
    <origin xyz="0 0 0"/>
  </joint>
  <!-- Chassis -->
  <link name="base_center">
    <inertial>
      <mass value="200.0"/>
      <origin xyz="-0.045 0 0.067"/>
      <inertia ixx="0.4255" ixy="0.0" ixz="0.0" iyy="0.4955" iyz="0.0" izz="0.7441"/>
    </inertial>
    <visual name="base_visual">
      <origin rpy="0 0 0" xyz="-0.045 0 0.067"/>
      <geometry name="pioneer_geom">
        <mesh filename="package://champ_description/meshes/p3dx_meshes/chassis.stl"/>
      </geometry>
      <material name="ChassisYellow">
        <color rgba="0.715 0.583 0.210 1.0"/>
      </material>
    </visual>
    <collision>
      <origin rpy="0 0 0" xyz="-0.045 0 0.067"/>
      <geometry>
        <mesh filename="package://champ_description/meshes/p3dx_meshes/chassis.stl"/>
      </geometry>
    </collision>
  </link>
  <gazebo reference="base_center">
    <material value="Gazebo/Yellow"/>
  </gazebo>
  <!-- Top -->
  <joint name="base_top_joint" type="fixed">
    <!--origin xyz="-0.045 0 0.325" rpy="0 0 0"/-->
    <origin rpy="0 0 0" xyz="-0.045 0 0.277"/>
    <parent link="base_center"/>
    <child link="top_plate"/>
  </joint>
  <!-- Top plate -->
  <link name="top_plate">
    <inertial>
      <mass value="0.1"/>
      <origin xyz="0 0 0"/>
      <inertia ixx="1" ixy="0" ixz="0" iyy="1" iyz="0" izz="1"/>
    </inertial>
    <visual>
      <origin rpy="0 0 0" xyz="0 0 0"/>
      <geometry name="top_geom">
        <mesh filename="package://champ_description/meshes/p3dx_meshes/top.stl"/>
      </geometry>
      <material name="TopBlack">
        <color rgba="0.038 0.038 0.038 1.0"/>
      </material>
    </visual>
    <collision>
      <origin rpy="0 0 0" xyz="0 0 0"/>
      <geometry>
        <mesh filename="package://champ_description/meshes/p3dx_meshes/top.stl"/>
      </geometry>
    </collision>
  </link>
  <gazebo reference="top_plate">
    <material value="Gazebo/Black"/>
  </gazebo>
  <!-- Right Swivel support-->
  <link name="right_swivel_support">
    <inertial>
      <mass value="0.1"/>
      <origin rpy="0 0 0" xyz="0 0 0"/>
      <inertia ixx="0.01" ixy="0" ixz="0" iyy="0.01" iyz="0" izz="0.01"/>
    </inertial>
    <visual name="right_swivel_support_visual">
      <origin rpy="0 0 0" xyz="0 0 0"/>
      <geometry name="swivel">
        <mesh filename="package://champ_description/meshes/p3dx_meshes/swivel_support.stl"/>
      </geometry>
      <material name="swivel">
        <color rgba="0.9 0.9 0.9 1"/>
      </material>
    </visual>
    <collision>
      <origin rpy="0 0 0" xyz="0 0 0"/>
      <geometry>
        <mesh filename="package://champ_description/meshes/p3dx_meshes/swivel_support.stl"/>
      </geometry>
    </collision>
  </link>
  <gazebo reference="swivel">
    <material value="Gazebo/Grey"/>
  </gazebo>
  <joint name="right_base_swivel_support_joint" type="fixed">
    <origin rpy="0 0 0" xyz="-0.215 -0.2 -0.091"/>
    <parent link="base_center"/>
    <child link="right_swivel_support"/>
  </joint>
  <!-- Right Swivel -->
  <link name="right_swivel">
    <inertial>
      <mass value="0.1"/>
      <origin rpy="0 0 0" xyz="0 0 0"/>
      <inertia ixx="0.01" ixy="0" ixz="0" iyy="0.01" iyz="0" izz="0.01"/>
    </inertial>
    <visual name="right_swivel_visual">
      <origin rpy="0 0 0" xyz="0 0 0"/>
      <geometry name="swivel">
        <mesh filename="package://champ_description/meshes/p3dx_meshes/swivel.stl"/>
      </geometry>
      <material name="swivel">
        <color rgba="0.5 0.5 0.5 1"/>
      </material>
    </visual>
    <collision>
      <origin rpy="0 0 0" xyz="0 0 0"/>
      <geometry>
        <mesh filename="package://champ_description/meshes/p3dx_meshes/swivel.stl"/>
      </geometry>
    </collision>
  </link>
  <gazebo reference="swivel">
    <material value="Gazebo/Grey"/>
  </gazebo>
  <joint name="right_base_swivel_joint" type="fixed">
    <origin rpy="0 0 0" xyz="0 0 -0.04855"/>
    <!--<axis xyz="0 0 1"/>
	    	<limit effort="100" velocity="100" k_velocity="0" />
	    	<joint_properties damping="0.0" friction="0.0" />-->
    <parent link="right_swivel_support"/>
    <child link="right_swivel"/>
  </joint>
  <!-- Right swivel Wheel + Hubcap -->
  <link name="right_swivel_hubcap">
    <inertial>
      <mass value="0.01"/>
      <origin xyz="0 0 0"/>
      <inertia ixx="0.012411765597" ixy="-0.000711733678" ixz="0.00050272983" iyy="0.015218160428" iyz="-0.000004273467" izz="0.011763977943"/>
    </inertial>
    <visual name="right_swivel_hubcap">
      <origin rpy="0 0 0" xyz="0 0 0"/>
      <geometry name="pioneer_geom">
        <mesh filename="package://champ_description/meshes/p3dx_meshes/center_hubcap.stl"/>
      </geometry>
      <material name="swivel">
        <color rgba="0.5 0.5 0.5 1"/>
      </material>
    </visual>
    <collision>
      <origin rpy="0 0 0" xyz="0 0 0"/>
      <geometry>
        <mesh filename="package://champ_description/meshes/p3dx_meshes/center_hubcap.stl"/>
      </geometry>
    </collision>
  </link>
  <gazebo reference="swivel_hubcap">
    <material value="Gazebo/Grey"/>
  </gazebo>
  <joint name="right_swivel_hubcap_joint" type="continuous">
    <origin rpy="0 0 0" xyz="-0.036 0 -0.029"/>
    <axis xyz="0 1 0"/>
    <anchor xyz="0 0 0"/>
    <limit effort="100" k_velocity="0" velocity="100"/>
    <joint_properties damping="7.0" friction="0.0"/>
    <parent link="right_swivel"/>
    <child link="right_swivel_hubcap"/>
  </joint>
  <link name="right_swivel_wheel">
    <inertial>
      <mass value="0.1"/>
      <origin xyz="0 0 0"/>
      <inertia ixx="0.012411765597" ixy="-0.000711733678" ixz="0.00050272983" iyy="0.015218160428" iyz="-0.000004273467" izz="0.011763977943"/>
    </inertial>
    <visual name="right_swivel_wheel">
      <origin rpy="0 0 0" xyz="0 0 0"/>
      <geometry name="swivel_wheel">
        <mesh filename="package://champ_description/meshes/p3dx_meshes/center_wheel.stl"/>
      </geometry>
      <material name="WheelBlack">
        <color rgba="0.117 0.117 0.117 1"/>
      </material>
    </visual>
    <collision>
      <origin rpy=" -1.57079635 0 0" xyz="0 0 0"/>
      <geometry>
        <cylinder length="0.0422" radius="0.0669"/>
      </geometry>
    </collision>
  </link>
  <gazebo reference="swivel_wheel">
    <material value="Gazebo/Black"/>
  </gazebo>
  <joint name="right_swivel_wheel_hubcap_joint" type="fixed">
    <origin rpy="0 0 0" xyz="0 0 0"/>
    <parent link="right_swivel_hubcap"/>
    <child link="right_swivel_wheel"/>
  </joint>
  <!-- Left Swivel support-->
  <link name="left_swivel_support">
    <inertial>
      <mass value="0.1"/>
      <origin rpy="0 0 0" xyz="0 0 0"/>
      <inertia ixx="0.01" ixy="0" ixz="0" iyy="0.01" iyz="0" izz="0.01"/>
    </inertial>
    <visual name="left_swivel_support_visual">
      <origin rpy="0 0 0" xyz="0 0 0"/>
      <geometry name="swivel">
        <mesh filename="package://champ_description/meshes/p3dx_meshes/swivel_support.stl"/>
      </geometry>
      <material name="swivel">
        <color rgba="0.9 0.9 0.9 1"/>
      </material>
    </visual>
    <collision>
      <origin rpy="0 0 0" xyz="0 0 0"/>
      <geometry>
        <mesh filename="package://champ_description/meshes/p3dx_meshes/swivel_support.stl"/>
      </geometry>
    </collision>
  </link>
  <gazebo reference="swivel">
    <material value="Gazebo/Grey"/>
  </gazebo>
  <joint name="left_base_swivel_support_joint" type="fixed">
    <origin rpy="0 0 0" xyz="-0.215 0.2 -0.091"/>
    <parent link="base_center"/>
    <child link="left_swivel_support"/>
  </joint>
  <!--Left Swivel -->
  <link name="left_swivel">
    <inertial>
      <mass value="0.1"/>
      <origin rpy="0 0 0" xyz="0 0 0"/>
      <inertia ixx="0.01" ixy="0" ixz="0" iyy="0.01" iyz="0" izz="0.01"/>
    </inertial>
    <visual name="left_swivel_visual">
      <origin rpy="0 0 0" xyz="0 0 0"/>
      <geometry name="swivel">
        <mesh filename="package://champ_description/meshes/p3dx_meshes/swivel.stl"/>
      </geometry>
      <material name="swivel">
        <color rgba="0.5 0.5 0.5 1"/>
      </material>
    </visual>
    <collision>
      <origin rpy="0 0 0" xyz="0 0 0"/>
      <geometry>
        <mesh filename="package://champ_description/meshes/p3dx_meshes/swivel.stl"/>
      </geometry>
    </collision>
  </link>
  <gazebo reference="swivel">
    <material value="Gazebo/Grey"/>
  </gazebo>
  <joint name="left_base_swivel_joint" type="fixed">
    <origin rpy="0 0 0" xyz="0 0 -0.04855"/>
    <!--	<axis xyz="0 0 1"/>
         <limit effort="100" velocity="100" k_velocity="0" />
    	<joint_properties damping="0.0" friction="0.0" />-->
    <parent link="left_swivel_support"/>
    <child link="left_swivel"/>
  </joint>
  <!-- left swivel Wheel + Hubcap -->
  <link name="left_swivel_hubcap">
    <inertial>
      <mass value="0.01"/>
      <origin xyz="0 0 0"/>
      <inertia ixx="0.012411765597" ixy="-0.000711733678" ixz="0.00050272983" iyy="0.015218160428" iyz="-0.000004273467" izz="0.011763977943"/>
    </inertial>
    <visual name="left_swivel_hubcap">
      <origin rpy="0 0 0" xyz="0 0 0"/>
      <geometry name="pioneer_geom">
        <mesh filename="package://champ_description/meshes/p3dx_meshes/center_hubcap.stl"/>
      </geometry>
      <material name="swivel">
        <color rgba="0.5 0.5 0.5 1"/>
      </material>
    </visual>
    <collision>
      <origin rpy="0 0 0" xyz="0 0 0"/>
      <geometry>
        <mesh filename="package://champ_description/meshes/p3dx_meshes/center_hubcap.stl"/>
      </geometry>
    </collision>
  </link>
  <gazebo reference="swivel_hubcap">
    <material value="Gazebo/Grey"/>
  </gazebo>
  <joint name="left_swivel_hubcap_joint" type="continuous">
    <origin rpy="0 0 0" xyz="-0.036 0 -0.029"/>
    <axis xyz="0 1 0"/>
    <anchor xyz="0 0 0"/>
    <limit effort="100" k_velocity="0" velocity="100"/>
    <joint_properties damping="7.0" friction="0.0"/>
    <parent link="left_swivel"/>
    <child link="left_swivel_hubcap"/>
  </joint>
  <link name="left_swivel_wheel">
    <inertial>
      <mass value="0.1"/>
      <origin xyz="0 0 0"/>
      <inertia ixx="0.012411765597" ixy="-0.000711733678" ixz="0.00050272983" iyy="0.015218160428" iyz="-0.000004273467" izz="0.011763977943"/>
    </inertial>
    <visual name="left_swivel_wheel">
      <origin rpy="0 0 0" xyz="0 0 0"/>
      <geometry name="swivel_wheel">
        <mesh filename="package://champ_description/meshes/p3dx_meshes/center_wheel.stl"/>
      </geometry>
      <material name="WheelBlack">
        <color rgba="0.117 0.117 0.117 1"/>
      </material>
    </visual>
    <collision>
      <origin rpy=" -1.57079635 0 0" xyz="0 0 0"/>
      <geometry>
        <cylinder length="0.0422" radius="0.0669"/>
      </geometry>
    </collision>
  </link>
  <gazebo reference="right_wheel">
    <material value="Gazebo/Black"/>
  </gazebo>
  <joint name="left_swivel_wheel_hubcap_joint" type="fixed">
    <origin rpy="0 0 0" xyz="0 0 0"/>
    <parent link="left_swivel_hubcap"/>
    <child link="left_swivel_wheel"/>
  </joint>
  <!--Left Wheel and hub-->
  <link name="left_hubcap">
    <inertial>
      <mass value="0.08"/>
      <origin xyz="0 0 0"/>
      <inertia ixx="0.012411765597" ixy="0" ixz="0" iyy="0.015218160428" iyz="0" izz="0.011763977943"/>
    </inertial>
    <visual>
      <origin rpy="0 0 0" xyz="0 0 0"/>
      <geometry>
        <mesh filename="package://champ_description/meshes/p3dx_meshes/hubcap.stl"/>
      </geometry>
      <material name="HubcapWhite">
        <color rgba="1.0 1.0 1.0 1.0"/>
      </material>
    </visual>
    <collision>
      <origin rpy="0 0 0" xyz="0 0 0"/>
      <geometry>
        <mesh filename="package://champ_description/meshes/p3dx_meshes/hubcap.stl"/>
      </geometry>
    </collision>
  </link>
  <joint name="left_hub_joint" type="continuous">
    <origin rpy="0 0 0" xyz="0.084 0.35 -0.0835"/>
    <anchor xyz="0 0 0"/>
    <limit effort="100" velocity="100"/>
    <joint_properties damping="0.0" friction="0.0"/>
    <parent link="base_center"/>
    <child link="left_hubcap"/>
    <axis xyz="0 1 0"/>
  </joint>
  <link name="left_wheel">
    <inertial>
      <mass value="10.25"/>
      <origin xyz="0 0 0"/>
      <inertia ixx="0.012411765597" ixy="0" ixz="0" iyy="0.015218160428" iyz="0" izz="0.011763977943"/>
    </inertial>
    <visual>
      <origin rpy="0 0 0" xyz="0 0 0"/>
      <geometry>
        <mesh filename="package://champ_description/meshes/p3dx_meshes/wheel.stl"/>
      </geometry>
      <material name="WheelBlack">
        <color rgba="0.117 0.117 0.117 1"/>
      </material>
    </visual>
    <collision>
      <origin rpy="-1.57079635 0 0" xyz="0 0 0"/>
      <geometry>
        <cylinder length="0.065" radius="0.1315"/>
      </geometry>
    </collision>
  </link>
  <joint name="left_wheel_joint" type="fixed">
    <origin rpy="0 0 0" xyz="0 0 0"/>
    <parent link="left_hubcap"/>
    <child link="left_wheel"/>
  </joint>
  <gazebo reference="left_wheel">
    <material value="Gazebo/Black"/>
  </gazebo>
  <!--Right Wheel and hub-->
  <link name="right_hubcap">
    <inertial>
      <mass value="0.08"/>
      <origin xyz="0 0 0"/>
      <inertia ixx="0.012411765597" ixy="0" ixz="0" iyy="0.015218160428" iyz="0" izz="0.011763977943"/>
    </inertial>
    <visual>
      <origin rpy="0 0 0" xyz="0 0 0"/>
      <geometry>
        <mesh filename="package://champ_description/meshes/p3dx_meshes/hubcap.stl"/>
      </geometry>
      <material name="HubcapWhite">
        <color rgba="1.0 1.0 1.0 1.0"/>
      </material>
    </visual>
    <collision>
      <origin rpy="0 0 0" xyz="0 0 0"/>
      <geometry>
        <mesh filename="package://champ_description/meshes/p3dx_meshes/hubcap.stl"/>
      </geometry>
    </collision>
  </link>
  <joint name="right_hub_joint" type="continuous">
    <origin rpy="0 0 0" xyz="0.084 -0.35 -0.0835"/>
    <anchor xyz="0 0 0"/>
    <limit effort="100" velocity="100"/>
    <joint_properties damping="0.0" friction="0.0"/>
    <parent link="base_center"/>
    <child link="right_hubcap"/>
    <axis xyz="0 1 0"/>
  </joint>
  <link name="right_wheel">
    <inertial>
      <mass value="10.25"/>
      <origin xyz="0 0 0"/>
      <inertia ixx="0.012411765597" ixy="0" ixz="0" iyy="0.015218160428" iyz="0" izz="0.011763977943"/>
    </inertial>
    <visual>
      <origin rpy="0 0 0" xyz="0 0 0"/>
      <geometry>
        <mesh filename="package://champ_description/meshes/p3dx_meshes/wheel.stl"/>
      </geometry>
      <material name="WheelBlack">
        <color rgba="0.117 0.117 0.117 1"/>
      </material>
    </visual>
    <collision>
      <origin rpy="-1.57079635 0 0" xyz="0 0 0"/>
      <geometry>
        <cylinder length="0.065" radius="0.1315"/>
      </geometry>
    </collision>
  </link>
  <joint name="right_wheel_joint" type="fixed">
    <origin rpy="0 0 0" xyz="0 0 0"/>
    <parent link="right_hubcap"/>
    <child link="right_wheel"/>
  </joint>
  <gazebo reference="right_wheel">
    <material value="Gazebo/Black"/>
  </gazebo>
  <joint name="kinect_joint" type="fixed">
    <origin rpy="0.0202643 0.415979 0.0134257" xyz="0.451798 0.0081349 0.461428"/>
    <parent link="base_center"/>
    <child link="kinect_link"/>
  </joint>
  <link name="kinect_link">
    <inertial>
      <mass value="0.200"/>
      <origin rpy="0 0 0" xyz="0 0 0"/>
      <inertia ixx="5.8083e-4" ixy="0" ixz="0" iyy="3.0833e-5" iyz="0" izz="5.9083e-4"/>
    </inertial>
    <visual>
      <origin rpy="0 0 0" xyz="0 0 0"/>
      <!--
          <geometry>
            <box size="0.05 0.2 0.04"/>   <box size="0.035 0.185 0.025"/>
          </geometry>
          -->
      <geometry>
        <mesh filename="package://champ_description/meshes/asus_camera/asus_camera_simple.dae"/>
      </geometry>
    </visual>
    <collision>
      <origin rpy="0 0 0" xyz="0 0 0"/>
      <geometry>
        <mesh filename="package://champ_description/meshes/asus_camera/asus_camera_simple.dae"/>
        <!--box size="0.035 0.185 0.025"/-->
      </geometry>
    </collision>
  </link>
  <joint name="kinect_depth_joint" type="fixed">
    <origin rpy="0 0 0" xyz="0.0 0.049 0.0"/>
    <parent link="kinect_link"/>
    <child link="kinect_depth_frame"/>
  </joint>
  <link name="kinect_depth_frame"/>
  <joint name="kinect_depth_optical_joint" type="fixed">
    <origin rpy="-1.57079632679 0.0 -1.57079632679" xyz="0 0 0"/>
    <parent link="kinect_depth_frame"/>
    <child link="kinect_depth_optical_frame"/>
  </joint>
  <link name="kinect_depth_optical_frame"/>
  <joint name="kinect_rgb_joint" type="fixed">
    <origin rpy="0 0 0" xyz="0.0 0.022 0.0"/>
    <parent link="kinect_link"/>
    <child link="kinect_rgb_frame"/>
  </joint>
  <link name="kinect_rgb_frame"/>
  <joint name="kinect_rgb_optical_joint" type="fixed">
    <origin rpy="-1.57079632679 0.0 -1.57079632679" xyz="0 0 0"/>
    <parent link="kinect_rgb_frame"/>
    <child link="kinect_rgb_optical_frame"/>
  </joint>
  <link name="kinect_rgb_optical_frame"/>
  <!-- Root link is in the world frame-->
  <link name="world"/>
  <!-- ArmStuff -->
  <joint name="wam/bhand/bhand_base_joint" type="fixed">
    <parent link="wam/wrist_palm_link"/>
    <child link="wam/bhand/bhand_palm_link"/>
    <origin rpy="0 0 0" xyz="0 0 0.06"/>
  </joint>
  <gazebo reference="wam/bhand/bhand_palm_link">
    <mu1>0.8</mu1>
    <mu2>0.8</mu2>
  </gazebo>
  <link name="wam/bhand/bhand_palm_link">
    <inertial>
      <origin xyz="-5.1098e-005 0.0050433 0.036671"/>
      <mass value="0.50573"/>
      <inertia ixx="3.8374e-005" ixy="-5.604e-008" ixz="-4.2034e-005" iyy="0.00022405" iyz="1.3283e-007" izz="0.00020045"/>
    </inertial>
    <visual>
      <material name="WAMGrey">
        <color rgba="0.9 0.9 0.9 0.0"/>
      </material>
      <geometry>
        <mesh filename="package://champ_description/meshes/sw_meshes/bhand/bhand_palm_fine.stl"/>
      </geometry>
    </visual>
    <collision>
      <geometry>
        <mesh filename="package://champ_description/meshes/sw_meshes/bhand/bhand_palm_link_convex_decomposition.dae"/>
      </geometry>
    </collision>
  </link>
  <joint name="wam/bhand/bhand_palm_surface_joint" type="fixed">
    <parent link="wam/bhand/bhand_palm_link"/>
    <child link="wam/bhand/bhand_palm_surface_link"/>
    <origin rpy="0 0 0" xyz="0 0 0.08"/>
    <limit effort="5" lower="0" upper="3.14159265359" velocity="5.0"/>
    <dynamics damping="0.11" friction="0"/>
  </joint>
  <link name="wam/bhand/bhand_palm_surface_link">
    <inertial>
      <mass value="0.000001"/>
      <inertia ixx="0.000001" ixy="0.0" ixz="0.0" iyy="0.000001" iyz="0.0" izz="0.000001"/>
    </inertial>
  </link>
  <joint name="wam/bhand/bhand_grasp_joint" type="fixed">
    <parent link="wam/bhand/bhand_palm_link"/>
    <child link="wam/bhand/bhand_grasp_link"/>
    <origin rpy="0 0 0" xyz="0 0 0.12"/>
    <limit effort="5" lower="0" upper="3.14159265359" velocity="5.0"/>
    <dynamics damping="0.11" friction="0"/>
  </joint>
  <link name="wam/bhand/bhand_grasp_link">
    <inertial>
      <mass value="0.000001"/>
      <inertia ixx="0.000001" ixy="0.0" ixz="0.0" iyy="0.000001" iyz="0.0" izz="0.000001"/>
    </inertial>
  </link>
  <joint name="wam/bhand/finger_1/prox_joint" type="revolute">
    <parent link="wam/bhand/bhand_palm_link"/>
    <child link="wam/bhand/finger_1/prox_link"/>
    <origin rpy="0 0 -1.57079632679" xyz="-0.025 0.0 0.0415"/>
    <axis xyz="0 0 -1"/>
    <limit effort="5" lower="0" upper="3.14159265359" velocity="5.0"/>
    <dynamics damping="0.11" friction="0"/>
    <!--
	<xacro:if value= "${prefix=='wam/bhand/finger_2'}">
	  <mimic joint="wam/bhand/finger_1/prox_joint" multiplier="-1.0" offset="0.0" />
	</xacro:if>
-->
  </joint>
  <gazebo reference="wam/bhand/finger_1/prox_joint">
    <provideFeedback>true</provideFeedback>
    <implicitSpringDamper>true</implicitSpringDamper>
    <!--<kp>0.0</kp>[> CFM <]-->
    <!--<kd>0.0</kd>[> ERP <]-->
    <!--<cfmDamping>true</cfmDamping>-->
    <!--<dynamics damping="5.5" friction="1"/>-->
  </gazebo>
  <gazebo reference="wam/bhand/finger_1/prox_link">
    <mu1>0.8</mu1>
    <mu2>0.8</mu2>
  </gazebo>
  <link name="wam/bhand/finger_1/prox_link">
    <inertial>
      <origin xyz="0.023133 0.00078642 0.00052792"/>
      <mass value="0.14109"/>
      <inertia ixx="4.872e-006" ixy="1.7103e-006" ixz="3.4041e-008" iyy="7.6588e-005" iyz="2.3133e-008" izz="7.7733e-005"/>
    </inertial>
    <visual>
      <material name="WAMGrey">
        <color rgba="0.9 0.9 0.9 0.0"/>
      </material>
      <geometry>
        <mesh filename="package://champ_description/meshes/sw_meshes/bhand/bhand_finger_prox_link_fine.stl"/>
      </geometry>
    </visual>
    <collision>
      <geometry>
        <mesh filename="package://champ_description/meshes/sw_meshes/bhand/bhand_finger_prox_link_convex_decomposition.dae"/>
      </geometry>
    </collision>
  </link>
  <joint name="wam/bhand/finger_1/med_joint" type="revolute">
    <parent link="wam/bhand/finger_1/prox_link"/>
    <child link="wam/bhand/finger_1/med_link"/>
    <origin rpy="1.57079632679 0 0" xyz="0.05 0.0 0.03390"/>
    <axis xyz="0 0 1"/>
    <limit effort="5" lower="0" upper="2.44346095279" velocity="5.00"/>
    <dynamics damping="0.11" friction="0"/>
  </joint>
  <gazebo reference="wam/bhand/finger_1/med_joint">
    <provideFeedback>true</provideFeedback>
    <implicitSpringDamper>true</implicitSpringDamper>
    <!--<kp>0.0</kp>[> CFM <]-->
    <!--<kd>0.0</kd>[> ERP <]-->
    <!--<cfmDamping>true</cfmDamping>-->
    <!--<dynamics damping="5.5" friction="1"/>-->
  </gazebo>
  <gazebo reference="wam/bhand/finger_1/med_link">
    <mu1>0.8</mu1>
    <mu2>0.8</mu2>
  </gazebo>
  <link name="wam/bhand/finger_1/med_link">
    <inertial>
      <origin xyz="0.023133 0.00078642 0.00052792"/>
      <mass value="0.062139"/>
      <inertia ixx="4.872e-006" ixy="1.7103e-006" ixz="3.4041e-008" iyy="7.6588e-005" iyz="2.3133e-008" izz="7.7733e-005"/>
    </inertial>
    <visual>
      <material name="WAMGrey">
        <color rgba="0.9 0.9 0.9 0.0"/>
      </material>
      <geometry>
        <mesh filename="package://champ_description/meshes/sw_meshes/bhand/bhand_finger_med_link_fine.stl"/>
      </geometry>
    </visual>
    <collision>
      <geometry>
        <mesh filename="package://champ_description/meshes/sw_meshes/bhand/bhand_finger_med_link_convex.dae"/>
      </geometry>
    </collision>
  </link>
  <joint name="wam/bhand/finger_1/dist_joint" type="revolute">
    <parent link="wam/bhand/finger_1/med_link"/>
    <child link="wam/bhand/finger_1/dist_link"/>
    <origin rpy="0 0 0.785398163397" xyz="0.06994 0.003 0.0"/>
    <axis xyz="0 0 1"/>
    <limit effort="5" lower="0" upper="0.837758040957" velocity="5.00"/>
    <dynamics damping="0.11" friction="0"/>
  </joint>
  <gazebo reference="wam/bhand/finger_1/dist_joint">
    <provideFeedback>true</provideFeedback>
    <implicitSpringDamper>true</implicitSpringDamper>
    <!--<kp>0.0</kp>[> CFM <]-->
    <!--<kd>0.0</kd>[> ERP <]-->
    <!--<cfmDamping>true</cfmDamping>-->
    <!--<dynamics damping="5.5" friction="1"/>-->
  </gazebo>
  <gazebo reference="wam/bhand/finger_1/dist_link">
    <mu1>0.8</mu1>
    <mu2>0.8</mu2>
    <selfCollide>true</selfCollide>
  </gazebo>
  <link name="wam/bhand/finger_1/dist_link">
    <inertial>
      <origin rpy="0 0 0" xyz="0.022825 0.0010491 0.0004203"/>
      <mass value="0.041377"/>
      <inertia ixx="3.1582e-006" ixy="1.4308e-006" ixz="1.0106e-007" iyy="3.8376e-005" iyz="0" izz="3.7275e-005"/>
    </inertial>
    <visual>
      <origin rpy="0 0 -0.785398163397"/>
      <material name="WAMGrey">
        <color rgba="0.9 0.9 0.9 0.0"/>
      </material>
      <geometry>
        <mesh filename="package://champ_description/meshes/sw_meshes/bhand/bhand_finger_dist_link_fine.stl"/>
      </geometry>
    </visual>
    <collision>
      <origin rpy="0 0 -0.785398163397"/>
      <geometry>
        <mesh filename="package://champ_description/meshes/sw_meshes/bhand/bhand_finger_dist_link_convex.dae"/>
      </geometry>
    </collision>
  </link>
  <joint name="wam/bhand/finger_1/tip_joint" type="fixed">
    <parent link="wam/bhand/finger_1/dist_link"/>
    <child link="wam/bhand/finger_1/tip_link"/>
    <origin rpy="0 0 0" xyz="0.05 0.0 0.0"/>
  </joint>
  <link name="wam/bhand/finger_1/tip_link">
    <inertial>
      <mass value="1E-6"/>
      <inertia ixx="1E-6" ixy="0" ixz="0" iyy="1E-6" iyz="0" izz="1E-6"/>
    </inertial>
  </link>
  <joint name="wam/bhand/finger_2/prox_joint" type="revolute">
    <parent link="wam/bhand/bhand_palm_link"/>
    <child link="wam/bhand/finger_2/prox_link"/>
    <origin rpy="0 0 -1.57079632679" xyz="0.025 0.0 0.0415"/>
    <axis xyz="0 0 1"/>
    <limit effort="5" lower="0" upper="3.14159265359" velocity="5.0"/>
    <dynamics damping="0.11" friction="0"/>
    <!--
	<xacro:if value= "${prefix=='wam/bhand/finger_2'}">
	  <mimic joint="wam/bhand/finger_1/prox_joint" multiplier="-1.0" offset="0.0" />
	</xacro:if>
-->
  </joint>
  <gazebo reference="wam/bhand/finger_2/prox_joint">
    <provideFeedback>true</provideFeedback>
    <implicitSpringDamper>true</implicitSpringDamper>
    <!--<kp>0.0</kp>[> CFM <]-->
    <!--<kd>0.0</kd>[> ERP <]-->
    <!--<cfmDamping>true</cfmDamping>-->
    <!--<dynamics damping="5.5" friction="1"/>-->
  </gazebo>
  <gazebo reference="wam/bhand/finger_2/prox_link">
    <mu1>0.8</mu1>
    <mu2>0.8</mu2>
  </gazebo>
  <link name="wam/bhand/finger_2/prox_link">
    <inertial>
      <origin xyz="0.023133 0.00078642 0.00052792"/>
      <mass value="0.14109"/>
      <inertia ixx="4.872e-006" ixy="1.7103e-006" ixz="3.4041e-008" iyy="7.6588e-005" iyz="2.3133e-008" izz="7.7733e-005"/>
    </inertial>
    <visual>
      <material name="WAMGrey">
        <color rgba="0.9 0.9 0.9 0.0"/>
      </material>
      <geometry>
        <mesh filename="package://champ_description/meshes/sw_meshes/bhand/bhand_finger_prox_link_fine.stl"/>
      </geometry>
    </visual>
    <collision>
      <geometry>
        <mesh filename="package://champ_description/meshes/sw_meshes/bhand/bhand_finger_prox_link_convex_decomposition.dae"/>
      </geometry>
    </collision>
  </link>
  <joint name="wam/bhand/finger_2/med_joint" type="revolute">
    <parent link="wam/bhand/finger_2/prox_link"/>
    <child link="wam/bhand/finger_2/med_link"/>
    <origin rpy="1.57079632679 0 0" xyz="0.05 0.0 0.03390"/>
    <axis xyz="0 0 1"/>
    <limit effort="5" lower="0" upper="2.44346095279" velocity="5.00"/>
    <dynamics damping="0.11" friction="0"/>
  </joint>
  <gazebo reference="wam/bhand/finger_2/med_joint">
    <provideFeedback>true</provideFeedback>
    <implicitSpringDamper>true</implicitSpringDamper>
    <!--<kp>0.0</kp>[> CFM <]-->
    <!--<kd>0.0</kd>[> ERP <]-->
    <!--<cfmDamping>true</cfmDamping>-->
    <!--<dynamics damping="5.5" friction="1"/>-->
  </gazebo>
  <gazebo reference="wam/bhand/finger_2/med_link">
    <mu1>0.8</mu1>
    <mu2>0.8</mu2>
  </gazebo>
  <link name="wam/bhand/finger_2/med_link">
    <inertial>
      <origin xyz="0.023133 0.00078642 0.00052792"/>
      <mass value="0.062139"/>
      <inertia ixx="4.872e-006" ixy="1.7103e-006" ixz="3.4041e-008" iyy="7.6588e-005" iyz="2.3133e-008" izz="7.7733e-005"/>
    </inertial>
    <visual>
      <material name="WAMGrey">
        <color rgba="0.9 0.9 0.9 0.0"/>
      </material>
      <geometry>
        <mesh filename="package://champ_description/meshes/sw_meshes/bhand/bhand_finger_med_link_fine.stl"/>
      </geometry>
    </visual>
    <collision>
      <geometry>
        <mesh filename="package://champ_description/meshes/sw_meshes/bhand/bhand_finger_med_link_convex.dae"/>
      </geometry>
    </collision>
  </link>
  <joint name="wam/bhand/finger_2/dist_joint" type="revolute">
    <parent link="wam/bhand/finger_2/med_link"/>
    <child link="wam/bhand/finger_2/dist_link"/>
    <origin rpy="0 0 0.785398163397" xyz="0.06994 0.003 0.0"/>
    <axis xyz="0 0 1"/>
    <limit effort="5" lower="0" upper="0.837758040957" velocity="5.00"/>
    <dynamics damping="0.11" friction="0"/>
  </joint>
  <gazebo reference="wam/bhand/finger_2/dist_joint">
    <provideFeedback>true</provideFeedback>
    <implicitSpringDamper>true</implicitSpringDamper>
    <!--<kp>0.0</kp>[> CFM <]-->
    <!--<kd>0.0</kd>[> ERP <]-->
    <!--<cfmDamping>true</cfmDamping>-->
    <!--<dynamics damping="5.5" friction="1"/>-->
  </gazebo>
  <gazebo reference="wam/bhand/finger_2/dist_link">
    <mu1>0.8</mu1>
    <mu2>0.8</mu2>
    <selfCollide>true</selfCollide>
  </gazebo>
  <link name="wam/bhand/finger_2/dist_link">
    <inertial>
      <origin rpy="0 0 0" xyz="0.022825 0.0010491 0.0004203"/>
      <mass value="0.041377"/>
      <inertia ixx="3.1582e-006" ixy="1.4308e-006" ixz="1.0106e-007" iyy="3.8376e-005" iyz="0" izz="3.7275e-005"/>
    </inertial>
    <visual>
      <origin rpy="0 0 -0.785398163397"/>
      <material name="WAMGrey">
        <color rgba="0.9 0.9 0.9 0.0"/>
      </material>
      <geometry>
        <mesh filename="package://champ_description/meshes/sw_meshes/bhand/bhand_finger_dist_link_fine.stl"/>
      </geometry>
    </visual>
    <collision>
      <origin rpy="0 0 -0.785398163397"/>
      <geometry>
        <mesh filename="package://champ_description/meshes/sw_meshes/bhand/bhand_finger_dist_link_convex.dae"/>
      </geometry>
    </collision>
  </link>
  <joint name="wam/bhand/finger_2/tip_joint" type="fixed">
    <parent link="wam/bhand/finger_2/dist_link"/>
    <child link="wam/bhand/finger_2/tip_link"/>
    <origin rpy="0 0 0" xyz="0.05 0.0 0.0"/>
  </joint>
  <link name="wam/bhand/finger_2/tip_link">
    <inertial>
      <mass value="1E-6"/>
      <inertia ixx="1E-6" ixy="0" ixz="0" iyy="1E-6" iyz="0" izz="1E-6"/>
    </inertial>
  </link>
  <joint name="wam/bhand/finger_3/med_joint" type="revolute">
    <parent link="wam/bhand/bhand_palm_link"/>
    <child link="wam/bhand/finger_3/med_link"/>
    <origin rpy="1.57079632679 0 1.57079632679" xyz="0 0.05 0.0754"/>
    <axis xyz="0 0 1"/>
    <limit effort="5" lower="0" upper="2.44346095279" velocity="5.00"/>
    <dynamics damping="0.11" friction="0"/>
  </joint>
  <gazebo reference="wam/bhand/finger_3/med_joint">
    <provideFeedback>true</provideFeedback>
    <implicitSpringDamper>true</implicitSpringDamper>
    <!--<kp>0.0</kp>[> CFM <]-->
    <!--<kd>0.0</kd>[> ERP <]-->
    <!--<cfmDamping>true</cfmDamping>-->
    <!--<dynamics damping="5.5" friction="1"/>-->
  </gazebo>
  <gazebo reference="wam/bhand/finger_3/med_link">
    <mu1>0.8</mu1>
    <mu2>0.8</mu2>
  </gazebo>
  <link name="wam/bhand/finger_3/med_link">
    <inertial>
      <origin xyz="0.023133 0.00078642 0.00052792"/>
      <mass value="0.062139"/>
      <inertia ixx="4.872e-006" ixy="1.7103e-006" ixz="3.4041e-008" iyy="7.6588e-005" iyz="2.3133e-008" izz="7.7733e-005"/>
    </inertial>
    <visual>
      <material name="WAMGrey">
        <color rgba="0.9 0.9 0.9 0.0"/>
      </material>
      <geometry>
        <mesh filename="package://champ_description/meshes/sw_meshes/bhand/bhand_finger_med_link_fine.stl"/>
      </geometry>
    </visual>
    <collision>
      <geometry>
        <mesh filename="package://champ_description/meshes/sw_meshes/bhand/bhand_finger_med_link_convex.dae"/>
      </geometry>
    </collision>
  </link>
  <joint name="wam/bhand/finger_3/dist_joint" type="revolute">
    <parent link="wam/bhand/finger_3/med_link"/>
    <child link="wam/bhand/finger_3/dist_link"/>
    <origin rpy="0 0 0.785398163397" xyz="0.06994 0.003 0.0"/>
    <axis xyz="0 0 1"/>
    <limit effort="5" lower="0" upper="0.837758040957" velocity="5.00"/>
    <dynamics damping="0.11" friction="0"/>
  </joint>
  <gazebo reference="wam/bhand/finger_3/dist_joint">
    <provideFeedback>true</provideFeedback>
    <implicitSpringDamper>true</implicitSpringDamper>
    <!--<kp>0.0</kp>[> CFM <]-->
    <!--<kd>0.0</kd>[> ERP <]-->
    <!--<cfmDamping>true</cfmDamping>-->
    <!--<dynamics damping="5.5" friction="1"/>-->
  </gazebo>
  <gazebo reference="wam/bhand/finger_3/dist_link">
    <mu1>0.8</mu1>
    <mu2>0.8</mu2>
    <selfCollide>true</selfCollide>
  </gazebo>
  <link name="wam/bhand/finger_3/dist_link">
    <inertial>
      <origin rpy="0 0 0" xyz="0.022825 0.0010491 0.0004203"/>
      <mass value="0.041377"/>
      <inertia ixx="3.1582e-006" ixy="1.4308e-006" ixz="1.0106e-007" iyy="3.8376e-005" iyz="0" izz="3.7275e-005"/>
    </inertial>
    <visual>
      <origin rpy="0 0 -0.785398163397"/>
      <material name="WAMGrey">
        <color rgba="0.9 0.9 0.9 0.0"/>
      </material>
      <geometry>
        <mesh filename="package://champ_description/meshes/sw_meshes/bhand/bhand_finger_dist_link_fine.stl"/>
      </geometry>
    </visual>
    <collision>
      <origin rpy="0 0 -0.785398163397"/>
      <geometry>
        <mesh filename="package://champ_description/meshes/sw_meshes/bhand/bhand_finger_dist_link_convex.dae"/>
      </geometry>
    </collision>
  </link>
  <joint name="wam/bhand/finger_3/tip_joint" type="fixed">
    <parent link="wam/bhand/finger_3/dist_link"/>
    <child link="wam/bhand/finger_3/tip_link"/>
    <origin rpy="0 0 0" xyz="0.05 0.0 0.0"/>
  </joint>
  <link name="wam/bhand/finger_3/tip_link">
    <inertial>
      <mass value="1E-6"/>
      <inertia ixx="1E-6" ixy="0" ixz="0" iyy="1E-6" iyz="0" izz="1E-6"/>
    </inertial>
  </link>
  <joint name="wam/wam_fixed_joint" type="fixed">
    <parent link="arm_plate"/>
    <child link="wam/base_link"/>
    <origin rpy="0 0 0" xyz="0.22 0.0 0.05"/>
  </joint>
  <link name="wam/base_link">
    <inertial>
      <origin xyz="0 0 0"/>
      <mass value="1"/>
      <inertia ixx="0.1" ixy="0" ixz="0" iyy="0.1" iyz="0" izz="0.1"/>
    </inertial>
    <visual>
      <material name="WAMGrey">
        <color rgba="0.7 0.7 0.7 0.0"/>
      </material>
      <geometry>
        <mesh filename="package://champ_description/meshes/sw_meshes/base_link_fine.stl"/>
      </geometry>
    </visual>
    <collision>
      <geometry>
        <mesh filename="package://champ_description/meshes/sw_meshes/base_link_convex.dae"/>
      </geometry>
    </collision>
  </link>
  <joint name="wam/base_yaw_joint" type="revolute">
    <parent link="wam/base_link"/>
    <child link="wam/shoulder_yaw_link"/>
    <origin rpy="0 0 0" xyz="0 0 0.346"/>
    <axis xyz="0 0 1"/>
    <limit effort="60" lower="-2.6" upper="2.6" velocity="2.0"/>
    <dynamics damping="1.98" friction="0"/>
  </joint>
  <gazebo reference="wam/base_yaw_joint">
    <provideFeedback>true</provideFeedback>
    <implicitSpringDamper>true</implicitSpringDamper>
    <!--<kp>0.0</kp>[> CFM <]-->
    <!--<kd>0.0</kd>[> ERP <]-->
    <!--<cfmDamping>true</cfmDamping>-->
    <!--<dynamics damping="5.5" friction="1"/>-->
  </gazebo>
  <link name="wam/shoulder_yaw_link">
    <inertial>
      <origin xyz="-.00443422 -.00066489 -0.1289039 "/>
      <mass value="5.0"/>
      <inertia ixx=".13488033" ixy="-0.00012485" ixz="0.00213041" iyy=".09046330" iyz="-.00068555" izz=".11328369"/>
    </inertial>
    <visual>
      <material name="WAMGrey">
        <color rgba="0.7 0.7 0.7 1.0"/>
      </material>
      <geometry>
        <mesh filename="package://champ_description/meshes/sw_meshes/shoulder_link_fine.stl"/>
      </geometry>
    </visual>
    <collision>
      <geometry>
        <mesh filename="package://champ_description/meshes/sw_meshes/shoulder_link_convex_decomposition.dae"/>
      </geometry>
    </collision>
  </link>
  <joint name="wam/shoulder_pitch_joint" type="revolute">
    <parent link="wam/shoulder_yaw_link"/>
    <child link="wam/shoulder_pitch_link"/>
    <origin rpy="-1.57079632679 0 0" xyz="0 0 0"/>
    <axis xyz="0 0 1"/>
    <limit effort="60" lower="-1.985" upper="1.985" velocity="2.0"/>
    <dynamics damping="0.55" friction="0"/>
  </joint>
  <gazebo reference="wam/shoulder_pitch_joint">
    <provideFeedback>true</provideFeedback>
    <implicitSpringDamper>true</implicitSpringDamper>
    <!--<kp>0.0</kp>[> CFM <]-->
    <!--<kd>0.0</kd>[> ERP <]-->
    <!--<cfmDamping>true</cfmDamping>-->
    <!--<dynamics damping="5.5" friction="1"/>-->
  </gazebo>
  <link name="wam/shoulder_pitch_link">
    <visual>
      <material name="WAMGrey">
        <color rgba="0.7 0.7 0.7 1.0"/>
      </material>
      <geometry>
        <mesh filename="package://champ_description/meshes/sw_meshes/shoulder_pitch_link_fine.stl"/>
      </geometry>
    </visual>
    <inertial>
      <origin xyz="-.00236981 -.01542114 .03105614 "/>
      <mass value="3.87493756"/>
      <inertia ixx="0.02140958" ixy="-0.00002461" ixz="0.00027172" iyy="0.015589060" iyz="0.0018192" izz="0.01377875"/>
    </inertial>
    <collision>
      <geometry>
        <mesh filename="package://champ_description/meshes/sw_meshes/shoulder_pitch_link_convex.dae"/>
      </geometry>
    </collision>
  </link>
  <joint name="wam/shoulder_yaw_joint" type="revolute">
    <parent link="wam/shoulder_pitch_link"/>
    <child link="wam/upper_arm_link"/>
    <origin rpy="1.57079632679 0 0" xyz="0 0 0"/>
    <axis xyz="0 0 1"/>
    <limit effort="45" lower="-2.8" upper="2.8" velocity="2.0"/>
    <dynamics damping="1.65" friction="0"/>
  </joint>
  <gazebo reference="wam/shoulder_yaw_joint">
    <provideFeedback>true</provideFeedback>
    <implicitSpringDamper>true</implicitSpringDamper>
    <!--<kp>0.0</kp>[> CFM <]-->
    <!--<kd>0.0</kd>[> ERP <]-->
    <!--<cfmDamping>true</cfmDamping>-->
    <!--<dynamics damping="5.5" friction="1"/>-->
  </gazebo>
  <link name="wam/upper_arm_link">
    <inertial>
      <origin xyz="0.00683258580000000 0.000033090000000 0.392492300000000"/>
      <mass value="2.20228141"/>
      <inertia ixx=".05911077" ixy="-0.00000738" ixz="-0.00249612" iyy="0.05927043" iyz="0.00001767" izz="0.0032455"/>
    </inertial>
    <visual>
      <material name="WAMGrey">
        <color rgba="0.7 0.7 0.7 1.0"/>
      </material>
      <geometry>
        <mesh filename="package://champ_description/meshes/sw_meshes/upper_arm_link_fine.stl"/>
      </geometry>
    </visual>
    <collision>
      <geometry>
        <mesh filename="package://champ_description/meshes/sw_meshes/upper_arm_link_convex_decomposition.dae"/>
      </geometry>
    </collision>
  </link>
  <joint name="wam/elbow_pitch_joint" type="revolute">
    <parent link="wam/upper_arm_link"/>
    <child link="wam/forearm_link"/>
    <origin rpy="-1.57079632679 0 0" xyz="0.045 0 0.55"/>
    <axis xyz="0 0 1"/>
    <limit effort="30" lower="-0.9" upper="3.14159265359" velocity="2.00"/>
    <dynamics damping="0.88" friction="0"/>
  </joint>
  <gazebo reference="wam/elbow_pitch_joint">
    <provideFeedback>true</provideFeedback>
    <implicitSpringDamper>true</implicitSpringDamper>
    <!--<kp>0.0</kp>[> CFM <]-->
    <!--<kd>0.0</kd>[> ERP <]-->
    <!--<cfmDamping>true</cfmDamping>-->
    <!--<dynamics damping="5.5" friction="1"/>-->
  </gazebo>
  <link name="wam/forearm_link">
    <inertial>
      <mass value="0.50016804"/>
      <origin rpy="0 0 0" xyz="-0.04001488 -.14271662 -.00022942 "/>
      <inertia ixx="0.01491672" ixy="0.001506040000000" ixz="0.000017410000000" iyy="0.002944630000000" iyz="0.000021090000000" izz="0.014829880000000"/>
    </inertial>
    <visual>
      <material name="WAMGrey">
        <color rgba="0.7 0.7 0.7 1.0"/>
      </material>
      <geometry>
        <mesh filename="package://champ_description/meshes/sw_meshes/elbow_link_fine.stl"/>
      </geometry>
    </visual>
    <collision>
      <geometry>
        <mesh filename="package://champ_description/meshes/sw_meshes/elbow_link_convex.dae"/>
      </geometry>
    </collision>
    <visual>
      <material name="WAMGrey">
        <color rgba="0.7 0.7 0.7 1.0"/>
      </material>
      <origin rpy="1.57079632679 0 0" xyz="-0.045 -0.0730 0"/>
      <geometry>
        <mesh filename="package://champ_description/meshes/sw_meshes/forearm_link_fine.stl"/>
      </geometry>
    </visual>
    <collision>
      <origin rpy="1.57079632679 0 0" xyz="-0.045 -0.0730 0"/>
      <geometry>
        <mesh filename="package://champ_description/meshes/sw_meshes/forearm_link_convex_decomposition.dae"/>
      </geometry>
    </collision>
  </link>
  <joint name="wam/wrist_yaw_joint" type="revolute">
    <parent link="wam/forearm_link"/>
    <child link="wam/wrist_yaw_link"/>
    <origin rpy="1.57079632679 0 0" xyz="-0.045 -0.3 0"/>
    <axis xyz="0 0 1"/>
    <limit effort="10" lower="-4.55" upper="1.25" velocity="2.0"/>
    <dynamics damping="0.55" friction="0"/>
  </joint>
  <gazebo reference="wam/wrist_yaw_joint">
    <provideFeedback>true</provideFeedback>
    <implicitSpringDamper>true</implicitSpringDamper>
    <!--<kp>0.0</kp>[> CFM <]-->
    <!--<kd>0.0</kd>[> ERP <]-->
    <!--<cfmDamping>true</cfmDamping>-->
    <!--<dynamics damping="5.5" friction="1"/>-->
  </gazebo>
  <link name="wam/wrist_yaw_link">
    <inertial>
      <origin xyz="0.00008921 0.00435824 -0.00511217 "/>
      <mass value="1.05376019"/>
      <inertia ixx="0.00005029" ixy="0.00000020" ixz="0.00007582" iyy="0.00007582" iyz="-0.00000359" izz="0.00006270"/>
    </inertial>
    <visual>
      <material name="WAMGrey">
        <color rgba="0.7 0.7 0.7 1.0"/>
      </material>
      <origin rpy="0 0 0" xyz="0 0 0"/>
      <geometry>
        <mesh filename="package://champ_description/meshes/sw_meshes/wrist_yaw_link_fine.stl"/>
      </geometry>
    </visual>
    <collision>
      <origin rpy="0 0 0" xyz="0 0 0"/>
      <geometry>
        <mesh filename="package://champ_description/meshes/sw_meshes/wrist_yaw_link_convex_decomposition.dae"/>
      </geometry>
    </collision>
  </link>
  <joint name="wam/wrist_pitch_joint" type="revolute">
    <parent link="wam/wrist_yaw_link"/>
    <child link="wam/wrist_pitch_link"/>
    <origin rpy="-1.57079632679 0 0" xyz="0 0 0"/>
    <axis xyz="0 0 1"/>
    <limit effort="10" lower="-1.5707" upper="1.5707" velocity="2.00"/>
    <dynamics damping="0.11" friction="0"/>
  </joint>
  <gazebo reference="wam/wrist_pitch_joint">
    <provideFeedback>true</provideFeedback>
    <implicitSpringDamper>true</implicitSpringDamper>
    <!--<kp>0.0</kp>[> CFM <]-->
    <!--<kd>0.0</kd>[> ERP <]-->
    <!--<cfmDamping>true</cfmDamping>-->
    <!--<dynamics damping="5.5" friction="1"/>-->
  </gazebo>
  <link name="wam/wrist_pitch_link">
    <inertial>
      <origin rpy="0 0 0" xyz="-0.00012262 -0.02468336 -0.01703194 "/>
      <mass value="0.51797364"/>
      <inertia ixx="0.00055516" ixy="0.00000061" ixz="-0.00000074" iyy="0.00024367" iyz="-0.00004590" izz="0.00045358"/>
    </inertial>
    <visual>
      <material name="WAMGrey">
        <color rgba="0.7 0.7 0.7 1.0"/>
      </material>
      <geometry>
        <mesh filename="package://champ_description/meshes/sw_meshes/wrist_pitch_link_fine.stl"/>
      </geometry>
    </visual>
    <collision>
      <geometry>
        <mesh filename="package://champ_description/meshes/sw_meshes/wrist_pitch_link_convex_decomposition.dae"/>
      </geometry>
    </collision>
  </link>
  <joint name="wam/palm_yaw_joint" type="revolute">
    <parent link="wam/wrist_pitch_link"/>
    <child link="wam/wrist_palm_link"/>
    <origin rpy="1.57079632679 0 0" xyz="0 0 0"/>
    <axis xyz="0 0 1"/>
    <limit effort="10" lower="-3.0" upper="3.0" velocity="2.00"/>
    <!-- 2.95 is a limit taken in from 3 due to saftey and differences between arms. -->
    <dynamics damping="0.11" friction="0"/>
  </joint>
  <gazebo reference="wam/palm_yaw_joint">
    <provideFeedback>true</provideFeedback>
    <implicitSpringDamper>true</implicitSpringDamper>
    <!--<kp>0.0</kp>[> CFM <]-->
    <!--<kd>0.0</kd>[> ERP <]-->
    <!--<cfmDamping>true</cfmDamping>-->
    <!--<dynamics damping="5.5" friction="1"/>-->
  </gazebo>
  <link name="wam/wrist_palm_link">
    <inertial>
      <origin rpy="0 0 0" xyz="0.0 0.0 0.055"/>
      <mass value="0.08286134"/>
      <inertia ixx="0.00010859" ixy="0.00000000" ixz="-0.00000000" iyy="0.00020683" iyz="-0.0000000" izz="0.00010851"/>
    </inertial>
    <visual>
      <material name="WAMGrey">
        <color rgba="0.7 0.7 0.7 1.0"/>
      </material>
      <origin rpy="0 0 0" xyz="0 0 0"/>
      <geometry>
        <mesh filename="package://champ_description/meshes/sw_meshes/wrist_palm_link_fine.stl"/>
      </geometry>
    </visual>
    <collision>
      <origin rpy="0 0 0" xyz="0 0 0"/>
      <geometry>
        <mesh filename="package://champ_description/meshes/sw_meshes/wrist_palm_link_convex.dae"/>
      </geometry>
    </collision>
  </link>
  <joint name="wam/wrist_palm_stump_joint" type="fixed">
    <parent link="wam/wrist_palm_link"/>
    <child link="wam/wrist_palm_stump_link"/>
    <origin rpy="0 0 0" xyz="0 0 0.06"/>
  </joint>
  <link name="wam/wrist_palm_stump_link">
    <inertial>
      <mass value="0.000001"/>
      <inertia ixx="0.0000001" ixy="0.0" ixz="0.0" iyy="0.0000001" iyz="0.0" izz="0.0000001"/>
    </inertial>
  </link>
  <joint name="powerbot/world_joint" type="planar">
    <parent link="world"/>
    <child link="base_center"/>
    <origin rpy="0 0 0" xyz="0.0 0.0 0.0"/>
  </joint>
  <!--Joint Controllers
- ARM
      - wam/base_yaw_joint
      - wam/shoulder_pitch_joint
      - wam/shoulder_yaw_joint
      - wam/elbow_pitch_joint
      - wam/wrist_yaw_joint
      - wam/wrist_pitch_joint
      - wam/palm_yaw_joint
- HAND
      - wam/bhand/finger_1/med_joint
      - wam/bhand/finger_1/dist_joint

      - wam/bhand/finger_2/med_joint
      - wam/bhand/finger_2/dist_joint

      - wam/bhand/finger_3/dist_joint

-->
  <!-- wam/base_yaw_joint -->
  <transmission name="w1">
    <type>transmission_interface/SimpleTransmission</type>
    <joint name="wam/base_yaw_joint">
      <hardwareInterface>hardware_interface/EffortJointInterface</hardwareInterface>
    </joint>
    <actuator name="motor1">
      <hardwareInterface>hardware_interface/EffortJointInterface</hardwareInterface>
      <mechanicalReduction>1</mechanicalReduction>
    </actuator>
  </transmission>
  <!-- wam/shoulder_pitch_joint -->
  <transmission name="w2">
    <type>transmission_interface/SimpleTransmission</type>
    <joint name="wam/shoulder_pitch_joint">
      <hardwareInterface>hardware_interface/EffortJointInterface</hardwareInterface>
    </joint>
    <actuator name="motor2">
      <hardwareInterface>hardware_interface/EffortJointInterface</hardwareInterface>
      <mechanicalReduction>1</mechanicalReduction>
    </actuator>
  </transmission>
  <!-- wam/shoulder_yaw_joint -->
  <transmission name="w3">
    <type>transmission_interface/SimpleTransmission</type>
    <joint name="wam/shoulder_yaw_joint">
      <hardwareInterface>hardware_interface/EffortJointInterface</hardwareInterface>
    </joint>
    <actuator name="motor3">
      <hardwareInterface>hardware_interface/EffortJointInterface</hardwareInterface>
      <mechanicalReduction>1</mechanicalReduction>
    </actuator>
  </transmission>
  <!-- wam/elbow_pitch_joint -->
  <transmission name="w4">
    <type>transmission_interface/SimpleTransmission</type>
    <joint name="wam/elbow_pitch_joint">
      <hardwareInterface>hardware_interface/EffortJointInterface</hardwareInterface>
    </joint>
    <actuator name="motor4">
      <hardwareInterface>hardware_interface/EffortJointInterface</hardwareInterface>
      <mechanicalReduction>1</mechanicalReduction>
    </actuator>
  </transmission>
  <!-- wam/wrist_yaw_joint -->
  <transmission name="w5">
    <type>transmission_interface/SimpleTransmission</type>
    <joint name="wam/wrist_yaw_joint">
      <hardwareInterface>hardware_interface/EffortJointInterface</hardwareInterface>
    </joint>
    <actuator name="motor5">
      <hardwareInterface>hardware_interface/EffortJointInterface</hardwareInterface>
      <mechanicalReduction>1</mechanicalReduction>
    </actuator>
  </transmission>
  <!-- wam/wrist_pitch_joint -->
  <transmission name="w6">
    <type>transmission_interface/SimpleTransmission</type>
    <joint name="wam/wrist_pitch_joint">
      <hardwareInterface>hardware_interface/EffortJointInterface</hardwareInterface>
    </joint>
    <actuator name="motor6">
      <hardwareInterface>hardware_interface/EffortJointInterface</hardwareInterface>
      <mechanicalReduction>1</mechanicalReduction>
    </actuator>
  </transmission>
  <!-- wam/palm_yaw_joint -->
  <transmission name="w7">
    <type>transmission_interface/SimpleTransmission</type>
    <joint name="wam/palm_yaw_joint">
      <hardwareInterface>hardware_interface/EffortJointInterface</hardwareInterface>
    </joint>
    <actuator name="motor7">
      <hardwareInterface>hardware_interface/EffortJointInterface</hardwareInterface>
      <mechanicalReduction>1</mechanicalReduction>
    </actuator>
  </transmission>
  <!-- wam/bhand/finger_1/prox_joint -->
  <transmission name="f1_prox">
    <type>transmission_interface/SimpleTransmission</type>
    <joint name="wam/bhand/finger_1/prox_joint">
      <hardwareInterface>hardware_interface/EffortJointInterface</hardwareInterface>
    </joint>
    <actuator name="motor8_1">
      <hardwareInterface>hardware_interface/EffortJointInterface</hardwareInterface>
      <mechanicalReduction>1</mechanicalReduction>
    </actuator>
  </transmission>
  <!-- wam/bhand/finger_1/med_joint -->
  <transmission name="f1_med">
    <type>transmission_interface/SimpleTransmission</type>
    <joint name="wam/bhand/finger_1/med_joint">
      <hardwareInterface>hardware_interface/EffortJointInterface</hardwareInterface>
    </joint>
    <actuator name="motor8_2">
      <hardwareInterface>hardware_interface/EffortJointInterface</hardwareInterface>
      <mechanicalReduction>1</mechanicalReduction>
    </actuator>
  </transmission>
  <!-- wam/bhand/finger_1/dist_joint -->
  <transmission name="f1_dist">
    <type>transmission_interface/SimpleTransmission</type>
    <joint name="wam/bhand/finger_1/dist_joint">
      <hardwareInterface>hardware_interface/EffortJointInterface</hardwareInterface>
    </joint>
    <actuator name="motor8_3">
      <hardwareInterface>hardware_interface/EffortJointInterface</hardwareInterface>
      <mechanicalReduction>1</mechanicalReduction>
    </actuator>
  </transmission>
  <!-- wam/bhand/finger_2/prox_joint -->
  <transmission name="f2_prox">
    <type>transmission_interface/SimpleTransmission</type>
    <joint name="wam/bhand/finger_2/prox_joint">
      <hardwareInterface>hardware_interface/EffortJointInterface</hardwareInterface>
    </joint>
    <actuator name="motor9_1">
      <hardwareInterface>hardware_interface/EffortJointInterface</hardwareInterface>
      <mechanicalReduction>1</mechanicalReduction>
    </actuator>
  </transmission>
  <!-- wam/bhand/finger_2/med_joint -->
  <transmission name="f2_med">
    <type>transmission_interface/SimpleTransmission</type>
    <joint name="wam/bhand/finger_2/med_joint">
      <hardwareInterface>hardware_interface/EffortJointInterface</hardwareInterface>
    </joint>
    <actuator name="motor9_2">
      <hardwareInterface>hardware_interface/EffortJointInterface</hardwareInterface>
      <mechanicalReduction>1</mechanicalReduction>
    </actuator>
  </transmission>
  <!-- wam/bhand/finger_2/dist_joint -->
  <transmission name="f2_dist">
    <type>transmission_interface/SimpleTransmission</type>
    <joint name="wam/bhand/finger_2/dist_joint">
      <hardwareInterface>hardware_interface/EffortJointInterface</hardwareInterface>
    </joint>
    <actuator name="motor9_3">
      <hardwareInterface>hardware_interface/EffortJointInterface</hardwareInterface>
      <mechanicalReduction>1</mechanicalReduction>
    </actuator>
  </transmission>
  <!-- wam/bhand/finger_3/med_joint -->
  <transmission name="f3_med">
    <type>transmission_interface/SimpleTransmission</type>
    <joint name="wam/bhand/finger_3/med_joint">
      <hardwareInterface>hardware_interface/EffortJointInterface</hardwareInterface>
    </joint>
    <actuator name="motor10_1">
      <hardwareInterface>hardware_interface/EffortJointInterface</hardwareInterface>
      <mechanicalReduction>1</mechanicalReduction>
    </actuator>
  </transmission>
  <!-- wam/bhand/finger_3/dist_joint -->
  <transmission name="f3_dist">
    <type>transmission_interface/SimpleTransmission</type>
    <joint name="wam/bhand/finger_3/dist_joint">
      <hardwareInterface>hardware_interface/EffortJointInterface</hardwareInterface>
    </joint>
    <actuator name="motor10_2">
      <hardwareInterface>hardware_interface/EffortJointInterface</hardwareInterface>
      <mechanicalReduction>1</mechanicalReduction>
    </actuator>
  </transmission>
  <gazebo>
    <plugin filename="libgazebo_ros_control.so" name="gazebo_ros_control">
      <robotNamespace>/wam_powerbot</robotNamespace>
    </plugin>
  </gazebo>
</robot>

